Workbook

Sheet Shrinkage
A1: Date | B1: Zone | C1: city_name_ | D1: Store Name | E1: CLM | F1: IM | G1: locationtype2 | H1: Adj_Amt | I1: FCC_Bin_Amt | J1: Other_Bin_Amt | K1: Shortpick_Amt | L1: RTO_Loss | M1: PP PO Closed (curr+prev) | N1: PP STO Closed (curr+prev) | O1: PP Canc Closed (curr+prev) | P1: Total Inhouse | Q1: SLP Ticket ID / Mail | R1: SLP Recovery | S1: RCA & POA | T1: Expected Recovery by 11th Oct | U1: Top 2 Net Loss Aisle | V1: Top 2 Aisle Net Loss Value
A2: 46303 | B2: South1 | C2: Bengaluru | D2: BLR-Shivaji Nagar SS | E2: {=IF(D2="","",IFERROR(INDEX('CLM & IM Mapping'!$B$2:$B$270,MATCH(TRIM(D2),'CLM & IM Mapping'!$A$2:$A$270,0)),"Not Mapped"))} -> Arun Raj | F2: {=IF(D2="","",IFERROR(INDEX('CLM & IM Mapping'!$C$2:$C$270,MATCH(TRIM(D2),'CLM & IM Mapping'!$A$2:$A$270,0)),"Not Mapped"))} -> Simon Manoharan | G2: SUPERSTORE | H2: 69321 | I2: 75628 | J2: 0 | K2: 246 | L2: 1427 | M2: 0 | N2: 0 | O2: 9015 | P2: 155636 | Q2: Theft investigation – recovery of ₹15,000. | R2: 15000 | S2: * Total IH loss is ₹1.56L, mainly from FCC bin ₹75.6K and Adjustment ₹69.3K. * Top loss categories: Apparel & Lifestyle ₹20.6K (18%), Whey Protein (Protein & Nutrition) ₹16.0K (14%), Pet Care ₹12.0K (11%), Sports & Fitness (Toys & Sports) ₹10.2K (9%), Home Needs ₹8.9K (8%). Share is of ₹1.13L net loss across loss-making categories. * Loss is spread across 706 SKUs and the top 10 make 15% of SKU-level loss. * Theft-prone SKUs show net loss of ₹16.5K, led by whey ₹15.0K, chargers ₹567 and deos ₹567. * DHM adherence gap and SBC completion pending. * LSS racks over capacity, pickers unable to locate stock in aisle. * SLP theft investigation: ₹15,000 recovery. | T2: 150000 | U2: P,J | V2: 36994
A3: 46303 | B3: South1 | C3: Bengaluru | D3: BLR-RICHMOND TOWN SS | E3: {=IF(D3="","",IFERROR(INDEX('CLM & IM Mapping'!$B$2:$B$270,MATCH(TRIM(D3),'CLM & IM Mapping'!$A$2:$A$270,0)),"Not Mapped"))} -> Arun Raj | F3: {=IF(D3="","",IFERROR(INDEX('CLM & IM Mapping'!$C$2:$C$270,MATCH(TRIM(D3),'CLM & IM Mapping'!$A$2:$A$270,0)),"Not Mapped"))} -> Simon Manoharan | G3: SUPERSTORE | H3: 18075 | I3: 115931 | J3: -13909 | K3: 463 | L3: 14666 | M3: 0 | N3: 0 | O3: 0 | P3: 135225 | Q3: SLP investigation is ongoing. | S3: * Total IH loss is ₹1.35L, mainly from FCC bin ₹1.16L, Adjustment ₹18.1K and RTO loss ₹14.7K. * Majority impact is from FCC bin of ₹1.16L. Excluding this, the store is ₹19.3K in loss. * Top loss categories: Apparel & Lifestyle ₹48.3K (39%), Home Needs ₹25.6K (21%), Electronics & Appliances ₹9.0K (7%), Toys & Sports ₹8.8K (7%), Plant & Vegan Protein (Protein & Nutrition) ₹7.2K (6%). Share is of ₹1.25L net loss across loss-making categories. * Loss is spread across 657 SKUs and the top 10 make 11% of SKU-level loss. * Theft-prone SKUs show net loss of ₹18.8K, led by whey ₹3.7K, earphones ₹3.4K and speakers ₹3.0K. * Stock movement is in progress for the 1st floor expansion; aisle I has been fully moved to the 2nd floor. * SLP investigation is ongoing; wrong adjustments have been identified. | T3: 100000 | U3: I,A | V3: 48268
A4: 46303 | B4: South1 | C4: Bengaluru | D4: BLR-Mathikere | E4: {=IF(D4="","",IFERROR(INDEX('CLM & IM Mapping'!$B$2:$B$270,MATCH(TRIM(D4),'CLM & IM Mapping'!$A$2:$A$270,0)),"Not Mapped"))} -> Manoj Kj | F4: {=IF(D4="","",IFERROR(INDEX('CLM & IM Mapping'!$C$2:$C$270,MATCH(TRIM(D4),'CLM & IM Mapping'!$A$2:$A$270,0)),"Not Mapped"))} -> Srittam Dhal | G4: RETAIL_STORE | H4: -82711 | I4: 0 | J4: 0 | K4: 191944 | L4: 0 | M4: 0 | N4: 0 | O4: 1470 | P4: 110703 | Q4: Shrinkage Loss - BLR-Mathikere - Immediate Action Required | R4: 25000 | S4: DHM adherence issues have been observed, and SBC was not 100% completed in the month of August. For these short picks, a mail was raised to the SLP team for investigation, and a squad has also been deployed for recovery. Last month, due to an MP issue, all LC1 packers incorrectly did the putaway after the store closed. During picking, the items went into recirculation, and the STO associate marked them as short picks. This issue was identified during the theft investigation, resulting in a recovery of ₹25,000. The maximum loss is due to damaged stock; the team marked 10 to 20 crates as short picks. | T4: 30000 | U4: K | V4: 35
A5: 46303 | B5: South1 | C5: Bengaluru | D5: BLR-SHIVAJI NAGAR Network | E5: {=IF(D5="","",IFERROR(INDEX('CLM & IM Mapping'!$B$2:$B$270,MATCH(TRIM(D5),'CLM & IM Mapping'!$A$2:$A$270,0)),"Not Mapped"))} -> Vijay M | F5: {=IF(D5="","",IFERROR(INDEX('CLM & IM Mapping'!$C$2:$C$270,MATCH(TRIM(D5),'CLM & IM Mapping'!$A$2:$A$270,0)),"Not Mapped"))} -> Kantha Kumar | G5: RETAIL_STORE | H5: 39978 | I5: 61074 | J5: 219 | K5: 451 | L5: 1542 | M5: 0 | N5: 1737 | O5: 0 | P5: 105001 | Q5: Wrong putaway incidents were identified during the last month, with suspected theft involvement. The matter has been escalated to the SLP team, and the investigation is currently in progress. | S5: Wrong putaway incidents were identified during the last month, with suspected theft involvement. The matter has been escalated to the SLP team, and the investigation is currently in progress. | T5: 50000 | U5: A,B | V5: 45816
A6: 46303 | B6: South1 | C6: Bengaluru | D6: BLR-Dooravani Nagar | E6: {=IF(D6="","",IFERROR(INDEX('CLM & IM Mapping'!$B$2:$B$270,MATCH(TRIM(D6),'CLM & IM Mapping'!$A$2:$A$270,0)),"Not Mapped"))} -> Rizwan Ahmed | F6: {=IF(D6="","",IFERROR(INDEX('CLM & IM Mapping'!$C$2:$C$270,MATCH(TRIM(D6),'CLM & IM Mapping'!$A$2:$A$270,0)),"Not Mapped"))} -> Un Mapped | G6: RETAIL_STORE | H6: 22334 | I6: 66087 | J6: 0 | K6: 731 | L6: 763 | M6: 0 | N6: 4541 | O6: 0 | P6: 94456 | S6: * Total IH loss is ₹94.5K, mainly from FCC bin ₹66.1K and Adjustment ₹22.3K. * Majority impact is from FCC bin of ₹66.1K. Excluding this, the store is ₹28.4K in loss. * Top loss categories: Dairy, Bread & Eggs ₹10.4K (14%), Cold Drinks & Juices ₹8.2K (11%), Frozen Food ₹6.7K (9%), Munchies ₹5.8K (8%), Creatine (Protein & Nutrition) ₹4.0K (6%). Share is of ₹72.1K net loss across loss-making categories. * Loss is spread across 1315 SKUs and the top 10 make 8% of SKU-level loss. * Theft-prone SKUs show net loss of ₹4.7K, led by creatine ₹2.1K, condoms ₹1.2K and serums ₹604. * Aisles A and I hold ₹54.0K, 57% of bin-level loss. | U6: A,E | V6: 61440
A7: 46303 | B7: South1 | C7: Bengaluru | D7: BLR-Kalkere | E7: {=IF(D7="","",IFERROR(INDEX('CLM & IM Mapping'!$B$2:$B$270,MATCH(TRIM(D7),'CLM & IM Mapping'!$A$2:$A$270,0)),"Not Mapped"))} -> Rizwan Ahmed | F7: {=IF(D7="","",IFERROR(INDEX('CLM & IM Mapping'!$C$2:$C$270,MATCH(TRIM(D7),'CLM & IM Mapping'!$A$2:$A$270,0)),"Not Mapped"))} -> Un Mapped | G7: RETAIL_STORE | H7: 71595 | I7: 9181 | J7: 0 | K7: 360 | L7: 87 | M7: 0 | N7: 1957 | O7: 0 | P7: 83180 | S7: * Total IH loss is ₹83.2K, mainly from Adjustment ₹71.6K and FCC bin ₹9.2K. * Top loss categories: Rice & More (Atta, Rice, Oil & Dals) ₹15.2K (17%), Cleaning Essentials ₹11.1K (13%), Cups (Ice Creams & More) ₹8.6K (10%), Dairy, Bread & Eggs ₹7.6K (9%), Home Needs ₹7.3K (8%). Share is of ₹88.3K net loss across loss-making categories. * Loss is spread across 1035 SKUs and the top 10 make 13% of SKU-level loss. * Theft-prone SKUs show net loss of ₹7.6K, led by dry fruits & nuts ₹3.2K, cigarettes ₹1.7K and premium chocolates ₹862. | U7: I,C | V7: 16676
A8: 46303 | B8: South1 | C8: Bengaluru | D8: BLR-HSR-3 | E8: {=IF(D8="","",IFERROR(INDEX('CLM & IM Mapping'!$B$2:$B$270,MATCH(TRIM(D8),'CLM & IM Mapping'!$A$2:$A$270,0)),"Not Mapped"))} -> Saddam Hussain | F8: {=IF(D8="","",IFERROR(INDEX('CLM & IM Mapping'!$C$2:$C$270,MATCH(TRIM(D8),'CLM & IM Mapping'!$A$2:$A$270,0)),"Not Mapped"))} -> Un Mapped | G8: RETAIL_STORE | H8: 15940 | I8: 42998 | J8: 1688 | K8: 2605 | L8: 3932 | M8: 0 | N8: 680 | O8: 0 | P8: 67844 | S8: * Total IH loss is ₹67.8K, mainly from FCC bin ₹43.0K and Adjustment ₹15.9K. * Majority impact is from FCC bin of ₹43.0K. Excluding this, the store is ₹24.8K in loss. * Top loss categories: Ice Creams & More ₹19.4K (27%), Cold Drinks & Juices ₹10.8K (15%), Dry Fruits & Nuts (Masala, Dry Fruits & More) ₹9.9K (14%), Chips & Crisps (Munchies) ₹6.5K (9%), Detergent Powder & Bars (Cleaning Essentials) ₹5.8K (8%). Share is of ₹71.0K net loss across loss-making categories. * Loss is spread across 1299 SKUs and the top 10 make 11% of SKU-level loss. * Theft-prone SKUs show net loss of ₹10.7K, led by dry fruits & nuts ₹7.5K, cigarettes ₹1.7K and creatine ₹567. * Aisles H and B hold ₹27.6K, 58% of bin-level loss. | U8: A,I | V8: 41543
A9: 46303 | B9: South1 | C9: Bengaluru | D9: BLR-Malleshwaram SS | E9: {=IF(D9="","",IFERROR(INDEX('CLM & IM Mapping'!$B$2:$B$270,MATCH(TRIM(D9),'CLM & IM Mapping'!$A$2:$A$270,0)),"Not Mapped"))} -> Arun Raj | F9: {=IF(D9="","",IFERROR(INDEX('CLM & IM Mapping'!$C$2:$C$270,MATCH(TRIM(D9),'CLM & IM Mapping'!$A$2:$A$270,0)),"Not Mapped"))} -> Simon Manoharan | G9: SUPERSTORE | H9: 19452 | I9: 38867 | J9: 0 | K9: 0 | L9: 530 | M9: 0 | N9: 37 | O9: 0 | P9: 58886 | S9: Due to a delta of 7 MP, the store was only 50% audited last month. A squad team is currently deployed at the store to close the W2W audit. As per the SSM, all stocks are available at the store and will be recovered once the W2W audit is closed. | T9: 50000 | U9: I,G | V9: 18584
A10: 46303 | B10: South1 | C10: Bengaluru | D10: BLR-BASAVANAPURA NETWORK 2 | E10: {=IF(D10="","",IFERROR(INDEX('CLM & IM Mapping'!$B$2:$B$270,MATCH(TRIM(D10),'CLM & IM Mapping'!$A$2:$A$270,0)),"Not Mapped"))} -> Richard Harris | F10: {=IF(D10="","",IFERROR(INDEX('CLM & IM Mapping'!$C$2:$C$270,MATCH(TRIM(D10),'CLM & IM Mapping'!$A$2:$A$270,0)),"Not Mapped"))} -> Kantha Kumar | G10: RETAIL_STORE | H10: 41355 | I10: 12847 | J10: 226 | K10: 2374 | L10: 948 | M10: 0 | N10: 0 | O10: 0 | P10: 57750 | S10: DHM adherence issues have been observed, and proper SBC completion is still pending. To strengthen inventory accuracy and identify process gaps, a W2W audit is currently being conducted by the Squad Team. | T10: 40000 | U10: K,A | V10: 31906
A11: 46303 | B11: South1 | C11: Bengaluru | D11: BLR-Mico layout New | E11: {=IF(D11="","",IFERROR(INDEX('CLM & IM Mapping'!$B$2:$B$270,MATCH(TRIM(D11),'CLM & IM Mapping'!$A$2:$A$270,0)),"Not Mapped"))} -> Keshav G | F11: {=IF(D11="","",IFERROR(INDEX('CLM & IM Mapping'!$C$2:$C$270,MATCH(TRIM(D11),'CLM & IM Mapping'!$A$2:$A$270,0)),"Not Mapped"))} -> Un Mapped | G11: RETAIL_STORE | H11: 5817 | I11: 29841 | J11: 0 | K11: 1403 | L11: 3816 | M11: 0 | N11: 0 | O11: 13273 | P11: 54150 | S11: * Total IH loss is ₹54.1K, mainly from FCC bin ₹29.8K, PO cancel ₹13.3K and Adjustment ₹5.8K. * Top loss categories: Dairy, Bread & Eggs ₹12.0K (22%), Fruits & Vegetables ₹7.4K (14%), Ice Creams & More ₹6.0K (11%), Medical Devices (Pharma & Wellness) ₹4.1K (8%), Baking Mixes & Ingredients (Packaged Food) ₹3.3K (6%). Share is of ₹53.4K net loss across loss-making categories. * Loss is spread across 681 SKUs and the top 10 make 16% of SKU-level loss. * Aisles L and A hold ₹22.5K, 54% of bin-level loss. | U11: J,A | V11: 23909
A12: 46303 | B12: South1 | C12: Bengaluru | D12: BLR-HSR Layout New | E12: {=IF(D12="","",IFERROR(INDEX('CLM & IM Mapping'!$B$2:$B$270,MATCH(TRIM(D12),'CLM & IM Mapping'!$A$2:$A$270,0)),"Not Mapped"))} -> Saddam Hussain | F12: {=IF(D12="","",IFERROR(INDEX('CLM & IM Mapping'!$C$2:$C$270,MATCH(TRIM(D12),'CLM & IM Mapping'!$A$2:$A$270,0)),"Not Mapped"))} -> Un Mapped | G12: RETAIL_STORE | H12: 20452 | I12: 23732 | J12: 0 | K12: 7696 | L12: 584 | M12: 0 | N12: 1629 | O12: 0 | P12: 54093 | S12: * Total IH loss is ₹54.1K, mainly from FCC bin ₹23.7K, Adjustment ₹20.5K and Shortpick ₹7.7K. * Top loss categories: Whey Protein (Protein & Nutrition) ₹7.0K (15%), Kitchen Appliances (Electronics & Appliances) ₹6.4K (14%), Cold Drinks & Juices ₹5.2K (11%), Rice & More (Atta, Rice, Oil & Dals) ₹3.9K (9%), Frozen Food ₹3.8K (8%). Share is of ₹45.6K net loss across loss-making categories. * Loss is spread across 546 SKUs and the top 10 make 27% of SKU-level loss. * Theft-prone SKUs show net loss of ₹9.6K, led by whey ₹7.6K, premium chocolates ₹1.6K and cigarettes ₹475. | U12: J,K | V12: 17533
A13: 46303 | B13: South1 | C13: Bengaluru | D13: BLR-Siddapura | E13: {=IF(D13="","",IFERROR(INDEX('CLM & IM Mapping'!$B$2:$B$270,MATCH(TRIM(D13),'CLM & IM Mapping'!$A$2:$A$270,0)),"Not Mapped"))} -> Basil Scariya | F13: {=IF(D13="","",IFERROR(INDEX('CLM & IM Mapping'!$C$2:$C$270,MATCH(TRIM(D13),'CLM & IM Mapping'!$A$2:$A$270,0)),"Not Mapped"))} -> Prakash BS | G13: RETAIL_STORE | H13: 37013 | I13: 13720 | J13: 0 | K13: 0 | L13: 69 | M13: 0 | N13: 1350 | O13: 0 | P13: 52152 | S13: SBC is still in progress, and the store team is focusing on W2W today against the ₹15K target. This amount will be recovered without fail, and the remaining amount will be recovered by the 11th. | T13: 40000 | U13: D,C | V13: 36339
A14: 46303 | B14: South1 | C14: Bengaluru | D14: BLR-Narayanapura | E14: {=IF(D14="","",IFERROR(INDEX('CLM & IM Mapping'!$B$2:$B$270,MATCH(TRIM(D14),'CLM & IM Mapping'!$A$2:$A$270,0)),"Not Mapped"))} -> Adhavan Subramani | F14: {=IF(D14="","",IFERROR(INDEX('CLM & IM Mapping'!$C$2:$C$270,MATCH(TRIM(D14),'CLM & IM Mapping'!$A$2:$A$270,0)),"Not Mapped"))} -> Mohammed Akbar | G14: RETAIL_STORE | H14: 16761 | I14: 27598 | J14: 0 | K14: 5808 | L14: 1603 | M14: 0 | N14: 0 | O14: 0 | P14: 51771 | S14: High FC was primarily due to wrong putaway, which resulted in stock being misplaced across different bins and led to shrinkage in the high FC bucket. SBC was not happening due to a delta of 3 CCAs. A squad has been aligned for recovery. | T14: 40000 | U14: I,J | V14: 28906
A15: 46303 | B15: South1 | C15: Bengaluru | D15: BLR-Challakere | E15: {=IF(D15="","",IFERROR(INDEX('CLM & IM Mapping'!$B$2:$B$270,MATCH(TRIM(D15),'CLM & IM Mapping'!$A$2:$A$270,0)),"Not Mapped"))} -> Girish N | F15: {=IF(D15="","",IFERROR(INDEX('CLM & IM Mapping'!$C$2:$C$270,MATCH(TRIM(D15),'CLM & IM Mapping'!$A$2:$A$270,0)),"Not Mapped"))} -> Un Mapped | G15: RETAIL_STORE | H15: 34189 | I15: 13467 | J15: 1279 | K15: 0 | L15: 541 | M15: 0 | N15: 21 | O15: 0 | P15: 49497 | S15: * Total IH loss is ₹49.5K, mainly from Adjustment ₹34.2K and FCC bin ₹13.5K. * Top loss categories: Chocolates (Sweet Cravings) ₹10.9K (25%), Ice Creams & More ₹8.3K (19%), Atta, Rice, Oil & Dals ₹6.7K (15%), Chips & Crisps (Munchies) ₹4.0K (9%), Fruits & Vegetables ₹2.9K (7%). Share is of ₹43.6K net loss across loss-making categories. * Loss is spread across 808 SKUs and the top 10 make 15% of SKU-level loss. * Theft-prone SKUs show net loss of ₹7.2K, led by premium chocolates ₹4.4K, dry fruits & nuts ₹1.6K and earphones ₹1.0K. * Aisles J and K hold ₹17.0K, 59% of bin-level loss. | U15: J,K | V15: 20482
A16: 46303 | B16: South1 | C16: Bengaluru | D16: BLR-Banjara Layout | E16: {=IF(D16="","",IFERROR(INDEX('CLM & IM Mapping'!$B$2:$B$270,MATCH(TRIM(D16),'CLM & IM Mapping'!$A$2:$A$270,0)),"Not Mapped"))} -> Rizwan Ahmed | F16: {=IF(D16="","",IFERROR(INDEX('CLM & IM Mapping'!$C$2:$C$270,MATCH(TRIM(D16),'CLM & IM Mapping'!$A$2:$A$270,0)),"Not Mapped"))} -> Un Mapped | G16: RETAIL_STORE | H16: 31101 | I16: 16912 | J16: 235 | K16: 28 | L16: 595 | M16: 0 | N16: 0 | O16: 0 | P16: 48871 | S16: * Total IH loss is ₹48.9K, mainly from Adjustment ₹31.1K and FCC bin ₹16.9K. * Top loss categories: Ice Creams & More ₹21.3K (30%), Frozen Food ₹20.2K (29%), Dairy, Bread & Eggs ₹9.8K (14%), Fresh Vegetables (Fruits & Vegetables) ₹7.0K (10%), Chicken (Meats, Fish & Eggs) ₹2.6K (4%). Share is of ₹70.4K net loss across loss-making categories. * Loss is spread across 1028 SKUs and the top 10 make 11% of SKU-level loss. * Theft-prone SKUs show net loss of ₹2.4K, led by cigarettes ₹1.7K and premium chocolates ₹769. * Aisles M and L hold ₹56.3K, 90% of bin-level loss. | U16: L,P | V16: 11018
A17: 46303 | B17: South1 | C17: Bengaluru | D17: BLR-Vijay Nagar Network | E17: {=IF(D17="","",IFERROR(INDEX('CLM & IM Mapping'!$B$2:$B$270,MATCH(TRIM(D17),'CLM & IM Mapping'!$A$2:$A$270,0)),"Not Mapped"))} -> Narasimhamurthy R | F17: {=IF(D17="","",IFERROR(INDEX('CLM & IM Mapping'!$C$2:$C$270,MATCH(TRIM(D17),'CLM & IM Mapping'!$A$2:$A$270,0)),"Not Mapped"))} -> Kishor K | G17: RETAIL_STORE | H17: 26779 | I17: 20348 | J17: 0 | K17: 1436 | L17: 101 | M17: 0 | N17: 0 | O17: 0 | P17: 48665 | S17: The W2W audit is in progress. Assortment and capacity have breached more than 100%, due to which item fall-down cases are increasing and floor handover is not being done properly. Wrong putaway was also done in the store. The SI and one CCA have now been aligned for recovery. | T17: 40000 | U17: A,G | V17: 29310
A18: 46303 | B18: South1 | C18: Bengaluru | D18: BLR-Malleshpalya | E18: {=IF(D18="","",IFERROR(INDEX('CLM & IM Mapping'!$B$2:$B$270,MATCH(TRIM(D18),'CLM & IM Mapping'!$A$2:$A$270,0)),"Not Mapped"))} -> Silambarasan E | F18: {=IF(D18="","",IFERROR(INDEX('CLM & IM Mapping'!$C$2:$C$270,MATCH(TRIM(D18),'CLM & IM Mapping'!$A$2:$A$270,0)),"Not Mapped"))} -> Arivind S | G18: RETAIL_STORE | H18: 44009 | I18: 4060 | J18: 0 | K18: 0 | L18: 190 | M18: 0 | N18: 0 | O18: 0 | P18: 48259 | Q18: BLR-Malleshpalya Shrinkage – 2026-10-05 | S18: The store has been converted from FOCO to COCO; a wall-to-wall (W2W) audit was done for the handover. | U18: L,M | V18: 15781
A19: 46303 | B19: South1 | C19: Bengaluru | D19: BLR-Doddakannelli | E19: {=IF(D19="","",IFERROR(INDEX('CLM & IM Mapping'!$B$2:$B$270,MATCH(TRIM(D19),'CLM & IM Mapping'!$A$2:$A$270,0)),"Not Mapped"))} -> Sundaresh S | F19: {=IF(D19="","",IFERROR(INDEX('CLM & IM Mapping'!$C$2:$C$270,MATCH(TRIM(D19),'CLM & IM Mapping'!$A$2:$A$270,0)),"Not Mapped"))} -> Un Mapped | G19: RETAIL_STORE | H19: 15241 | I19: 17511 | J19: 0 | K19: 651 | L19: 1730 | M19: 0 | N19: 12084 | O19: 0 | P19: 47218 | S19: * Total IH loss is ₹47.2K, mainly from FCC bin ₹17.5K, Adjustment ₹15.2K and STO short receipt ₹12.1K. * SKU-level net is ₹2.0K, under 10% of IH loss, so the gap is not category driven and sits in FCC bin. * Theft-prone SKUs show net loss of ₹3.3K, led by dry fruits & nuts ₹2.0K, perfumes ₹983 and cigarettes ₹359. * Aisles E and K hold ₹18.8K, 58% of bin-level loss. | U19: E,C | V19: 21608
A20: 46303 | B20: South1 | C20: Bengaluru | D20: BLR-Murugeshpalya | E20: {=IF(D20="","",IFERROR(INDEX('CLM & IM Mapping'!$B$2:$B$270,MATCH(TRIM(D20),'CLM & IM Mapping'!$A$2:$A$270,0)),"Not Mapped"))} -> Keshav G | F20: {=IF(D20="","",IFERROR(INDEX('CLM & IM Mapping'!$C$2:$C$270,MATCH(TRIM(D20),'CLM & IM Mapping'!$A$2:$A$270,0)),"Not Mapped"))} -> Mohammed Akbar | G20: RETAIL_STORE | H20: 9409 | I20: 27235 | J20: 0 | K20: 235 | L20: 6731 | M20: 0 | N20: 3486 | O20: 0 | P20: 47094 | S20: DHM & SI monitoring issue at the store: despite stock being available in primary bins, items were marked FC by packers, and SS RTO is not being cleared on time. A permanent squad has been deployed for recovery in high-FC aisles; out of ₹80K, ₹40K was recovered yesterday. | T20: 40000 | U20: AI,G | V20: 25002
A21: 46303 | B21: South1 | C21: Bengaluru | D21: BLR-Kudlu | E21: {=IF(D21="","",IFERROR(INDEX('CLM & IM Mapping'!$B$2:$B$270,MATCH(TRIM(D21),'CLM & IM Mapping'!$A$2:$A$270,0)),"Not Mapped"))} -> Raghavendra Vernekar | F21: {=IF(D21="","",IFERROR(INDEX('CLM & IM Mapping'!$C$2:$C$270,MATCH(TRIM(D21),'CLM & IM Mapping'!$A$2:$A$270,0)),"Not Mapped"))} -> Prakash BS | G21: RETAIL_STORE | H21: 27603 | I21: 14083 | J21: 0 | K21: 3884 | L21: 804 | M21: 0 | N21: 0 | O21: 0 | P21: 46374 | S21: W2W audit is in progress; around ₹15,000 will be recovered, and all losses will be recovered by the 11th. | T21: 40000 | U21: C,I | V21: 31277
A22: 46303 | B22: South1 | C22: Bengaluru | D22: BLR-Bommanahalli | E22: {=IF(D22="","",IFERROR(INDEX('CLM & IM Mapping'!$B$2:$B$270,MATCH(TRIM(D22),'CLM & IM Mapping'!$A$2:$A$270,0)),"Not Mapped"))} -> Raghavendra Vernekar | F22: {=IF(D22="","",IFERROR(INDEX('CLM & IM Mapping'!$C$2:$C$270,MATCH(TRIM(D22),'CLM & IM Mapping'!$A$2:$A$270,0)),"Not Mapped"))} -> Prakash BS | G22: RETAIL_STORE | H22: 201 | I22: 2037 | J22: 0 | K22: 0 | L22: 170 | M22: 0 | N22: 41386 | O22: 0 | P22: 43795 | S22: Stock from Mathikere was not dispatched as per the SOP; the major bucket is from STO putaway due. DHM is validating the stores, and the stock will be recovered by EOD today. | T22: 43000 | U22: R,Q | V22: 4747
A23: 46303 | B23: South1 | C23: Bengaluru | D23: BLR-Electronic city network | E23: {=IF(D23="","",IFERROR(INDEX('CLM & IM Mapping'!$B$2:$B$270,MATCH(TRIM(D23),'CLM & IM Mapping'!$A$2:$A$270,0)),"Not Mapped"))} -> Balaji G | F23: {=IF(D23="","",IFERROR(INDEX('CLM & IM Mapping'!$C$2:$C$270,MATCH(TRIM(D23),'CLM & IM Mapping'!$A$2:$A$270,0)),"Not Mapped"))} -> Mohammed Akbar | G23: RETAIL_STORE | H23: 3171 | I23: 31819 | J23: 2882 | K23: 3955 | L23: 1745 | M23: 0 | N23: 0 | O23: 0 | P23: 43571 | S23: Due to a wrong putaway issue in the frozen section, most SKUs are stacked in deep bins. Blind spots in the milk room have led to identified munching of chocolates, ice cream and chips. Squad has been deployed for recovery in high-FC aisles. | T23: 40000 | U23: I,J | V23: 31810
A24: 46303 | B24: South1 | C24: Bengaluru | D24: BLR-Sattava East | E24: {=IF(D24="","",IFERROR(INDEX('CLM & IM Mapping'!$B$2:$B$270,MATCH(TRIM(D24),'CLM & IM Mapping'!$A$2:$A$270,0)),"Not Mapped"))} -> Ashwath S | F24: {=IF(D24="","",IFERROR(INDEX('CLM & IM Mapping'!$C$2:$C$270,MATCH(TRIM(D24),'CLM & IM Mapping'!$A$2:$A$270,0)),"Not Mapped"))} -> Kantha Kumar | G24: RETAIL_STORE | H24: 33628 | I24: 9141 | J24: 0 | K24: 0 | L24: 243 | M24: 0 | N24: 0 | O24: 0 | P24: 43012 | S24: The W2W audit is currently in progress. Excess stock has been identified at the store and is being reviewed as part of the ongoing audit to identify the root cause and the required corrective actions. | T24: 40000 | U24: H,B | V24: 20793
A25: 46303 | B25: South1 | C25: Bengaluru | D25: BLR-Kadarenahalli | E25: {=IF(D25="","",IFERROR(INDEX('CLM & IM Mapping'!$B$2:$B$270,MATCH(TRIM(D25),'CLM & IM Mapping'!$A$2:$A$270,0)),"Not Mapped"))} -> Raghavendra Vernekar | F25: {=IF(D25="","",IFERROR(INDEX('CLM & IM Mapping'!$C$2:$C$270,MATCH(TRIM(D25),'CLM & IM Mapping'!$A$2:$A$270,0)),"Not Mapped"))} -> Prakash BS | G25: RETAIL_STORE | H25: -18636 | I25: 26089 | J25: 0 | K25: 228 | L25: 237 | M25: 0 | N25: 2148 | O25: 32886 | P25: 42952 | S25: DHM adherence and monitoring issue. Recirculation stock was picked and sent to the MH without being dispatched in the system; due to this, the recirculation was cancelled and the same loss is reflecting in shrinkage. | T25: 30000 | U25: C,H | V25: 17465
A26: 46303 | B26: South1 | C26: Bengaluru | D26: BLR-Marathahalli-3 | E26: {=IF(D26="","",IFERROR(INDEX('CLM & IM Mapping'!$B$2:$B$270,MATCH(TRIM(D26),'CLM & IM Mapping'!$A$2:$A$270,0)),"Not Mapped"))} -> Sundaresh S | F26: {=IF(D26="","",IFERROR(INDEX('CLM & IM Mapping'!$C$2:$C$270,MATCH(TRIM(D26),'CLM & IM Mapping'!$A$2:$A$270,0)),"Not Mapped"))} -> Un Mapped | G26: RETAIL_STORE | H26: 23680 | I26: 12580 | J26: 38 | K26: 5740 | L26: 746 | M26: 0 | N26: 0 | O26: 0 | P26: 42783 | S26: * Total IH loss is ₹42.8K, mainly from Adjustment ₹23.7K, FCC bin ₹12.6K and Shortpick ₹5.7K. * SKU-level net is a gain of ₹138, under 10% of IH loss, so the gap is not category driven and sits in FCC bin. * Theft-prone SKUs show net loss of ₹8.8K, led by whey ₹8.7K, cigars ₹71 and perfumes ₹64. * Aisles C and H hold ₹36.0K, 63% of bin-level loss. | U26: H,C | V26: 36506
A27: 46303 | B27: South1 | C27: Bengaluru | D27: BLR-Jakkur Network | E27: {=IF(D27="","",IFERROR(INDEX('CLM & IM Mapping'!$B$2:$B$270,MATCH(TRIM(D27),'CLM & IM Mapping'!$A$2:$A$270,0)),"Not Mapped"))} -> Girish N | F27: {=IF(D27="","",IFERROR(INDEX('CLM & IM Mapping'!$C$2:$C$270,MATCH(TRIM(D27),'CLM & IM Mapping'!$A$2:$A$270,0)),"Not Mapped"))} -> Un Mapped | G27: RETAIL_STORE | H27: 29680 | I27: 9315 | J27: 0 | K27: 3498 | L27: 283 | M27: 0 | N27: 0 | O27: 0 | P27: 42776 | S27: * Total IH loss is ₹42.8K, mainly from Adjustment ₹29.7K and FCC bin ₹9.3K. * Top loss categories: Atta, Rice, Oil & Dals ₹7.2K (16%), Fresh Vegetables (Fruits & Vegetables) ₹6.3K (14%), Muesli & Oats (Breakfast & Sauces) ₹5.4K (12%), Munchies ₹4.3K (10%), Cold Drinks & Juices ₹4.1K (9%). Share is of ₹44.0K net loss across loss-making categories. * Loss is spread across 567 SKUs and the top 10 make 15% of SKU-level loss. * Theft-prone SKUs show net loss of ₹5.1K, led by dry fruits & nuts ₹3.4K, whey ₹1.2K and pre-workout ₹386. * Aisles A and B hold ₹30.1K, 72% of bin-level loss. | U27: A,B | V27: 24298
A28: 46303 | B28: South1 | C28: Bengaluru | D28: BLR-Thyagaraja Nagar | E28: {=IF(D28="","",IFERROR(INDEX('CLM & IM Mapping'!$B$2:$B$270,MATCH(TRIM(D28),'CLM & IM Mapping'!$A$2:$A$270,0)),"Not Mapped"))} -> Suhas N | F28: {=IF(D28="","",IFERROR(INDEX('CLM & IM Mapping'!$C$2:$C$270,MATCH(TRIM(D28),'CLM & IM Mapping'!$A$2:$A$270,0)),"Not Mapped"))} -> Aravind S | G28: RETAIL_STORE | H28: 29203 | I28: 9567 | J28: 0 | K28: 778 | L28: 2992 | M28: 0 | N28: 0 | O28: 0 | P28: 42540 | Q28: Salary hold request – theft investigation and recovery // BLR-Thyagaraja Nagar // & Stock adjustment request – theft case // BLR-Thyagaraja Nagar. | R28: 18000+30000=48000 | S28: Store mass theft involvement identified. **SLP investigation has been completed, and the IR is pending.** | T28: Nil | U28: E,I | V28: 20194
A29: 46303 | B29: South1 | C29: Bengaluru | D29: BLR-VIJAY NAGAR | E29: {=IF(D29="","",IFERROR(INDEX('CLM & IM Mapping'!$B$2:$B$270,MATCH(TRIM(D29),'CLM & IM Mapping'!$A$2:$A$270,0)),"Not Mapped"))} -> Narasimhamurthy R | F29: {=IF(D29="","",IFERROR(INDEX('CLM & IM Mapping'!$C$2:$C$270,MATCH(TRIM(D29),'CLM & IM Mapping'!$A$2:$A$270,0)),"Not Mapped"))} -> Kishor K | G29: RETAIL_STORE | H29: 16668 | I29: 23989 | J29: 0 | K29: 0 | L29: 843 | M29: 0 | N29: 0 | O29: 0 | P29: 41500 | S29: Assortment and capacity have been breached by more than 100%. Floor handover is not being done properly, and stock-fall cases are high due to the mini store. There is also a DHM and SI monitoring gap. The store had a CCA delta; 3 CCAs have now been hired. | T29: 40000 | U29: O,D | V29: 15143
A30: 46303 | B30: South1 | C30: Bengaluru | D30: BLR-Nikoo Home New | E30: {=IF(D30="","",IFERROR(INDEX('CLM & IM Mapping'!$B$2:$B$270,MATCH(TRIM(D30),'CLM & IM Mapping'!$A$2:$A$270,0)),"Not Mapped"))} -> Adhavan Subramani | F30: {=IF(D30="","",IFERROR(INDEX('CLM & IM Mapping'!$C$2:$C$270,MATCH(TRIM(D30),'CLM & IM Mapping'!$A$2:$A$270,0)),"Not Mapped"))} -> Mohammed Akbar | G30: RETAIL_STORE | H30: 27933 | I30: 6780 | J30: 0 | K30: 3921 | L30: 2264 | M30: 0 | N30: 180 | O30: 248 | P30: 41326 | Q30: ₹6K recovered by SLP from the packer. | R30: 6000 | S30: Putaway error by LC1 IBAs in the freezer. The freezer audit has been completed today: 4 HV crates are available in the store and are being added back to inventory, plus a ₹6K theft case. | T30: 34000 | U30: F,H | V30: 16179
A31: 46303 | B31: South1 | C31: Bengaluru | D31: BLR-Kogilu Road | E31: {=IF(D31="","",IFERROR(INDEX('CLM & IM Mapping'!$B$2:$B$270,MATCH(TRIM(D31),'CLM & IM Mapping'!$A$2:$A$270,0)),"Not Mapped"))} -> Adhavan Subramani | F31: {=IF(D31="","",IFERROR(INDEX('CLM & IM Mapping'!$C$2:$C$270,MATCH(TRIM(D31),'CLM & IM Mapping'!$A$2:$A$270,0)),"Not Mapped"))} -> Mohammed Akbar | G31: RETAIL_STORE | H31: 30178 | I31: 6153 | J31: 0 | K31: 3968 | L31: 810 | M31: 0 | N31: 0 | O31: 0 | P31: 41109 | S31: Chiller and freezer audit has been closed; 8 crates are available. 2 CCAs have been aligned, and stock is being added back to inventory today. | T31: 40000 | U31: K,A | V31: 28949
A32: 46303 | B32: South1 | C32: Bengaluru | D32: BLR-INDIRANAGAR NEW | E32: {=IF(D32="","",IFERROR(INDEX('CLM & IM Mapping'!$B$2:$B$270,MATCH(TRIM(D32),'CLM & IM Mapping'!$A$2:$A$270,0)),"Not Mapped"))} -> Balaji G | F32: {=IF(D32="","",IFERROR(INDEX('CLM & IM Mapping'!$C$2:$C$270,MATCH(TRIM(D32),'CLM & IM Mapping'!$A$2:$A$270,0)),"Not Mapped"))} -> Mohammed Akbar | G32: RETAIL_STORE | H32: 29057 | I32: 9676 | J32: 340 | K32: 395 | L32: 773 | M32: 0 | N32: 0 | O32: 0 | P32: 40242 | S32: F&V adjustment appears high in FnV, done by QA without DHM knowledge; 2 QA associates have been removed. A permanent squad has been deployed along with CCAs for recovery through CC. | T32: 40000 | U32: J,M | V32: 14773
A33: 46303 | B33: South1 | C33: Bengaluru | D33: BLR-CV RAMAN NAGAR NEW | E33: {=IF(D33="","",IFERROR(INDEX('CLM & IM Mapping'!$B$2:$B$270,MATCH(TRIM(D33),'CLM & IM Mapping'!$A$2:$A$270,0)),"Not Mapped"))} -> Silambarasan E | F33: {=IF(D33="","",IFERROR(INDEX('CLM & IM Mapping'!$C$2:$C$270,MATCH(TRIM(D33),'CLM & IM Mapping'!$A$2:$A$270,0)),"Not Mapped"))} -> Arivind S | G33: RETAIL_STORE | H33: 13995 | I33: 11558 | J33: 415 | K33: 828 | L33: 1365 | M33: 0 | N33: 2031 | O33: 9909 | P33: 40101 | S33: * Total IH loss is ₹40.1K, mainly from Adjustment ₹14.0K, FCC bin ₹11.6K and PO cancel ₹9.9K. * Top loss categories: Fruits & Vegetables ₹15.0K (41%), Batters & Mixes (Dairy, Bread & Eggs) ₹4.8K (13%), Atta (Atta, Rice, Oil & Dals) ₹3.9K (11%), Chocolates (Sweet Cravings) ₹2.2K (6%), Cold Drinks & Juices ₹1.6K (4%). Share is of ₹36.2K net loss across loss-making categories. * Loss is spread across 531 SKUs and the top 10 make 22% of SKU-level loss. * Theft-prone SKUs show net loss of ₹5.7K, led by gift cards ₹3.3K, dry fruits & nuts ₹1.3K and creatine ₹520. * Aisles G and H hold ₹19.9K, 55% of bin-level loss. | U33: G,H | V33: 11356
A34: 46303 | B34: South1 | C34: Bengaluru | D34: BLR-Jakkur New | E34: {=IF(D34="","",IFERROR(INDEX('CLM & IM Mapping'!$B$2:$B$270,MATCH(TRIM(D34),'CLM & IM Mapping'!$A$2:$A$270,0)),"Not Mapped"))} -> Girish N | F34: {=IF(D34="","",IFERROR(INDEX('CLM & IM Mapping'!$C$2:$C$270,MATCH(TRIM(D34),'CLM & IM Mapping'!$A$2:$A$270,0)),"Not Mapped"))} -> Un Mapped | G34: RETAIL_STORE | H34: 19635 | I34: 18346 | J34: 0 | K34: 292 | L34: 1633 | M34: 0 | N34: 0 | O34: 0 | P34: 39906 | S34: * Total IH loss is ₹39.9K, mainly from Adjustment ₹19.6K and FCC bin ₹18.3K. * Top loss categories: Ice Creams & More ₹8.1K (19%), Chocolates (Sweet Cravings) ₹6.8K (16%), Cold Drinks & Juices ₹6.0K (14%), Cheese (Dairy, Bread & Eggs) ₹4.8K (12%), Energy Bars (Munchies) ₹2.2K (5%). Share is of ₹41.9K net loss across loss-making categories. * Loss is spread across 743 SKUs and the top 10 make 11% of SKU-level loss. * Aisles M and L hold ₹21.5K, 54% of bin-level loss. | U34: L,K | V34: 16904
A35: 46303 | B35: South1 | C35: Bengaluru | D35: BLR-Kannamangala | E35: {=IF(D35="","",IFERROR(INDEX('CLM & IM Mapping'!$B$2:$B$270,MATCH(TRIM(D35),'CLM & IM Mapping'!$A$2:$A$270,0)),"Not Mapped"))} -> Ashwath S | F35: {=IF(D35="","",IFERROR(INDEX('CLM & IM Mapping'!$C$2:$C$270,MATCH(TRIM(D35),'CLM & IM Mapping'!$A$2:$A$270,0)),"Not Mapped"))} -> Kantha Kumar | G35: RETAIL_STORE | H35: 28774 | I35: 10857 | J35: 0 | K35: 0 | L35: 49 | M35: 0 | N35: 0 | O35: 0 | P35: 39679 | S35: SBC is currently in progress, with the team working towards completing the pending bins. The store is also operating with a 3-MP manpower gap, which is impacting operational execution. | T35: 40000 | U35: O,H | V35: 28849
A36: 46303 | B36: South1 | C36: Bengaluru | D36: BLR-HSR-2 | E36: {=IF(D36="","",IFERROR(INDEX('CLM & IM Mapping'!$B$2:$B$270,MATCH(TRIM(D36),'CLM & IM Mapping'!$A$2:$A$270,0)),"Not Mapped"))} -> Saddam Hussain | F36: {=IF(D36="","",IFERROR(INDEX('CLM & IM Mapping'!$C$2:$C$270,MATCH(TRIM(D36),'CLM & IM Mapping'!$A$2:$A$270,0)),"Not Mapped"))} -> Un Mapped | G36: RETAIL_STORE | H36: 21968 | I36: 12107 | J36: 0 | K36: 5366 | L36: 0 | M36: 0 | N36: 0 | O36: 0 | P36: 39440 | S36: * Total IH loss is ₹39.4K, mainly from Adjustment ₹22.0K, FCC bin ₹12.1K and Shortpick ₹5.4K. * Top loss categories: Ice Creams & More ₹14.4K (40%), Munchies ₹6.3K (17%), Cheese (Dairy, Bread & Eggs) ₹4.5K (13%), Dry Fruits & Nuts (Masala, Dry Fruits & More) ₹2.5K (7%), Cold Drinks & Juices ₹2.1K (6%). Share is of ₹36.2K net loss across loss-making categories. * Loss is spread across 618 SKUs and the top 10 make 15% of SKU-level loss. * Theft-prone SKUs show net loss of ₹3.7K, led by dry fruits & nuts ₹3.3K and premium chocolates ₹389. * Aisles L and H hold ₹23.0K, 66% of bin-level loss. | U36: L,K | V36: 18504
A37: 46303 | B37: South1 | C37: Bengaluru | D37: BLR-Kothnur New | E37: {=IF(D37="","",IFERROR(INDEX('CLM & IM Mapping'!$B$2:$B$270,MATCH(TRIM(D37),'CLM & IM Mapping'!$A$2:$A$270,0)),"Not Mapped"))} -> Raghavendra Vernekar | F37: {=IF(D37="","",IFERROR(INDEX('CLM & IM Mapping'!$C$2:$C$270,MATCH(TRIM(D37),'CLM & IM Mapping'!$A$2:$A$270,0)),"Not Mapped"))} -> Prakash BS | G37: RETAIL_STORE | H37: 16378 | I37: 18410 | J37: 227 | K37: 2848 | L37: 751 | M37: 0 | N37: 756 | O37: 0 | P37: 39369 | S37: Due to the ATA mode conversion of CC, we are unable to get access to add back; an SI has been deployed to recover the losses. | T37: 30000 | U37: A,E | V37: 17206
A38: 46303 | B38: South1 | C38: Bengaluru | D38: BLR-Marathalli SS | E38: {=IF(D38="","",IFERROR(INDEX('CLM & IM Mapping'!$B$2:$B$270,MATCH(TRIM(D38),'CLM & IM Mapping'!$A$2:$A$270,0)),"Not Mapped"))} -> Arun Raj | F38: {=IF(D38="","",IFERROR(INDEX('CLM & IM Mapping'!$C$2:$C$270,MATCH(TRIM(D38),'CLM & IM Mapping'!$A$2:$A$270,0)),"Not Mapped"))} -> Simon Manoharan | G38: SUPERSTORE | H38: 23481 | I38: 11376 | J38: 0 | K38: 0 | L38: 3479 | M38: 0 | N38: 0 | O38: 0 | P38: 38336 | S38: Putaway issue due to aisle congestion; CCA is checking aisles '1' and 'M' to recover the stock. | T38: 38000 | U38: I,M | V38: 14287
A39: 46303 | B39: South1 | C39: Bengaluru | D39: BLR-Dasarahalli | E39: {=IF(D39="","",IFERROR(INDEX('CLM & IM Mapping'!$B$2:$B$270,MATCH(TRIM(D39),'CLM & IM Mapping'!$A$2:$A$270,0)),"Not Mapped"))} -> Mohaideen DH | F39: {=IF(D39="","",IFERROR(INDEX('CLM & IM Mapping'!$C$2:$C$270,MATCH(TRIM(D39),'CLM & IM Mapping'!$A$2:$A$270,0)),"Not Mapped"))} -> Mohammed Akbar | G39: RETAIL_STORE | H39: 7420 | I39: 28642 | J39: 116 | K39: 710 | L39: 298 | M39: 0 | N39: 0 | O39: 0 | P39: 37186 | S39: * Total IH loss is ₹37.2K, mainly from FCC bin ₹28.6K and Adjustment ₹7.4K. * Majority impact is from FCC bin of ₹28.6K. Excluding this, the store is ₹8.5K in loss. * Top loss categories: Chips & Crisps (Munchies) ₹12.4K (29%), Oil (Atta, Rice, Oil & Dals) ₹6.0K (14%), Whey Protein (Protein & Nutrition) ₹5.6K (13%), Biscuits ₹3.5K (8%), Fruits & Vegetables ₹3.5K (8%). Share is of ₹42.5K net loss across loss-making categories. * Loss is spread across 929 SKUs and the top 10 make 12% of SKU-level loss. * Theft-prone SKUs show net loss of ₹5.8K, led by whey ₹3.7K, creatine ₹781 and pen drives ₹542. * Aisles A and C hold ₹33.6K, 81% of bin-level loss. | T39: 37000 | U39: A,C | V39: 30449
A40: 46303 | B40: South1 | C40: Bengaluru | D40: BLR-Manjunatha layout | E40: {=IF(D40="","",IFERROR(INDEX('CLM & IM Mapping'!$B$2:$B$270,MATCH(TRIM(D40),'CLM & IM Mapping'!$A$2:$A$270,0)),"Not Mapped"))} -> Sundaresh S | F40: {=IF(D40="","",IFERROR(INDEX('CLM & IM Mapping'!$C$2:$C$270,MATCH(TRIM(D40),'CLM & IM Mapping'!$A$2:$A$270,0)),"Not Mapped"))} -> Un Mapped | G40: RETAIL_STORE | H40: 15298 | I40: 12439 | J40: 0 | K40: 1021 | L40: 1315 | M40: 0 | N40: 7022 | O40: 0 | P40: 37095 | S40: * Total IH loss is ₹37.1K, mainly from Adjustment ₹15.3K, FCC bin ₹12.4K and STO short receipt ₹7.0K. * Top loss categories: Dairy, Bread & Eggs ₹19.3K (37%), Munchies ₹7.9K (15%), Sweet Cravings ₹4.7K (9%), Packaged Food ₹3.8K (7%), Cold Drinks & Juices ₹3.5K (7%). Share is of ₹52.5K net loss across loss-making categories. * Loss is spread across 806 SKUs and the top 10 make 14% of SKU-level loss. * Theft-prone SKUs show net loss of ₹3.3K, led by trimmers ₹2.8K, premium chocolates ₹436 and deos ₹83. * Aisles B and H hold ₹19.9K, 56% of bin-level loss. | U40: H,C | V40: 16594
...

Sheet Inventory Hygiene
A1: Date | B1: store_name | C1: CLM | D1: IM | E1: sub_store_type | F1: planogram_enabled_flag | G1: city_name | H1: Total Bins | I1: Target CC MTD | J1: CC MTD % | K1: BA MTD % | L1: IA MTD % | M1: CC ACC % | N1: CCA | O1: RCA & POA | P1: ETA
A2: 46303 | B2: BLR-Vidyaranyapura | C2: {=IF(B2="","",IFERROR(INDEX('CLM & IM Mapping'!$B$2:$B$270,MATCH(TRIM(B2),'CLM & IM Mapping'!$A$2:$A$270,0)),"Not Mapped"))} -> Akshay P | D2: {=IF(B2="","",IFERROR(INDEX('CLM & IM Mapping'!$C$2:$C$270,MATCH(TRIM(B2),'CLM & IM Mapping'!$A$2:$A$270,0)),"Not Mapped"))} -> Srittam Dhal | E2: RETAIL_STORE | F2: Yes | G2: Bengaluru | H2: 5212 | I2: 0.7 | J2: 0 | N2: 1 | O2: Store has been closed.
A3: 46303 | B3: BLR-BROOKEFIELD | C3: {=IF(B3="","",IFERROR(INDEX('CLM & IM Mapping'!$B$2:$B$270,MATCH(TRIM(B3),'CLM & IM Mapping'!$A$2:$A$270,0)),"Not Mapped"))} -> Basil Scariya | D3: {=IF(B3="","",IFERROR(INDEX('CLM & IM Mapping'!$C$2:$C$270,MATCH(TRIM(B3),'CLM & IM Mapping'!$A$2:$A$270,0)),"Not Mapped"))} -> Prakash BS | E3: RETAIL_STORE | F3: Yes | G3: Bengaluru | H3: 7849 | I3: 0.7 | J3: 0 | O3: Store has been closed.
A4: 46303 | B4: BLR-Vidyaranyapura SS | C4: {=IF(B4="","",IFERROR(INDEX('CLM & IM Mapping'!$B$2:$B$270,MATCH(TRIM(B4),'CLM & IM Mapping'!$A$2:$A$270,0)),"Not Mapped"))} -> Arun Raj | D4: {=IF(B4="","",IFERROR(INDEX('CLM & IM Mapping'!$C$2:$C$270,MATCH(TRIM(B4),'CLM & IM Mapping'!$A$2:$A$270,0)),"Not Mapped"))} -> Simon Manoharan | E4: SUPERSTORE | F4: No | G4: Bengaluru | H4: 12051 | I4: 0.7 | J4: 0 | O4: Store has been closed.
A5: 46303 | B5: BLR-JC Nagar | C5: {=IF(B5="","",IFERROR(INDEX('CLM & IM Mapping'!$B$2:$B$270,MATCH(TRIM(B5),'CLM & IM Mapping'!$A$2:$A$270,0)),"Not Mapped"))} -> Manoj Kj | D5: {=IF(B5="","",IFERROR(INDEX('CLM & IM Mapping'!$C$2:$C$270,MATCH(TRIM(B5),'CLM & IM Mapping'!$A$2:$A$270,0)),"Not Mapped"))} -> Srittam Dhal | E5: RETAIL_STORE | F5: Yes | G5: Bengaluru | H5: 5421 | I5: 0.7 | J5: 0.01 | K5: 0.97 | L5: 0.99 | M5: 0.06 | N5: 5 | O5: Store has been closed.
A6: 46303 | B6: BLR-Balagere SS | C6: {=IF(B6="","",IFERROR(INDEX('CLM & IM Mapping'!$B$2:$B$270,MATCH(TRIM(B6),'CLM & IM Mapping'!$A$2:$A$270,0)),"Not Mapped"))} -> Arun Raj | D6: {=IF(B6="","",IFERROR(INDEX('CLM & IM Mapping'!$C$2:$C$270,MATCH(TRIM(B6),'CLM & IM Mapping'!$A$2:$A$270,0)),"Not Mapped"))} -> Simon Manoharan | E6: SUPERSTORE | F6: No | G6: Bengaluru | H6: 10619 | I6: 0.7 | J6: 0.02 | K6: 0 | L6: -22.56 | M6: 0 | O6: Store has been closed.
A7: 46303 | B7: BLR-JP Nagar SS | C7: {=IF(B7="","",IFERROR(INDEX('CLM & IM Mapping'!$B$2:$B$270,MATCH(TRIM(B7),'CLM & IM Mapping'!$A$2:$A$270,0)),"Not Mapped"))} -> Arun Raj | D7: {=IF(B7="","",IFERROR(INDEX('CLM & IM Mapping'!$C$2:$C$270,MATCH(TRIM(B7),'CLM & IM Mapping'!$A$2:$A$270,0)),"Not Mapped"))} -> Simon Manoharan | E7: SUPERSTORE | F7: No | G7: Bengaluru | H7: 13730 | I7: 0.7 | J7: 0.06 | K7: 0.96 | L7: 0.98 | M7: 0.26 | N7: 1 | O7: Store has been closed.
A8: 46303 | B8: BLR-Eldorado | C8: {=IF(B8="","",IFERROR(INDEX('CLM & IM Mapping'!$B$2:$B$270,MATCH(TRIM(B8),'CLM & IM Mapping'!$A$2:$A$270,0)),"Not Mapped"))} -> Adhavan Subramani | D8: {=IF(B8="","",IFERROR(INDEX('CLM & IM Mapping'!$C$2:$C$270,MATCH(TRIM(B8),'CLM & IM Mapping'!$A$2:$A$270,0)),"Not Mapped"))} -> Mohammed Akbar | E8: RETAIL_STORE | F8: Yes | G8: Bengaluru | H8: 5759 | I8: 0.7 | J8: 0.07 | K8: 0.92 | L8: 0.92 | O8: New store launched last month – no CCAs available. | P8: 15th Oct
A9: 46303 | B9: COI-R S Puram | C9: {=IF(B9="","",IFERROR(INDEX('CLM & IM Mapping'!$B$2:$B$270,MATCH(TRIM(B9),'CLM & IM Mapping'!$A$2:$A$270,0)),"Not Mapped"))} -> John Britto | D9: {=IF(B9="","",IFERROR(INDEX('CLM & IM Mapping'!$C$2:$C$270,MATCH(TRIM(B9),'CLM & IM Mapping'!$A$2:$A$270,0)),"Not Mapped"))} -> Aravind S | E9: RETAIL_STORE | F9: Yes | G9: Coimbatore | H9: 5114 | I9: 0.7 | J9: 0.07 | K9: 0.94 | L9: 0.96 | M9: 0.31 | N9: 1 | O9: SI & CC delta. Deployed 3 CCs from other stores. | P9: 15th Oct
A10: 46303 | B10: COI-Parashakti nagar | C10: {=IF(B10="","",IFERROR(INDEX('CLM & IM Mapping'!$B$2:$B$270,MATCH(TRIM(B10),'CLM & IM Mapping'!$A$2:$A$270,0)),"Not Mapped"))} -> John Britto | D10: {=IF(B10="","",IFERROR(INDEX('CLM & IM Mapping'!$C$2:$C$270,MATCH(TRIM(B10),'CLM & IM Mapping'!$A$2:$A$270,0)),"Not Mapped"))} -> Aravind S | E10: RETAIL_STORE | F10: Yes | G10: Coimbatore | H10: 6188 | I10: 0.7 | J10: 0.1 | K10: 0.81 | L10: 0.98 | M10: 0.35 | N10: 3 | O10: Lowest-Performing Stores – Performance Action Plan | P10: 15th Oct
A11: 46303 | B11: COI-Sundarapuram | C11: {=IF(B11="","",IFERROR(INDEX('CLM & IM Mapping'!$B$2:$B$270,MATCH(TRIM(B11),'CLM & IM Mapping'!$A$2:$A$270,0)),"Not Mapped"))} -> John Britto | D11: {=IF(B11="","",IFERROR(INDEX('CLM & IM Mapping'!$C$2:$C$270,MATCH(TRIM(B11),'CLM & IM Mapping'!$A$2:$A$270,0)),"Not Mapped"))} -> Aravind S | E11: RETAIL_STORE | F11: Yes | G11: Coimbatore | H11: 6277 | I11: 0.7 | J11: 0.1 | K11: 0.81 | L11: 0.97 | M11: 0.37 | N11: 2 | O11: Lowest-Performing Stores – Performance Action Plan | P11: 15th Oct
A12: 46303 | B12: KOC-Kalamassery SS | C12: {=IF(B12="","",IFERROR(INDEX('CLM & IM Mapping'!$B$2:$B$270,MATCH(TRIM(B12),'CLM & IM Mapping'!$A$2:$A$270,0)),"Not Mapped"))} -> Vishnu V | D12: {=IF(B12="","",IFERROR(INDEX('CLM & IM Mapping'!$C$2:$C$270,MATCH(TRIM(B12),'CLM & IM Mapping'!$A$2:$A$270,0)),"Not Mapped"))} -> Arivind S | E12: SUPERSTORE | F12: No | G12: Kochi | H12: 6058 | I12: 0.7 | J12: 0.12 | K12: 0.99 | L12: 1 | M12: 0.52 | N12: 1 | O12: Continuous MP absenteeism in the store: on Saturday, 4 and 5 were absent out of a total of 13 MP. Due to high putaway, unable to cross-deploy. | P12: 14th
A13: 46303 | B13: BLR-RICHMOND TOWN SS | C13: {=IF(B13="","",IFERROR(INDEX('CLM & IM Mapping'!$B$2:$B$270,MATCH(TRIM(B13),'CLM & IM Mapping'!$A$2:$A$270,0)),"Not Mapped"))} -> Arun Raj | D13: {=IF(B13="","",IFERROR(INDEX('CLM & IM Mapping'!$C$2:$C$270,MATCH(TRIM(B13),'CLM & IM Mapping'!$A$2:$A$270,0)),"Not Mapped"))} -> Simon Manoharan | E13: SUPERSTORE | F13: No | G13: Bengaluru | H13: 12938 | I13: 0.7 | J13: 0.13 | K13: 0.77 | L13: 0.92 | M13: 0.46 | N13: 4 | O13: Stock movement is currently ongoing; once the movement is closed, we will complete the full W2W. | P13: 25th
A14: 46303 | B14: BLR-Malleshwaram SS | C14: {=IF(B14="","",IFERROR(INDEX('CLM & IM Mapping'!$B$2:$B$270,MATCH(TRIM(B14),'CLM & IM Mapping'!$A$2:$A$270,0)),"Not Mapped"))} -> Arun Raj | D14: {=IF(B14="","",IFERROR(INDEX('CLM & IM Mapping'!$C$2:$C$270,MATCH(TRIM(B14),'CLM & IM Mapping'!$A$2:$A$270,0)),"Not Mapped"))} -> Simon Manoharan | E14: SUPERSTORE | F14: No | G14: Bengaluru | H14: 7680 | I14: 0.7 | J14: 0.14 | K14: 0.76 | L14: 0.96 | M14: 0.46 | N14: 1 | O14: Store is recovering from an MP delta; a squad is currently deployed for the W2W audit. | P14: 15th
A15: 46303 | B15: BLR-RR Nagar SS | C15: {=IF(B15="","",IFERROR(INDEX('CLM & IM Mapping'!$B$2:$B$270,MATCH(TRIM(B15),'CLM & IM Mapping'!$A$2:$A$270,0)),"Not Mapped"))} -> Arun Raj | D15: {=IF(B15="","",IFERROR(INDEX('CLM & IM Mapping'!$C$2:$C$270,MATCH(TRIM(B15),'CLM & IM Mapping'!$A$2:$A$270,0)),"Not Mapped"))} -> Simon Manoharan | E15: SUPERSTORE | F15: No | G15: Bengaluru | H15: 11984 | I15: 0.7 | J15: 0.14 | K15: 0.94 | L15: 0.99 | M15: 0.6 | O15: The store is recovering from a delta of 9 MP; the hiring issue has been raised with the HR team. | P15: 15th
A16: 46303 | B16: COI-Nehru Nagar | C16: {=IF(B16="","",IFERROR(INDEX('CLM & IM Mapping'!$B$2:$B$270,MATCH(TRIM(B16),'CLM & IM Mapping'!$A$2:$A$270,0)),"Not Mapped"))} -> John Britto | D16: {=IF(B16="","",IFERROR(INDEX('CLM & IM Mapping'!$C$2:$C$270,MATCH(TRIM(B16),'CLM & IM Mapping'!$A$2:$A$270,0)),"Not Mapped"))} -> Aravind S | E16: RETAIL_STORE | F16: Yes | G16: Coimbatore | H16: 6791 | I16: 0.7 | J16: 0.14 | K16: 0.98 | L16: 1 | O16: Newly launched store; CC not nominated. | P16: 15th Oct
A17: 46303 | B17: BLR-Jakkur Network | C17: {=IF(B17="","",IFERROR(INDEX('CLM & IM Mapping'!$B$2:$B$270,MATCH(TRIM(B17),'CLM & IM Mapping'!$A$2:$A$270,0)),"Not Mapped"))} -> Girish N | D17: {=IF(B17="","",IFERROR(INDEX('CLM & IM Mapping'!$C$2:$C$270,MATCH(TRIM(B17),'CLM & IM Mapping'!$A$2:$A$270,0)),"Not Mapped"))} -> Un Mapped | E17: RETAIL_STORE | F17: Yes | G17: Bengaluru | H17: 5106 | I17: 0.7 | J17: 0.16 | K17: 0.69 | L17: 0.98 | M17: 0.49 | N17: 11 | O17: CCAs have been converted to peak associates. SBC is system-generated through ATA. | P17: 16th Oct
A18: 46303 | B18: COI-Race Course | C18: {=IF(B18="","",IFERROR(INDEX('CLM & IM Mapping'!$B$2:$B$270,MATCH(TRIM(B18),'CLM & IM Mapping'!$A$2:$A$270,0)),"Not Mapped"))} -> John Britto | D18: {=IF(B18="","",IFERROR(INDEX('CLM & IM Mapping'!$C$2:$C$270,MATCH(TRIM(B18),'CLM & IM Mapping'!$A$2:$A$270,0)),"Not Mapped"))} -> Aravind S | E18: RETAIL_STORE | F18: Yes | G18: Coimbatore | H18: 7163 | I18: 0.7 | J18: 0.18 | K18: 0.91 | L18: 0.97 | M18: 0.72 | N18: 1 | O18: CC delta. Deployed 2 CCs from different stores. | P18: 15th Oct
A19: 46303 | B19: KOC-PALLURTHY | C19: {=IF(B19="","",IFERROR(INDEX('CLM & IM Mapping'!$B$2:$B$270,MATCH(TRIM(B19),'CLM & IM Mapping'!$A$2:$A$270,0)),"Not Mapped"))} -> Vishnu V | D19: {=IF(B19="","",IFERROR(INDEX('CLM & IM Mapping'!$C$2:$C$270,MATCH(TRIM(B19),'CLM & IM Mapping'!$A$2:$A$270,0)),"Not Mapped"))} -> Arivind S | E19: RETAIL_STORE | F19: Yes | G19: Kochi | H19: 5139 | I19: 0.7 | J19: 0.18 | K19: 0.7 | L19: 0.92 | M19: 0.55 | N19: 1 | O19: CC associate delta in the store; the CC associate was absent due to illness. Squad support has been requested. | P19: 14th
A20: 46303 | B20: BLR-VIJAY NAGAR | C20: {=IF(B20="","",IFERROR(INDEX('CLM & IM Mapping'!$B$2:$B$270,MATCH(TRIM(B20),'CLM & IM Mapping'!$A$2:$A$270,0)),"Not Mapped"))} -> Narasimhamurthy R | D20: {=IF(B20="","",IFERROR(INDEX('CLM & IM Mapping'!$C$2:$C$270,MATCH(TRIM(B20),'CLM & IM Mapping'!$A$2:$A$270,0)),"Not Mapped"))} -> Kishor K | E20: RETAIL_STORE | F20: No | G20: Bengaluru | H20: 5482 | I20: 0.7 | J20: 0.19 | K20: 0.6 | L20: 0.88 | M20: 0.5 | N20: 3 | O20: 2 CCAs – LC1 MP. One CCA has been removed from the job due to behavioural issues, and one more CCA will be hired from 9th October. The CCA will cover approximately 700 bins per day. | P20: 14th
A21: 46303 | B21: BLR-Dooravani Nagar SS | C21: {=IF(B21="","",IFERROR(INDEX('CLM & IM Mapping'!$B$2:$B$270,MATCH(TRIM(B21),'CLM & IM Mapping'!$A$2:$A$270,0)),"Not Mapped"))} -> Arun Raj | D21: {=IF(B21="","",IFERROR(INDEX('CLM & IM Mapping'!$C$2:$C$270,MATCH(TRIM(B21),'CLM & IM Mapping'!$A$2:$A$270,0)),"Not Mapped"))} -> Simon Manoharan | E21: SUPERSTORE | F21: No | G21: Bengaluru | H21: 12201 | I21: 0.7 | J21: 0.21 | K21: 0.92 | L21: 0.96 | M21: 0.86 | N21: 3 | O21: 1 CCA is on leave; 2 MP from the store team have been deployed to close the audit. | P21: 15th
A22: 46303 | B22: COI-Vadavalli 1 | C22: {=IF(B22="","",IFERROR(INDEX('CLM & IM Mapping'!$B$2:$B$270,MATCH(TRIM(B22),'CLM & IM Mapping'!$A$2:$A$270,0)),"Not Mapped"))} -> John Britto | D22: {=IF(B22="","",IFERROR(INDEX('CLM & IM Mapping'!$C$2:$C$270,MATCH(TRIM(B22),'CLM & IM Mapping'!$A$2:$A$270,0)),"Not Mapped"))} -> Aravind S | E22: RETAIL_STORE | F22: Yes | G22: Coimbatore | H22: 7099 | I22: 0.7 | J22: 0.21 | K22: 0.96 | L22: 0.97 | M22: 0.9 | N22: 1 | O22: CC delta. Deployed 2 CCs. | P22: 15th Oct
A23: 46303 | B23: BLR-BASAVANAPURA | C23: {=IF(B23="","",IFERROR(INDEX('CLM & IM Mapping'!$B$2:$B$270,MATCH(TRIM(B23),'CLM & IM Mapping'!$A$2:$A$270,0)),"Not Mapped"))} -> Richard Harris | D23: {=IF(B23="","",IFERROR(INDEX('CLM & IM Mapping'!$C$2:$C$270,MATCH(TRIM(B23),'CLM & IM Mapping'!$A$2:$A$270,0)),"Not Mapped"))} -> Kantha Kumar | E23: RETAIL_STORE | F23: Yes | G23: Bengaluru | H23: 4538 | I23: 0.7 | J23: 0.22 | K23: 0.41 | L23: 0.83 | M23: 0.39 | N23: 3
A24: 46303 | B24: BLR-HSR Layout New | C24: {=IF(B24="","",IFERROR(INDEX('CLM & IM Mapping'!$B$2:$B$270,MATCH(TRIM(B24),'CLM & IM Mapping'!$A$2:$A$270,0)),"Not Mapped"))} -> Saddam Hussain | D24: {=IF(B24="","",IFERROR(INDEX('CLM & IM Mapping'!$C$2:$C$270,MATCH(TRIM(B24),'CLM & IM Mapping'!$A$2:$A$270,0)),"Not Mapped"))} -> Un Mapped | E24: RETAIL_STORE | F24: Yes | G24: Bengaluru | H24: 6691 | I24: 0.7 | J24: 0.23 | K24: 0.73 | L24: 0.86 | M24: 0.73 | N24: 3 | O24: 1 CCA delta, and 1 CCA was on sick leave for 3 days. Conversion of 4 CCAs is done; targeting to complete 700 bins per day. | P24: 13th Oct
A25: 46303 | B25: BLR-Electronic City SS | C25: {=IF(B25="","",IFERROR(INDEX('CLM & IM Mapping'!$B$2:$B$270,MATCH(TRIM(B25),'CLM & IM Mapping'!$A$2:$A$270,0)),"Not Mapped"))} -> Arun Raj | D25: {=IF(B25="","",IFERROR(INDEX('CLM & IM Mapping'!$C$2:$C$270,MATCH(TRIM(B25),'CLM & IM Mapping'!$A$2:$A$270,0)),"Not Mapped"))} -> Simon Manoharan | E25: SUPERSTORE | F25: No | G25: Bengaluru | H25: 11048 | I25: 0.7 | J25: 0.23 | K25: 0.97 | L25: 0.99 | M25: 0.97 | N25: 1 | O25: On track; will close by the 15th. | P25: 15th
A26: 46303 | B26: BLR-Bellandur SS | C26: {=IF(B26="","",IFERROR(INDEX('CLM & IM Mapping'!$B$2:$B$270,MATCH(TRIM(B26),'CLM & IM Mapping'!$A$2:$A$270,0)),"Not Mapped"))} -> Arun Raj | D26: {=IF(B26="","",IFERROR(INDEX('CLM & IM Mapping'!$C$2:$C$270,MATCH(TRIM(B26),'CLM & IM Mapping'!$A$2:$A$270,0)),"Not Mapped"))} -> Simon Manoharan | E26: SUPERSTORE | F26: No | G26: Bengaluru | H26: 10796 | I26: 0.7 | J26: 0.23 | K26: 0.97 | L26: 0.99 | M26: 0.97 | N26: 1 | O26: On track; will close by the 15th. | P26: 15th
A27: 46303 | B27: BLR-Mico layout New | C27: {=IF(B27="","",IFERROR(INDEX('CLM & IM Mapping'!$B$2:$B$270,MATCH(TRIM(B27),'CLM & IM Mapping'!$A$2:$A$270,0)),"Not Mapped"))} -> Keshav G | D27: {=IF(B27="","",IFERROR(INDEX('CLM & IM Mapping'!$C$2:$C$270,MATCH(TRIM(B27),'CLM & IM Mapping'!$A$2:$A$270,0)),"Not Mapped"))} -> Un Mapped | E27: RETAIL_STORE | F27: Yes | G27: Bengaluru | H27: 5873 | I27: 0.7 | J27: 0.25 | K27: 0.73 | L27: 0.95 | M27: 0.73 | N27: 6
A28: 46303 | B28: BLR-Kothnur New | C28: {=IF(B28="","",IFERROR(INDEX('CLM & IM Mapping'!$B$2:$B$270,MATCH(TRIM(B28),'CLM & IM Mapping'!$A$2:$A$270,0)),"Not Mapped"))} -> Raghavendra Vernekar | D28: {=IF(B28="","",IFERROR(INDEX('CLM & IM Mapping'!$C$2:$C$270,MATCH(TRIM(B28),'CLM & IM Mapping'!$A$2:$A$270,0)),"Not Mapped"))} -> Prakash BS | E28: RETAIL_STORE | F28: Yes | G28: Bengaluru | H28: 5574 | I28: 0.7 | J28: 0.25 | K28: 0.78 | L28: 0.94 | M28: 0.78 | N28: 3 | O28: 2 CC associates are on leave and have not been reporting to the store for the past few days. 95% of CC will be completed by the 15th. | P28: 15/10/2026
A29: 46303 | B29: BLR-Avalahalli Main | C29: {=IF(B29="","",IFERROR(INDEX('CLM & IM Mapping'!$B$2:$B$270,MATCH(TRIM(B29),'CLM & IM Mapping'!$A$2:$A$270,0)),"Not Mapped"))} -> Suhas N | D29: {=IF(B29="","",IFERROR(INDEX('CLM & IM Mapping'!$C$2:$C$270,MATCH(TRIM(B29),'CLM & IM Mapping'!$A$2:$A$270,0)),"Not Mapped"))} -> Aravind S | E29: RETAIL_STORE | F29: Yes | G29: Bengaluru | H29: 6396 | I29: 0.7 | J29: 0.25 | K29: 0.7 | L29: 0.83 | M29: 0.7 | N29: 4 | O29: Critical bin and ground floor audits have been initiated. | P29: 20th Oct
A30: 46303 | B30: BLR-Kengeri | C30: {=IF(B30="","",IFERROR(INDEX('CLM & IM Mapping'!$B$2:$B$270,MATCH(TRIM(B30),'CLM & IM Mapping'!$A$2:$A$270,0)),"Not Mapped"))} -> Ravishankar gowda | D30: {=IF(B30="","",IFERROR(INDEX('CLM & IM Mapping'!$C$2:$C$270,MATCH(TRIM(B30),'CLM & IM Mapping'!$A$2:$A$270,0)),"Not Mapped"))} -> Kishor K | E30: RETAIL_STORE | F30: Yes | G30: Bengaluru | H30: 5765 | I30: 0.7 | J30: 0.26 | K30: 0.82 | L30: 0.96 | M30: 0.82 | N30: 4 | O30: 3 CCA delta. 1 CCA is on leave for 4 days due to exams. 4 CCAs have been hired and will report from 9th October; they will cover approximately 700 bins per day. | P30: 14th
A31: 46303 | B31: KOC-Edappally | C31: {=IF(B31="","",IFERROR(INDEX('CLM & IM Mapping'!$B$2:$B$270,MATCH(TRIM(B31),'CLM & IM Mapping'!$A$2:$A$270,0)),"Not Mapped"))} -> Vishnu V | D31: {=IF(B31="","",IFERROR(INDEX('CLM & IM Mapping'!$C$2:$C$270,MATCH(TRIM(B31),'CLM & IM Mapping'!$A$2:$A$270,0)),"Not Mapped"))} -> Arivind S | E31: RETAIL_STORE | F31: Yes | G31: Kochi | H31: 6097 | I31: 0.7 | J31: 0.26 | K31: 0.91 | L31: 0.92 | M31: 0.91 | N31: 1 | O31: Only one CC associate was available in the store, so squad support was requested. | P31: 13th
A32: 46303 | B32: PAL-Kalpathy | C32: {=IF(B32="","",IFERROR(INDEX('CLM & IM Mapping'!$B$2:$B$270,MATCH(TRIM(B32),'CLM & IM Mapping'!$A$2:$A$270,0)),"Not Mapped"))} -> Vishnu V | D32: {=IF(B32="","",IFERROR(INDEX('CLM & IM Mapping'!$C$2:$C$270,MATCH(TRIM(B32),'CLM & IM Mapping'!$A$2:$A$270,0)),"Not Mapped"))} -> Arivind S | E32: RETAIL_STORE | F32: Yes | G32: Palakkad | H32: 5121 | I32: 0.7 | J32: 0.26 | K32: 0.94 | L32: 0.99 | M32: 0.94 | O32: CC associate delta in the store for the past week; the DHM has given the nomination. Now covering 500 bins per day. | P32: 15th Oct
A33: 46303 | B33: BLR-Nehru Nagar SS | C33: {=IF(B33="","",IFERROR(INDEX('CLM & IM Mapping'!$B$2:$B$270,MATCH(TRIM(B33),'CLM & IM Mapping'!$A$2:$A$270,0)),"Not Mapped"))} -> Arun Raj | D33: {=IF(B33="","",IFERROR(INDEX('CLM & IM Mapping'!$C$2:$C$270,MATCH(TRIM(B33),'CLM & IM Mapping'!$A$2:$A$270,0)),"Not Mapped"))} -> Simon Manoharan | E33: SUPERSTORE | F33: No | G33: Bengaluru | H33: 13736 | I33: 0.7 | J33: 0.27 | K33: 0.97 | L33: 0.99 | M33: 0.97 | N33: 1 | O33: On track; will close by the 15th. | P33: 15th
A34: 46303 | B34: COI-Peelamedu | C34: {=IF(B34="","",IFERROR(INDEX('CLM & IM Mapping'!$B$2:$B$270,MATCH(TRIM(B34),'CLM & IM Mapping'!$A$2:$A$270,0)),"Not Mapped"))} -> John Britto | D34: {=IF(B34="","",IFERROR(INDEX('CLM & IM Mapping'!$C$2:$C$270,MATCH(TRIM(B34),'CLM & IM Mapping'!$A$2:$A$270,0)),"Not Mapped"))} -> Aravind S | E34: RETAIL_STORE | F34: Yes | G34: Coimbatore | H34: 6707 | I34: 0.7 | J34: 0.27 | K34: 0.82 | L34: 0.95 | M34: 0.82 | N34: 3 | O34: Lowest-Performing Stores – Performance Action Plan | P34: 20th Oct
A35: 46303 | B35: BLR-Marathahalli-3 | C35: {=IF(B35="","",IFERROR(INDEX('CLM & IM Mapping'!$B$2:$B$270,MATCH(TRIM(B35),'CLM & IM Mapping'!$A$2:$A$270,0)),"Not Mapped"))} -> Sundaresh S | D35: {=IF(B35="","",IFERROR(INDEX('CLM & IM Mapping'!$C$2:$C$270,MATCH(TRIM(B35),'CLM & IM Mapping'!$A$2:$A$270,0)),"Not Mapped"))} -> Un Mapped | E35: RETAIL_STORE | F35: Yes | G35: Bengaluru | H35: 6352 | I35: 0.7 | J35: 0.29 | K35: 0.69 | L35: 0.93 | M35: 0.69 | N35: 2 | O35: 2 CCAs are LC1 with low productivity; 2 associates will be deployed to cover 500 bins daily. | P35: 15th Oct
A36: 46303 | B36: BLR-Nikoo home SS | C36: {=IF(B36="","",IFERROR(INDEX('CLM & IM Mapping'!$B$2:$B$270,MATCH(TRIM(B36),'CLM & IM Mapping'!$A$2:$A$270,0)),"Not Mapped"))} -> Arun Raj | D36: {=IF(B36="","",IFERROR(INDEX('CLM & IM Mapping'!$C$2:$C$270,MATCH(TRIM(B36),'CLM & IM Mapping'!$A$2:$A$270,0)),"Not Mapped"))} -> Simon Manoharan | E36: SUPERSTORE | F36: No | G36: Bengaluru | H36: 13152 | I36: 0.7 | J36: 0.3 | K36: 0.97 | L36: 0.98 | M36: 0.97 | N36: 2 | O36: On track; will close by the 15th. | P36: 15th
A37: 46303 | B37: BLR-Silver County SS | C37: {=IF(B37="","",IFERROR(INDEX('CLM & IM Mapping'!$B$2:$B$270,MATCH(TRIM(B37),'CLM & IM Mapping'!$A$2:$A$270,0)),"Not Mapped"))} -> Arun Raj | D37: {=IF(B37="","",IFERROR(INDEX('CLM & IM Mapping'!$C$2:$C$270,MATCH(TRIM(B37),'CLM & IM Mapping'!$A$2:$A$270,0)),"Not Mapped"))} -> Simon Manoharan | E37: SUPERSTORE | F37: Yes | G37: Bengaluru | H37: 10893 | I37: 0.7 | J37: 0.3 | K37: 0.97 | L37: 0.99 | M37: 0.97 | O37: On track; will close by the 15th. | P37: 15th
A38: 46303 | B38: BLR-Sattava East SS | C38: {=IF(B38="","",IFERROR(INDEX('CLM & IM Mapping'!$B$2:$B$270,MATCH(TRIM(B38),'CLM & IM Mapping'!$A$2:$A$270,0)),"Not Mapped"))} -> Arun Raj | D38: {=IF(B38="","",IFERROR(INDEX('CLM & IM Mapping'!$C$2:$C$270,MATCH(TRIM(B38),'CLM & IM Mapping'!$A$2:$A$270,0)),"Not Mapped"))} -> Simon Manoharan | E38: SUPERSTORE | F38: No | G38: Bengaluru | H38: 12271 | I38: 0.7 | J38: 0.3 | K38: 0.99 | L38: 1 | M38: 0.99 | N38: 2 | O38: On track; will close by the 15th. | P38: 15th
A39: 46303 | B39: BLR-Bagalakunte | C39: {=IF(B39="","",IFERROR(INDEX('CLM & IM Mapping'!$B$2:$B$270,MATCH(TRIM(B39),'CLM & IM Mapping'!$A$2:$A$270,0)),"Not Mapped"))} -> Akshay P | D39: {=IF(B39="","",IFERROR(INDEX('CLM & IM Mapping'!$C$2:$C$270,MATCH(TRIM(B39),'CLM & IM Mapping'!$A$2:$A$270,0)),"Not Mapped"))} -> Srittam Dhal | E39: RETAIL_STORE | F39: Yes | G39: Bengaluru | H39: 7531 | I39: 0.7 | J39: 0.31 | K39: 0.82 | L39: 0.89 | M39: 0.82 | N39: 2 | O39: CCAs were deployed for the chiller and freezer audit, which took 3 days to complete. 2 CC associates left the job on 5th Oct, resulting in a 2 CC delta at the store. A squad will be deployed to complete CC. | P39: 13th
A40: 46303 | B40: BLR-HSR-2 | C40: {=IF(B40="","",IFERROR(INDEX('CLM & IM Mapping'!$B$2:$B$270,MATCH(TRIM(B40),'CLM & IM Mapping'!$A$2:$A$270,0)),"Not Mapped"))} -> Saddam Hussain | D40: {=IF(B40="","",IFERROR(INDEX('CLM & IM Mapping'!$C$2:$C$270,MATCH(TRIM(B40),'CLM & IM Mapping'!$A$2:$A$270,0)),"Not Mapped"))} -> Un Mapped | E40: RETAIL_STORE | F40: No | G40: Bengaluru | H40: 5314 | I40: 0.7 | J40: 0.32 | K40: 0.78 | L40: 0.97 | M40: 0.78 | N40: 4 | O40: 2 CCAs not reporting due to health issues – SI and 2 CCAs will be deployed to cover 600 bins per day. | P40: 13th Oct
...

Sheet CLM & IM Mapping
A1: Store Names | B1: CLM Updated | C1: New IM Mapping
A2: BLR-Sarjapur New | B2: Saddam Hussain | C2: Un Mapped
A3: BLR-Agrahara Road | B3: Saddam Hussain | C3: Un Mapped
A4: BLR-Sarjapur-2 | B4: Saddam Hussain | C4: Un Mapped
A5: BLR-Doddakannelli | B5: Sundaresh S | C5: Un Mapped
A6: BLR-Carmelaram | B6: Sundaresh S | C6: Un Mapped
A7: BLR-Kasavanahalli | B7: Saddam Hussain | C7: Un Mapped
A8: BLR-Kasturinagar New | B8: Rizwan Ahmed | C8: Un Mapped
A9: BLR-Dooravani Nagar | B9: Rizwan Ahmed | C9: Un Mapped
A10: BLR-TC Palaya | B10: Rizwan Ahmed | C10: Un Mapped
A11: BLR-Banjara Layout | B11: Rizwan Ahmed | C11: Un Mapped
A12: BLR-Ramamurthy Nagar Network | B12: Rizwan Ahmed | C12: Un Mapped
... A270: TIR-Thiru VK Nagar Road | B270: John Britto | C270: Aravind S

Sheet RSTO > 48hrs
A1: Date | B1: Row Labels | C1: CLM | D1: IM | E1: c) 48-72 hr | F1: d) 72-96 hr | G1: e) >96 hr | H1: Grand Total | I1: Grand Total | J1: RCA & POA | K1: ETA
A2: 46303 | B2: BLR-Hennur New | C2: {=IF(B2="","",IFERROR(INDEX('CLM & IM Mapping'!$B$2:$B$270,MATCH(TRIM(B2),'CLM & IM Mapping'!$A$2:$A$270,0)),"Not Mapped"))} -> Adhavan Subramani | D2: {=IF(B2="","",IFERROR(INDEX('CLM & IM Mapping'!$C$2:$C$270,MATCH(TRIM(B2),'CLM & IM Mapping'!$A$2:$A$270,0)),"Not Mapped"))} -> Mohammed Akbar | G2: 1632 | H2: 1632 | I2: 107843.72 | J2: Store closed; picking in progress. | K2: Dispatching tomorrow – 9th Oct.
A3: 46303 | B3: BLR-JC Nagar | C3: {=IF(B3="","",IFERROR(INDEX('CLM & IM Mapping'!$B$2:$B$270,MATCH(TRIM(B3),'CLM & IM Mapping'!$A$2:$A$270,0)),"Not Mapped"))} -> Manoj Kj | D3: {=IF(B3="","",IFERROR(INDEX('CLM & IM Mapping'!$C$2:$C$270,MATCH(TRIM(B3),'CLM & IM Mapping'!$A$2:$A$270,0)),"Not Mapped"))} -> Srittam Dhal | G3: 882 | H3: 882 | I3: 104241.31 | J3: Store closed; picking in progress.
A4: 46303 | B4: BLR-ITPL Layout | C4: {=IF(B4="","",IFERROR(INDEX('CLM & IM Mapping'!$B$2:$B$270,MATCH(TRIM(B4),'CLM & IM Mapping'!$A$2:$A$270,0)),"Not Mapped"))} -> Rizwan Ahmed | D4: {=IF(B4="","",IFERROR(INDEX('CLM & IM Mapping'!$C$2:$C$270,MATCH(TRIM(B4),'CLM & IM Mapping'!$A$2:$A$270,0)),"Not Mapped"))} -> Prakash BS | E4: 62 | G4: 383 | H4: 445 | I4: 97053.76 | J4: Out of 445 qty, only 225 qty is pending, and this qty has been mapped to Milapura MH. A request has been raised to the central team to change the mapping; once the mapping is done, picking and dispatch will be completed.
A5: 46303 | B5: BLR-Marathalli SS | C5: {=IF(B5="","",IFERROR(INDEX('CLM & IM Mapping'!$B$2:$B$270,MATCH(TRIM(B5),'CLM & IM Mapping'!$A$2:$A$270,0)),"Not Mapped"))} -> Arun Raj | D5: {=IF(B5="","",IFERROR(INDEX('CLM & IM Mapping'!$C$2:$C$270,MATCH(TRIM(B5),'CLM & IM Mapping'!$A$2:$A$270,0)),"Not Mapped"))} -> Simon Manoharan | E5: 74 | G5: 143 | H5: 217 | I5: 90995.49 | J5: Pharma is pending; will be closed by 8th Oct. | K5: 8th Oct
