Workbook

Sheet City Split
A1: Select Date ▶ | B1: 46304 | C1: =IF($B$1="All","<>",$B$1) | D1: (pick a date or "All" from the dropdown)
A3: DH - City Split
A4: Type | B4: City | C4: Store Count | D4: Total Bins | E4: CC MTD % | F4: BA MTD % | G4: IA MTD % | H4: CC ACC % | I4: PD % | J4: Inv Health | K4: CC MTD Target | L4: CC MTD Achieved %
A5: DH | B5: Bengaluru | C5: =COUNTIFS('Raw Data'!$Q$2:$Q$10000,"No",'Raw Data'!$A$2:$A$10000,$C$1,'Raw Data'!$N$2:$N$10000,"DH",'Raw Data'!$E$2:$E$10000,$B5) | D5: =SUMIFS('Raw Data'!$F$2:$F$10000,'Raw Data'!$Q$2:$Q$10000,"No",'Raw Data'!$A$2:$A$10000,$C$1,'Raw Data'!$N$2:$N$10000,"DH",'Raw Data'!$E$2:$E$10000,$B5) | E5: =IFERROR(AVERAGEIFS('Raw Data'!$G$2:$G$10000,'Raw Data'!$Q$2:$Q$10000,"No",'Raw Data'!$A$2:$A$10000,$C$1,'Raw Data'!$N$2:$N$10000,"DH",'Raw Data'!$E$2:$E$10000,$B5),"") | F5: =IFERROR(AVERAGEIFS('Raw Data'!$H$2:$H$10000,'Raw Data'!$Q$2:$Q$10000,"No",'Raw Data'!$A$2:$A$10000,$C$1,'Raw Data'!$N$2:$N$10000,"DH",'Raw Data'!$E$2:$E$10000,$B5),"") | G5: =IFERROR(AVERAGEIFS('Raw Data'!$I$2:$I$10000,'Raw Data'!$Q$2:$Q$10000,"No",'Raw Data'!$A$2:$A$10000,$C$1,'Raw Data'!$N$2:$N$10000,"DH",'Raw Data'!$E$2:$E$10000,$B5),"") | H5: =IFERROR(AVERAGEIFS('Raw Data'!$J$2:$J$10000,'Raw Data'!$Q$2:$Q$10000,"No",'Raw Data'!$A$2:$A$10000,$C$1,'Raw Data'!$N$2:$N$10000,"DH",'Raw Data'!$E$2:$E$10000,$B5),"") | I5: =IFERROR(AVERAGEIFS('Raw Data'!$K$2:$K$10000,'Raw Data'!$Q$2:$Q$10000,"No",'Raw Data'!$A$2:$A$10000,$C$1,'Raw Data'!$N$2:$N$10000,"DH",'Raw Data'!$E$2:$E$10000,$B5),"") | J5: =IFERROR(AVERAGEIFS('Raw Data'!$L$2:$L$10000,'Raw Data'!$Q$2:$Q$10000,"No",'Raw Data'!$A$2:$A$10000,$C$1,'Raw Data'!$N$2:$N$10000,"DH",'Raw Data'!$E$2:$E$10000,$B5),"") | K5: =IFERROR(AVERAGEIFS('Raw Data'!$R$2:$R$10000,'Raw Data'!$Q$2:$Q$10000,"No",'Raw Data'!$A$2:$A$10000,$C$1,'Raw Data'!$N$2:$N$10000,"DH",'Raw Data'!$E$2:$E$10000,$B5),"") | L5: =IFERROR(AVERAGEIFS('Raw Data'!$S$2:$S$10000,'Raw Data'!$Q$2:$Q$10000,"No",'Raw Data'!$A$2:$A$10000,$C$1,'Raw Data'!$N$2:$N$10000,"DH",'Raw Data'!$E$2:$E$10000,$B5),"")
A6: DH | B6: Kochi | C6: =COUNTIFS('Raw Data'!$Q$2:$Q$10000,"No",'Raw Data'!$A$2:$A$10000,$C$1,'Raw Data'!$N$2:$N$10000,"DH",'Raw Data'!$E$2:$E$10000,$B6) | D6: =SUMIFS('Raw Data'!$F$2:$F$10000,'Raw Data'!$Q$2:$Q$10000,"No",'Raw Data'!$A$2:$A$10000,$C$1,'Raw Data'!$N$2:$N$10000,"DH",'Raw Data'!$E$2:$E$10000,$B6) | E6: =IFERROR(AVERAGEIFS('Raw Data'!$G$2:$G$10000,'Raw Data'!$Q$2:$Q$10000,"No",'Raw Data'!$A$2:$A$10000,$C$1,'Raw Data'!$N$2:$N$10000,"DH",'Raw Data'!$E$2:$E$10000,$B6),"") | F6: =IFERROR(AVERAGEIFS('Raw Data'!$H$2:$H$10000,'Raw Data'!$Q$2:$Q$10000,"No",'Raw Data'!$A$2:$A$10000,$C$1,'Raw Data'!$N$2:$N$10000,"DH",'Raw Data'!$E$2:$E$10000,$B6),"") | G6: =IFERROR(AVERAGEIFS('Raw Data'!$I$2:$I$10000,'Raw Data'!$Q$2:$Q$10000,"No",'Raw Data'!$A$2:$A$10000,$C$1,'Raw Data'!$N$2:$N$10000,"DH",'Raw Data'!$E$2:$E$10000,$B6),"") | H6: =IFERROR(AVERAGEIFS('Raw Data'!$J$2:$J$10000,'Raw Data'!$Q$2:$Q$10000,"No",'Raw Data'!$A$2:$A$10000,$C$1,'Raw Data'!$N$2:$N$10000,"DH",'Raw Data'!$E$2:$E$10000,$B6),"") | I6: =IFERROR(AVERAGEIFS('Raw Data'!$K$2:$K$10000,'Raw Data'!$Q$2:$Q$10000,"No",'Raw Data'!$A$2:$A$10000,$C$1,'Raw Data'!$N$2:$N$10000,"DH",'Raw Data'!$E$2:$E$10000,$B6),"") | J6: =IFERROR(AVERAGEIFS('Raw Data'!$L$2:$L$10000,'Raw Data'!$Q$2:$Q$10000,"No",'Raw Data'!$A$2:$A$10000,$C$1,'Raw Data'!$N$2:$N$10000,"DH",'Raw Data'!$E$2:$E$10000,$B6),"") | K6: =IFERROR(AVERAGEIFS('Raw Data'!$R$2:$R$10000,'Raw Data'!$Q$2:$Q$10000,"No",'Raw Data'!$A$2:$A$10000,$C$1,'Raw Data'!$N$2:$N$10000,"DH",'Raw Data'!$E$2:$E$10000,$B6),"") | L6: =IFERROR(AVERAGEIFS('Raw Data'!$S$2:$S$10000,'Raw Data'!$Q$2:$Q$10000,"No",'Raw Data'!$A$2:$A$10000,$C$1,'Raw Data'!$N$2:$N$10000,"DH",'Raw Data'!$E$2:$E$10000,$B6),"")
A7: DH | B7: Coimbatore | C7: =COUNTIFS('Raw Data'!$Q$2:$Q$10000,"No",'Raw Data'!$A$2:$A$10000,$C$1,'Raw Data'!$N$2:$N$10000,"DH",'Raw Data'!$E$2:$E$10000,$B7) | D7: =SUMIFS('Raw Data'!$F$2:$F$10000,'Raw Data'!$Q$2:$Q$10000,"No",'Raw Data'!$A$2:$A$10000,$C$1,'Raw Data'!$N$2:$N$10000,"DH",'Raw Data'!$E$2:$E$10000,$B7) | E7: =IFERROR(AVERAGEIFS('Raw Data'!$G$2:$G$10000,'Raw Data'!$Q$2:$Q$10000,"No",'Raw Data'!$A$2:$A$10000,$C$1,'Raw Data'!$N$2:$N$10000,"DH",'Raw Data'!$E$2:$E$10000,$B7),"") | F7: =IFERROR(AVERAGEIFS('Raw Data'!$H$2:$H$10000,'Raw Data'!$Q$2:$Q$10000,"No",'Raw Data'!$A$2:$A$10000,$C$1,'Raw Data'!$N$2:$N$10000,"DH",'Raw Data'!$E$2:$E$10000,$B7),"") | G7: =IFERROR(AVERAGEIFS('Raw Data'!$I$2:$I$10000,'Raw Data'!$Q$2:$Q$10000,"No",'Raw Data'!$A$2:$A$10000,$C$1,'Raw Data'!$N$2:$N$10000,"DH",'Raw Data'!$E$2:$E$10000,$B7),"") | H7: =IFERROR(AVERAGEIFS('Raw Data'!$J$2:$J$10000,'Raw Data'!$Q$2:$Q$10000,"No",'Raw Data'!$A$2:$A$10000,$C$1,'Raw Data'!$N$2:$N$10000,"DH",'Raw Data'!$E$2:$E$10000,$B7),"") | I7: =IFERROR(AVERAGEIFS('Raw Data'!$K$2:$K$10000,'Raw Data'!$Q$2:$Q$10000,"No",'Raw Data'!$A$2:$A$10000,$C$1,'Raw Data'!$N$2:$N$10000,"DH",'Raw Data'!$E$2:$E$10000,$B7),"") | J7: =IFERROR(AVERAGEIFS('Raw Data'!$L$2:$L$10000,'Raw Data'!$Q$2:$Q$10000,"No",'Raw Data'!$A$2:$A$10000,$C$1,'Raw Data'!$N$2:$N$10000,"DH",'Raw Data'!$E$2:$E$10000,$B7),"") | K7: =IFERROR(AVERAGEIFS('Raw Data'!$R$2:$R$10000,'Raw Data'!$Q$2:$Q$10000,"No",'Raw Data'!$A$2:$A$10000,$C$1,'Raw Data'!$N$2:$N$10000,"DH",'Raw Data'!$E$2:$E$10000,$B7),"") | L7: =IFERROR(AVERAGEIFS('Raw Data'!$S$2:$S$10000,'Raw Data'!$Q$2:$Q$10000,"No",'Raw Data'!$A$2:$A$10000,$C$1,'Raw Data'!$N$2:$N$10000,"DH",'Raw Data'!$E$2:$E$10000,$B7),"")
A8: DH | B8: Mysuru | C8: =COUNTIFS('Raw Data'!$Q$2:$Q$10000,"No",'Raw Data'!$A$2:$A$10000,$C$1,'Raw Data'!$N$2:$N$10000,"DH",'Raw Data'!$E$2:$E$10000,$B8) | D8: =SUMIFS('Raw Data'!$F$2:$F$10000,'Raw Data'!$Q$2:$Q$10000,"No",'Raw Data'!$A$2:$A$10000,$C$1,'Raw Data'!$N$2:$N$10000,"DH",'Raw Data'!$E$2:$E$10000,$B8) | E8: =IFERROR(AVERAGEIFS('Raw Data'!$G$2:$G$10000,'Raw Data'!$Q$2:$Q$10000,"No",'Raw Data'!$A$2:$A$10000,$C$1,'Raw Data'!$N$2:$N$10000,"DH",'Raw Data'!$E$2:$E$10000,$B8),"") | F8: =IFERROR(AVERAGEIFS('Raw Data'!$H$2:$H$10000,'Raw Data'!$Q$2:$Q$10000,"No",'Raw Data'!$A$2:$A$10000,$C$1,'Raw Data'!$N$2:$N$10000,"DH",'Raw Data'!$E$2:$E$10000,$B8),"") | G8: =IFERROR(AVERAGEIFS('Raw Data'!$I$2:$I$10000,'Raw Data'!$Q$2:$Q$10000,"No",'Raw Data'!$A$2:$A$10000,$C$1,'Raw Data'!$N$2:$N$10000,"DH",'Raw Data'!$E$2:$E$10000,$B8),"") | H8: =IFERROR(AVERAGEIFS('Raw Data'!$J$2:$J$10000,'Raw Data'!$Q$2:$Q$10000,"No",'Raw Data'!$A$2:$A$10000,$C$1,'Raw Data'!$N$2:$N$10000,"DH",'Raw Data'!$E$2:$E$10000,$B8),"") | I8: =IFERROR(AVERAGEIFS('Raw Data'!$K$2:$K$10000,'Raw Data'!$Q$2:$Q$10000,"No",'Raw Data'!$A$2:$A$10000,$C$1,'Raw Data'!$N$2:$N$10000,"DH",'Raw Data'!$E$2:$E$10000,$B8),"") | J8: =IFERROR(AVERAGEIFS('Raw Data'!$L$2:$L$10000,'Raw Data'!$Q$2:$Q$10000,"No",'Raw Data'!$A$2:$A$10000,$C$1,'Raw Data'!$N$2:$N$10000,"DH",'Raw Data'!$E$2:$E$10000,$B8),"") | K8: =IFERROR(AVERAGEIFS('Raw Data'!$R$2:$R$10000,'Raw Data'!$Q$2:$Q$10000,"No",'Raw Data'!$A$2:$A$10000,$C$1,'Raw Data'!$N$2:$N$10000,"DH",'Raw Data'!$E$2:$E$10000,$B8),"") | L8: =IFERROR(AVERAGEIFS('Raw Data'!$S$2:$S$10000,'Raw Data'!$Q$2:$Q$10000,"No",'Raw Data'!$A$2:$A$10000,$C$1,'Raw Data'!$N$2:$N$10000,"DH",'Raw Data'!$E$2:$E$10000,$B8),"")
A9: DH | B9: Hubballi | C9: =COUNTIFS('Raw Data'!$Q$2:$Q$10000,"No",'Raw Data'!$A$2:$A$10000,$C$1,'Raw Data'!$N$2:$N$10000,"DH",'Raw Data'!$E$2:$E$10000,$B9) | D9: =SUMIFS('Raw Data'!$F$2:$F$10000,'Raw Data'!$Q$2:$Q$10000,"No",'Raw Data'!$A$2:$A$10000,$C$1,'Raw Data'!$N$2:$N$10000,"DH",'Raw Data'!$E$2:$E$10000,$B9) | E9: =IFERROR(AVERAGEIFS('Raw Data'!$G$2:$G$10000,'Raw Data'!$Q$2:$Q$10000,"No",'Raw Data'!$A$2:$A$10000,$C$1,'Raw Data'!$N$2:$N$10000,"DH",'Raw Data'!$E$2:$E$10000,$B9),"") | F9: =IFERROR(AVERAGEIFS('Raw Data'!$H$2:$H$10000,'Raw Data'!$Q$2:$Q$10000,"No",'Raw Data'!$A$2:$A$10000,$C$1,'Raw Data'!$N$2:$N$10000,"DH",'Raw Data'!$E$2:$E$10000,$B9),"") | G9: =IFERROR(AVERAGEIFS('Raw Data'!$I$2:$I$10000,'Raw Data'!$Q$2:$Q$10000,"No",'Raw Data'!$A$2:$A$10000,$C$1,'Raw Data'!$N$2:$N$10000,"DH",'Raw Data'!$E$2:$E$10000,$B9),"") | H9: =IFERROR(AVERAGEIFS('Raw Data'!$J$2:$J$10000,'Raw Data'!$Q$2:$Q$10000,"No",'Raw Data'!$A$2:$A$10000,$C$1,'Raw Data'!$N$2:$N$10000,"DH",'Raw Data'!$E$2:$E$10000,$B9),"") | I9: =IFERROR(AVERAGEIFS('Raw Data'!$K$2:$K$10000,'Raw Data'!$Q$2:$Q$10000,"No",'Raw Data'!$A$2:$A$10000,$C$1,'Raw Data'!$N$2:$N$10000,"DH",'Raw Data'!$E$2:$E$10000,$B9),"") | J9: =IFERROR(AVERAGEIFS('Raw Data'!$L$2:$L$10000,'Raw Data'!$Q$2:$Q$10000,"No",'Raw Data'!$A$2:$A$10000,$C$1,'Raw Data'!$N$2:$N$10000,"DH",'Raw Data'!$E$2:$E$10000,$B9),"") | K9: =IFERROR(AVERAGEIFS('Raw Data'!$R$2:$R$10000,'Raw Data'!$Q$2:$Q$10000,"No",'Raw Data'!$A$2:$A$10000,$C$1,'Raw Data'!$N$2:$N$10000,"DH",'Raw Data'!$E$2:$E$10000,$B9),"") | L9: =IFERROR(AVERAGEIFS('Raw Data'!$S$2:$S$10000,'Raw Data'!$Q$2:$Q$10000,"No",'Raw Data'!$A$2:$A$10000,$C$1,'Raw Data'!$N$2:$N$10000,"DH",'Raw Data'!$E$2:$E$10000,$B9),"")
A10: DH | B10: Palakkad | C10: =COUNTIFS('Raw Data'!$Q$2:$Q$10000,"No",'Raw Data'!$A$2:$A$10000,$C$1,'Raw Data'!$N$2:$N$10000,"DH",'Raw Data'!$E$2:$E$10000,$B10) | D10: =SUMIFS('Raw Data'!$F$2:$F$10000,'Raw Data'!$Q$2:$Q$10000,"No",'Raw Data'!$A$2:$A$10000,$C$1,'Raw Data'!$N$2:$N$10000,"DH",'Raw Data'!$E$2:$E$10000,$B10) | E10: =IFERROR(AVERAGEIFS('Raw Data'!$G$2:$G$10000,'Raw Data'!$Q$2:$Q$10000,"No",'Raw Data'!$A$2:$A$10000,$C$1,'Raw Data'!$N$2:$N$10000,"DH",'Raw Data'!$E$2:$E$10000,$B10),"") | F10: =IFERROR(AVERAGEIFS('Raw Data'!$H$2:$H$10000,'Raw Data'!$Q$2:$Q$10000,"No",'Raw Data'!$A$2:$A$10000,$C$1,'Raw Data'!$N$2:$N$10000,"DH",'Raw Data'!$E$2:$E$10000,$B10),"") | G10: =IFERROR(AVERAGEIFS('Raw Data'!$I$2:$I$10000,'Raw Data'!$Q$2:$Q$10000,"No",'Raw Data'!$A$2:$A$10000,$C$1,'Raw Data'!$N$2:$N$10000,"DH",'Raw Data'!$E$2:$E$10000,$B10),"") | H10: =IFERROR(AVERAGEIFS('Raw Data'!$J$2:$J$10000,'Raw Data'!$Q$2:$Q$10000,"No",'Raw Data'!$A$2:$A$10000,$C$1,'Raw Data'!$N$2:$N$10000,"DH",'Raw Data'!$E$2:$E$10000,$B10),"") | I10: =IFERROR(AVERAGEIFS('Raw Data'!$K$2:$K$10000,'Raw Data'!$Q$2:$Q$10000,"No",'Raw Data'!$A$2:$A$10000,$C$1,'Raw Data'!$N$2:$N$10000,"DH",'Raw Data'!$E$2:$E$10000,$B10),"") | J10: =IFERROR(AVERAGEIFS('Raw Data'!$L$2:$L$10000,'Raw Data'!$Q$2:$Q$10000,"No",'Raw Data'!$A$2:$A$10000,$C$1,'Raw Data'!$N$2:$N$10000,"DH",'Raw Data'!$E$2:$E$10000,$B10),"") | K10: =IFERROR(AVERAGEIFS('Raw Data'!$R$2:$R$10000,'Raw Data'!$Q$2:$Q$10000,"No",'Raw Data'!$A$2:$A$10000,$C$1,'Raw Data'!$N$2:$N$10000,"DH",'Raw Data'!$E$2:$E$10000,$B10),"") | L10: =IFERROR(AVERAGEIFS('Raw Data'!$S$2:$S$10000,'Raw Data'!$Q$2:$Q$10000,"No",'Raw Data'!$A$2:$A$10000,$C$1,'Raw Data'!$N$2:$N$10000,"DH",'Raw Data'!$E$2:$E$10000,$B10),"")
A11: DH | B11: Belgavi | C11: =COUNTIFS('Raw Data'!$Q$2:$Q$10000,"No",'Raw Data'!$A$2:$A$10000,$C$1,'Raw Data'!$N$2:$N$10000,"DH",'Raw Data'!$E$2:$E$10000,$B11) | D11: =SUMIFS('Raw Data'!$F$2:$F$10000,'Raw Data'!$Q$2:$Q$10000,"No",'Raw Data'!$A$2:$A$10000,$C$1,'Raw Data'!$N$2:$N$10000,"DH",'Raw Data'!$E$2:$E$10000,$B11) | E11: =IFERROR(AVERAGEIFS('Raw Data'!$G$2:$G$10000,'Raw Data'!$Q$2:$Q$10000,"No",'Raw Data'!$A$2:$A$10000,$C$1,'Raw Data'!$N$2:$N$10000,"DH",'Raw Data'!$E$2:$E$10000,$B11),"") | F11: =IFERROR(AVERAGEIFS('Raw Data'!$H$2:$H$10000,'Raw Data'!$Q$2:$Q$10000,"No",'Raw Data'!$A$2:$A$10000,$C$1,'Raw Data'!$N$2:$N$10000,"DH",'Raw Data'!$E$2:$E$10000,$B11),"") | G11: =IFERROR(AVERAGEIFS('Raw Data'!$I$2:$I$10000,'Raw Data'!$Q$2:$Q$10000,"No",'Raw Data'!$A$2:$A$10000,$C$1,'Raw Data'!$N$2:$N$10000,"DH",'Raw Data'!$E$2:$E$10000,$B11),"") | H11: =IFERROR(AVERAGEIFS('Raw Data'!$J$2:$J$10000,'Raw Data'!$Q$2:$Q$10000,"No",'Raw Data'!$A$2:$A$10000,$C$1,'Raw Data'!$N$2:$N$10000,"DH",'Raw Data'!$E$2:$E$10000,$B11),"") | I11: =IFERROR(AVERAGEIFS('Raw Data'!$K$2:$K$10000,'Raw Data'!$Q$2:$Q$10000,"No",'Raw Data'!$A$2:$A$10000,$C$1,'Raw Data'!$N$2:$N$10000,"DH",'Raw Data'!$E$2:$E$10000,$B11),"") | J11: =IFERROR(AVERAGEIFS('Raw Data'!$L$2:$L$10000,'Raw Data'!$Q$2:$Q$10000,"No",'Raw Data'!$A$2:$A$10000,$C$1,'Raw Data'!$N$2:$N$10000,"DH",'Raw Data'!$E$2:$E$10000,$B11),"") | K11: =IFERROR(AVERAGEIFS('Raw Data'!$R$2:$R$10000,'Raw Data'!$Q$2:$Q$10000,"No",'Raw Data'!$A$2:$A$10000,$C$1,'Raw Data'!$N$2:$N$10000,"DH",'Raw Data'!$E$2:$E$10000,$B11),"") | L11: =IFERROR(AVERAGEIFS('Raw Data'!$S$2:$S$10000,'Raw Data'!$Q$2:$Q$10000,"No",'Raw Data'!$A$2:$A$10000,$C$1,'Raw Data'!$N$2:$N$10000,"DH",'Raw Data'!$E$2:$E$10000,$B11),"")
A12: DH | B12: Davanagere | C12: =COUNTIFS('Raw Data'!$Q$2:$Q$10000,"No",'Raw Data'!$A$2:$A$10000,$C$1,'Raw Data'!$N$2:$N$10000,"DH",'Raw Data'!$E$2:$E$10000,$B12) | D12: =SUMIFS('Raw Data'!$F$2:$F$10000,'Raw Data'!$Q$2:$Q$10000,"No",'Raw Data'!$A$2:$A$10000,$C$1,'Raw Data'!$N$2:$N$10000,"DH",'Raw Data'!$E$2:$E$10000,$B12) | E12: =IFERROR(AVERAGEIFS('Raw Data'!$G$2:$G$10000,'Raw Data'!$Q$2:$Q$10000,"No",'Raw Data'!$A$2:$A$10000,$C$1,'Raw Data'!$N$2:$N$10000,"DH",'Raw Data'!$E$2:$E$10000,$B12),"") | F12: =IFERROR(AVERAGEIFS('Raw Data'!$H$2:$H$10000,'Raw Data'!$Q$2:$Q$10000,"No",'Raw Data'!$A$2:$A$10000,$C$1,'Raw Data'!$N$2:$N$10000,"DH",'Raw Data'!$E$2:$E$10000,$B12),"") | G12: =IFERROR(AVERAGEIFS('Raw Data'!$I$2:$I$10000,'Raw Data'!$Q$2:$Q$10000,"No",'Raw Data'!$A$2:$A$10000,$C$1,'Raw Data'!$N$2:$N$10000,"DH",'Raw Data'!$E$2:$E$10000,$B12),"") | H12: =IFERROR(AVERAGEIFS('Raw Data'!$J$2:$J$10000,'Raw Data'!$Q$2:$Q$10000,"No",'Raw Data'!$A$2:$A$10000,$C$1,'Raw Data'!$N$2:$N$10000,"DH",'Raw Data'!$E$2:$E$10000,$B12),"") | I12: =IFERROR(AVERAGEIFS('Raw Data'!$K$2:$K$10000,'Raw Data'!$Q$2:$Q$10000,"No",'Raw Data'!$A$2:$A$10000,$C$1,'Raw Data'!$N$2:$N$10000,"DH",'Raw Data'!$E$2:$E$10000,$B12),"") | J12: =IFERROR(AVERAGEIFS('Raw Data'!$L$2:$L$10000,'Raw Data'!$Q$2:$Q$10000,"No",'Raw Data'!$A$2:$A$10000,$C$1,'Raw Data'!$N$2:$N$10000,"DH",'Raw Data'!$E$2:$E$10000,$B12),"") | K12: =IFERROR(AVERAGEIFS('Raw Data'!$R$2:$R$10000,'Raw Data'!$Q$2:$Q$10000,"No",'Raw Data'!$A$2:$A$10000,$C$1,'Raw Data'!$N$2:$N$10000,"DH",'Raw Data'!$E$2:$E$10000,$B12),"") | L12: =IFERROR(AVERAGEIFS('Raw Data'!$S$2:$S$10000,'Raw Data'!$Q$2:$Q$10000,"No",'Raw Data'!$A$2:$A$10000,$C$1,'Raw Data'!$N$2:$N$10000,"DH",'Raw Data'!$E$2:$E$10000,$B12),"")
A13: DH | B13: Hosur | C13: =COUNTIFS('Raw Data'!$Q$2:$Q$10000,"No",'Raw Data'!$A$2:$A$10000,$C$1,'Raw Data'!$N$2:$N$10000,"DH",'Raw Data'!$E$2:$E$10000,$B13) | D13: =SUMIFS('Raw Data'!$F$2:$F$10000,'Raw Data'!$Q$2:$Q$10000,"No",'Raw Data'!$A$2:$A$10000,$C$1,'Raw Data'!$N$2:$N$10000,"DH",'Raw Data'!$E$2:$E$10000,$B13) | E13: =IFERROR(AVERAGEIFS('Raw Data'!$G$2:$G$10000,'Raw Data'!$Q$2:$Q$10000,"No",'Raw Data'!$A$2:$A$10000,$C$1,'Raw Data'!$N$2:$N$10000,"DH",'Raw Data'!$E$2:$E$10000,$B13),"") | F13: =IFERROR(AVERAGEIFS('Raw Data'!$H$2:$H$10000,'Raw Data'!$Q$2:$Q$10000,"No",'Raw Data'!$A$2:$A$10000,$C$1,'Raw Data'!$N$2:$N$10000,"DH",'Raw Data'!$E$2:$E$10000,$B13),"") | G13: =IFERROR(AVERAGEIFS('Raw Data'!$I$2:$I$10000,'Raw Data'!$Q$2:$Q$10000,"No",'Raw Data'!$A$2:$A$10000,$C$1,'Raw Data'!$N$2:$N$10000,"DH",'Raw Data'!$E$2:$E$10000,$B13),"") | H13: =IFERROR(AVERAGEIFS('Raw Data'!$J$2:$J$10000,'Raw Data'!$Q$2:$Q$10000,"No",'Raw Data'!$A$2:$A$10000,$C$1,'Raw Data'!$N$2:$N$10000,"DH",'Raw Data'!$E$2:$E$10000,$B13),"") | I13: =IFERROR(AVERAGEIFS('Raw Data'!$K$2:$K$10000,'Raw Data'!$Q$2:$Q$10000,"No",'Raw Data'!$A$2:$A$10000,$C$1,'Raw Data'!$N$2:$N$10000,"DH",'Raw Data'!$E$2:$E$10000,$B13),"") | J13: =IFERROR(AVERAGEIFS('Raw Data'!$L$2:$L$10000,'Raw Data'!$Q$2:$Q$10000,"No",'Raw Data'!$A$2:$A$10000,$C$1,'Raw Data'!$N$2:$N$10000,"DH",'Raw Data'!$E$2:$E$10000,$B13),"") | K13: =IFERROR(AVERAGEIFS('Raw Data'!$R$2:$R$10000,'Raw Data'!$Q$2:$Q$10000,"No",'Raw Data'!$A$2:$A$10000,$C$1,'Raw Data'!$N$2:$N$10000,"DH",'Raw Data'!$E$2:$E$10000,$B13),"") | L13: =IFERROR(AVERAGEIFS('Raw Data'!$S$2:$S$10000,'Raw Data'!$Q$2:$Q$10000,"No",'Raw Data'!$A$2:$A$10000,$C$1,'Raw Data'!$N$2:$N$10000,"DH",'Raw Data'!$E$2:$E$10000,$B13),"")
A14: DH | B14: Tumkuru | C14: =COUNTIFS('Raw Data'!$Q$2:$Q$10000,"No",'Raw Data'!$A$2:$A$10000,$C$1,'Raw Data'!$N$2:$N$10000,"DH",'Raw Data'!$E$2:$E$10000,$B14) | D14: =SUMIFS('Raw Data'!$F$2:$F$10000,'Raw Data'!$Q$2:$Q$10000,"No",'Raw Data'!$A$2:$A$10000,$C$1,'Raw Data'!$N$2:$N$10000,"DH",'Raw Data'!$E$2:$E$10000,$B14) | E14: =IFERROR(AVERAGEIFS('Raw Data'!$G$2:$G$10000,'Raw Data'!$Q$2:$Q$10000,"No",'Raw Data'!$A$2:$A$10000,$C$1,'Raw Data'!$N$2:$N$10000,"DH",'Raw Data'!$E$2:$E$10000,$B14),"") | F14: =IFERROR(AVERAGEIFS('Raw Data'!$H$2:$H$10000,'Raw Data'!$Q$2:$Q$10000,"No",'Raw Data'!$A$2:$A$10000,$C$1,'Raw Data'!$N$2:$N$10000,"DH",'Raw Data'!$E$2:$E$10000,$B14),"") | G14: =IFERROR(AVERAGEIFS('Raw Data'!$I$2:$I$10000,'Raw Data'!$Q$2:$Q$10000,"No",'Raw Data'!$A$2:$A$10000,$C$1,'Raw Data'!$N$2:$N$10000,"DH",'Raw Data'!$E$2:$E$10000,$B14),"") | H14: =IFERROR(AVERAGEIFS('Raw Data'!$J$2:$J$10000,'Raw Data'!$Q$2:$Q$10000,"No",'Raw Data'!$A$2:$A$10000,$C$1,'Raw Data'!$N$2:$N$10000,"DH",'Raw Data'!$E$2:$E$10000,$B14),"") | I14: =IFERROR(AVERAGEIFS('Raw Data'!$K$2:$K$10000,'Raw Data'!$Q$2:$Q$10000,"No",'Raw Data'!$A$2:$A$10000,$C$1,'Raw Data'!$N$2:$N$10000,"DH",'Raw Data'!$E$2:$E$10000,$B14),"") | J14: =IFERROR(AVERAGEIFS('Raw Data'!$L$2:$L$10000,'Raw Data'!$Q$2:$Q$10000,"No",'Raw Data'!$A$2:$A$10000,$C$1,'Raw Data'!$N$2:$N$10000,"DH",'Raw Data'!$E$2:$E$10000,$B14),"") | K14: =IFERROR(AVERAGEIFS('Raw Data'!$R$2:$R$10000,'Raw Data'!$Q$2:$Q$10000,"No",'Raw Data'!$A$2:$A$10000,$C$1,'Raw Data'!$N$2:$N$10000,"DH",'Raw Data'!$E$2:$E$10000,$B14),"") | L14: =IFERROR(AVERAGEIFS('Raw Data'!$S$2:$S$10000,'Raw Data'!$Q$2:$Q$10000,"No",'Raw Data'!$A$2:$A$10000,$C$1,'Raw Data'!$N$2:$N$10000,"DH",'Raw Data'!$E$2:$E$10000,$B14),"")
A15: DH | B15: Grand Total | C15: =COUNTIFS('Raw Data'!$Q$2:$Q$10000,"No",'Raw Data'!$A$2:$A$10000,$C$1,'Raw Data'!$N$2:$N$10000,"DH",'Raw Data'!$E$2:$E$10000,"<>") | D15: =SUMIFS('Raw Data'!$F$2:$F$10000,'Raw Data'!$Q$2:$Q$10000,"No",'Raw Data'!$A$2:$A$10000,$C$1,'Raw Data'!$N$2:$N$10000,"DH",'Raw Data'!$E$2:$E$10000,"<>") | E15: =IFERROR(AVERAGEIFS('Raw Data'!$G$2:$G$10000,'Raw Data'!$Q$2:$Q$10000,"No",'Raw Data'!$A$2:$A$10000,$C$1,'Raw Data'!$N$2:$N$10000,"DH",'Raw Data'!$E$2:$E$10000,"<>"),"") | F15: =IFERROR(AVERAGEIFS('Raw Data'!$H$2:$H$10000,'Raw Data'!$Q$2:$Q$10000,"No",'Raw Data'!$A$2:$A$10000,$C$1,'Raw Data'!$N$2:$N$10000,"DH",'Raw Data'!$E$2:$E$10000,"<>"),"") | G15: =IFERROR(AVERAGEIFS('Raw Data'!$I$2:$I$10000,'Raw Data'!$Q$2:$Q$10000,"No",'Raw Data'!$A$2:$A$10000,$C$1,'Raw Data'!$N$2:$N$10000,"DH",'Raw Data'!$E$2:$E$10000,"<>"),"") | H15: =IFERROR(AVERAGEIFS('Raw Data'!$J$2:$J$10000,'Raw Data'!$Q$2:$Q$10000,"No",'Raw Data'!$A$2:$A$10000,$C$1,'Raw Data'!$N$2:$N$10000,"DH",'Raw Data'!$E$2:$E$10000,"<>"),"") | I15: =IFERROR(AVERAGEIFS('Raw Data'!$K$2:$K$10000,'Raw Data'!$Q$2:$Q$10000,"No",'Raw Data'!$A$2:$A$10000,$C$1,'Raw Data'!$N$2:$N$10000,"DH",'Raw Data'!$E$2:$E$10000,"<>"),"") | J15: =IFERROR(AVERAGEIFS('Raw Data'!$L$2:$L$10000,'Raw Data'!$Q$2:$Q$10000,"No",'Raw Data'!$A$2:$A$10000,$C$1,'Raw Data'!$N$2:$N$10000,"DH",'Raw Data'!$E$2:$E$10000,"<>"),"") | K15: =IFERROR(AVERAGEIFS('Raw Data'!$R$2:$R$10000,'Raw Data'!$Q$2:$Q$10000,"No",'Raw Data'!$A$2:$A$10000,$C$1,'Raw Data'!$N$2:$N$10000,"DH",'Raw Data'!$E$2:$E$10000,"<>"),"") | L15: =IFERROR(AVERAGEIFS('Raw Data'!$S$2:$S$10000,'Raw Data'!$Q$2:$Q$10000,"No",'Raw Data'!$A$2:$A$10000,$C$1,'Raw Data'!$N$2:$N$10000,"DH",'Raw Data'!$E$2:$E$10000,"<>"),"")
A17: Superstore - City Split
A18: Type | B18: City | C18: Store Count | D18: Total Bins | E18: CC MTD % | F18: BA MTD % | G18: IA MTD % | H18: CC ACC % | I18: PD % | J18: Inv Health | K18: CC MTD Target | L18: CC MTD Achieved %
A19: Superstore | B19: Bengaluru | C19: =COUNTIFS('Raw Data'!$Q$2:$Q$10000,"No",'Raw Data'!$A$2:$A$10000,$C$1,'Raw Data'!$N$2:$N$10000,"Superstore",'Raw Data'!$E$2:$E$10000,$B19) | D19: =SUMIFS('Raw Data'!$F$2:$F$10000,'Raw Data'!$Q$2:$Q$10000,"No",'Raw Data'!$A$2:$A$10000,$C$1,'Raw Data'!$N$2:$N$10000,"Superstore",'Raw Data'!$E$2:$E$10000,$B19) | E19: =IFERROR(AVERAGEIFS('Raw Data'!$G$2:$G$10000,'Raw Data'!$Q$2:$Q$10000,"No",'Raw Data'!$A$2:$A$10000,$C$1,'Raw Data'!$N$2:$N$10000,"Superstore",'Raw Data'!$E$2:$E$10000,$B19),"") | F19: =IFERROR(AVERAGEIFS('Raw Data'!$H$2:$H$10000,'Raw Data'!$Q$2:$Q$10000,"No",'Raw Data'!$A$2:$A$10000,$C$1,'Raw Data'!$N$2:$N$10000,"Superstore",'Raw Data'!$E$2:$E$10000,$B19),"") | G19: =IFERROR(AVERAGEIFS('Raw Data'!$I$2:$I$10000,'Raw Data'!$Q$2:$Q$10000,"No",'Raw Data'!$A$2:$A$10000,$C$1,'Raw Data'!$N$2:$N$10000,"Superstore",'Raw Data'!$E$2:$E$10000,$B19),"") | H19: =IFERROR(AVERAGEIFS('Raw Data'!$J$2:$J$10000,'Raw Data'!$Q$2:$Q$10000,"No",'Raw Data'!$A$2:$A$10000,$C$1,'Raw Data'!$N$2:$N$10000,"Superstore",'Raw Data'!$E$2:$E$10000,$B19),"") | I19: =IFERROR(AVERAGEIFS('Raw Data'!$K$2:$K$10000,'Raw Data'!$Q$2:$Q$10000,"No",'Raw Data'!$A$2:$A$10000,$C$1,'Raw Data'!$N$2:$N$10000,"Superstore",'Raw Data'!$E$2:$E$10000,$B19),"") | J19: =IFERROR(AVERAGEIFS('Raw Data'!$L$2:$L$10000,'Raw Data'!$Q$2:$Q$10000,"No",'Raw Data'!$A$2:$A$10000,$C$1,'Raw Data'!$N$2:$N$10000,"Superstore",'Raw Data'!$E$2:$E$10000,$B19),"") | K19: =IFERROR(AVERAGEIFS('Raw Data'!$R$2:$R$10000,'Raw Data'!$Q$2:$Q$10000,"No",'Raw Data'!$A$2:$A$10000,$C$1,'Raw Data'!$N$2:$N$10000,"Superstore",'Raw Data'!$E$2:$E$10000,$B19),"") | L19: =IFERROR(AVERAGEIFS('Raw Data'!$S$2:$S$10000,'Raw Data'!$Q$2:$Q$10000,"No",'Raw Data'!$A$2:$A$10000,$C$1,'Raw Data'!$N$2:$N$10000,"Superstore",'Raw Data'!$E$2:$E$10000,$B19),"")
A20: Superstore | B20: Kochi | C20: =COUNTIFS('Raw Data'!$Q$2:$Q$10000,"No",'Raw Data'!$A$2:$A$10000,$C$1,'Raw Data'!$N$2:$N$10000,"Superstore",'Raw Data'!$E$2:$E$10000,$B20) | D20: =SUMIFS('Raw Data'!$F$2:$F$10000,'Raw Data'!$Q$2:$Q$10000,"No",'Raw Data'!$A$2:$A$10000,$C$1,'Raw Data'!$N$2:$N$10000,"Superstore",'Raw Data'!$E$2:$E$10000,$B20) | E20: =IFERROR(AVERAGEIFS('Raw Data'!$G$2:$G$10000,'Raw Data'!$Q$2:$Q$10000,"No",'Raw Data'!$A$2:$A$10000,$C$1,'Raw Data'!$N$2:$N$10000,"Superstore",'Raw Data'!$E$2:$E$10000,$B20),"") | F20: =IFERROR(AVERAGEIFS('Raw Data'!$H$2:$H$10000,'Raw Data'!$Q$2:$Q$10000,"No",'Raw Data'!$A$2:$A$10000,$C$1,'Raw Data'!$N$2:$N$10000,"Superstore",'Raw Data'!$E$2:$E$10000,$B20),"") | G20: =IFERROR(AVERAGEIFS('Raw Data'!$I$2:$I$10000,'Raw Data'!$Q$2:$Q$10000,"No",'Raw Data'!$A$2:$A$10000,$C$1,'Raw Data'!$N$2:$N$10000,"Superstore",'Raw Data'!$E$2:$E$10000,$B20),"") | H20: =IFERROR(AVERAGEIFS('Raw Data'!$J$2:$J$10000,'Raw Data'!$Q$2:$Q$10000,"No",'Raw Data'!$A$2:$A$10000,$C$1,'Raw Data'!$N$2:$N$10000,"Superstore",'Raw Data'!$E$2:$E$10000,$B20),"") | I20: =IFERROR(AVERAGEIFS('Raw Data'!$K$2:$K$10000,'Raw Data'!$Q$2:$Q$10000,"No",'Raw Data'!$A$2:$A$10000,$C$1,'Raw Data'!$N$2:$N$10000,"Superstore",'Raw Data'!$E$2:$E$10000,$B20),"") | J20: =IFERROR(AVERAGEIFS('Raw Data'!$L$2:$L$10000,'Raw Data'!$Q$2:$Q$10000,"No",'Raw Data'!$A$2:$A$10000,$C$1,'Raw Data'!$N$2:$N$10000,"Superstore",'Raw Data'!$E$2:$E$10000,$B20),"") | K20: =IFERROR(AVERAGEIFS('Raw Data'!$R$2:$R$10000,'Raw Data'!$Q$2:$Q$10000,"No",'Raw Data'!$A$2:$A$10000,$C$1,'Raw Data'!$N$2:$N$10000,"Superstore",'Raw Data'!$E$2:$E$10000,$B20),"") | L20: =IFERROR(AVERAGEIFS('Raw Data'!$S$2:$S$10000,'Raw Data'!$Q$2:$Q$10000,"No",'Raw Data'!$A$2:$A$10000,$C$1,'Raw Data'!$N$2:$N$10000,"Superstore",'Raw Data'!$E$2:$E$10000,$B20),"")
A21: Superstore | B21: Coimbatore | C21: =COUNTIFS('Raw Data'!$Q$2:$Q$10000,"No",'Raw Data'!$A$2:$A$10000,$C$1,'Raw Data'!$N$2:$N$10000,"Superstore",'Raw Data'!$E$2:$E$10000,$B21) | D21: =SUMIFS('Raw Data'!$F$2:$F$10000,'Raw Data'!$Q$2:$Q$10000,"No",'Raw Data'!$A$2:$A$10000,$C$1,'Raw Data'!$N$2:$N$10000,"Superstore",'Raw Data'!$E$2:$E$10000,$B21) | E21: =IFERROR(AVERAGEIFS('Raw Data'!$G$2:$G$10000,'Raw Data'!$Q$2:$Q$10000,"No",'Raw Data'!$A$2:$A$10000,$C$1,'Raw Data'!$N$2:$N$10000,"Superstore",'Raw Data'!$E$2:$E$10000,$B21),"") | F21: =IFERROR(AVERAGEIFS('Raw Data'!$H$2:$H$10000,'Raw Data'!$Q$2:$Q$10000,"No",'Raw Data'!$A$2:$A$10000,$C$1,'Raw Data'!$N$2:$N$10000,"Superstore",'Raw Data'!$E$2:$E$10000,$B21),"") | G21: =IFERROR(AVERAGEIFS('Raw Data'!$I$2:$I$10000,'Raw Data'!$Q$2:$Q$10000,"No",'Raw Data'!$A$2:$A$10000,$C$1,'Raw Data'!$N$2:$N$10000,"Superstore",'Raw Data'!$E$2:$E$10000,$B21),"") | H21: =IFERROR(AVERAGEIFS('Raw Data'!$J$2:$J$10000,'Raw Data'!$Q$2:$Q$10000,"No",'Raw Data'!$A$2:$A$10000,$C$1,'Raw Data'!$N$2:$N$10000,"Superstore",'Raw Data'!$E$2:$E$10000,$B21),"") | I21: =IFERROR(AVERAGEIFS('Raw Data'!$K$2:$K$10000,'Raw Data'!$Q$2:$Q$10000,"No",'Raw Data'!$A$2:$A$10000,$C$1,'Raw Data'!$N$2:$N$10000,"Superstore",'Raw Data'!$E$2:$E$10000,$B21),"") | J21: =IFERROR(AVERAGEIFS('Raw Data'!$L$2:$L$10000,'Raw Data'!$Q$2:$Q$10000,"No",'Raw Data'!$A$2:$A$10000,$C$1,'Raw Data'!$N$2:$N$10000,"Superstore",'Raw Data'!$E$2:$E$10000,$B21),"") | K21: =IFERROR(AVERAGEIFS('Raw Data'!$R$2:$R$10000,'Raw Data'!$Q$2:$Q$10000,"No",'Raw Data'!$A$2:$A$10000,$C$1,'Raw Data'!$N$2:$N$10000,"Superstore",'Raw Data'!$E$2:$E$10000,$B21),"") | L21: =IFERROR(AVERAGEIFS('Raw Data'!$S$2:$S$10000,'Raw Data'!$Q$2:$Q$10000,"No",'Raw Data'!$A$2:$A$10000,$C$1,'Raw Data'!$N$2:$N$10000,"Superstore",'Raw Data'!$E$2:$E$10000,$B21),"")
A22: Superstore | B22: Mysuru | C22: =COUNTIFS('Raw Data'!$Q$2:$Q$10000,"No",'Raw Data'!$A$2:$A$10000,$C$1,'Raw Data'!$N$2:$N$10000,"Superstore",'Raw Data'!$E$2:$E$10000,$B22) | D22: =SUMIFS('Raw Data'!$F$2:$F$10000,'Raw Data'!$Q$2:$Q$10000,"No",'Raw Data'!$A$2:$A$10000,$C$1,'Raw Data'!$N$2:$N$10000,"Superstore",'Raw Data'!$E$2:$E$10000,$B22) | E22: =IFERROR(AVERAGEIFS('Raw Data'!$G$2:$G$10000,'Raw Data'!$Q$2:$Q$10000,"No",'Raw Data'!$A$2:$A$10000,$C$1,'Raw Data'!$N$2:$N$10000,"Superstore",'Raw Data'!$E$2:$E$10000,$B22),"") | F22: =IFERROR(AVERAGEIFS('Raw Data'!$H$2:$H$10000,'Raw Data'!$Q$2:$Q$10000,"No",'Raw Data'!$A$2:$A$10000,$C$1,'Raw Data'!$N$2:$N$10000,"Superstore",'Raw Data'!$E$2:$E$10000,$B22),"") | G22: =IFERROR(AVERAGEIFS('Raw Data'!$I$2:$I$10000,'Raw Data'!$Q$2:$Q$10000,"No",'Raw Data'!$A$2:$A$10000,$C$1,'Raw Data'!$N$2:$N$10000,"Superstore",'Raw Data'!$E$2:$E$10000,$B22),"") | H22: =IFERROR(AVERAGEIFS('Raw Data'!$J$2:$J$10000,'Raw Data'!$Q$2:$Q$10000,"No",'Raw Data'!$A$2:$A$10000,$C$1,'Raw Data'!$N$2:$N$10000,"Superstore",'Raw Data'!$E$2:$E$10000,$B22),"") | I22: =IFERROR(AVERAGEIFS('Raw Data'!$K$2:$K$10000,'Raw Data'!$Q$2:$Q$10000,"No",'Raw Data'!$A$2:$A$10000,$C$1,'Raw Data'!$N$2:$N$10000,"Superstore",'Raw Data'!$E$2:$E$10000,$B22),"") | J22: =IFERROR(AVERAGEIFS('Raw Data'!$L$2:$L$10000,'Raw Data'!$Q$2:$Q$10000,"No",'Raw Data'!$A$2:$A$10000,$C$1,'Raw Data'!$N$2:$N$10000,"Superstore",'Raw Data'!$E$2:$E$10000,$B22),"") | K22: =IFERROR(AVERAGEIFS('Raw Data'!$R$2:$R$10000,'Raw Data'!$Q$2:$Q$10000,"No",'Raw Data'!$A$2:$A$10000,$C$1,'Raw Data'!$N$2:$N$10000,"Superstore",'Raw Data'!$E$2:$E$10000,$B22),"") | L22: =IFERROR(AVERAGEIFS('Raw Data'!$S$2:$S$10000,'Raw Data'!$Q$2:$Q$10000,"No",'Raw Data'!$A$2:$A$10000,$C$1,'Raw Data'!$N$2:$N$10000,"Superstore",'Raw Data'!$E$2:$E$10000,$B22),"")
A23: Superstore | B23: Hubballi | C23: =COUNTIFS('Raw Data'!$Q$2:$Q$10000,"No",'Raw Data'!$A$2:$A$10000,$C$1,'Raw Data'!$N$2:$N$10000,"Superstore",'Raw Data'!$E$2:$E$10000,$B23) | D23: =SUMIFS('Raw Data'!$F$2:$F$10000,'Raw Data'!$Q$2:$Q$10000,"No",'Raw Data'!$A$2:$A$10000,$C$1,'Raw Data'!$N$2:$N$10000,"Superstore",'Raw Data'!$E$2:$E$10000,$B23) | E23: =IFERROR(AVERAGEIFS('Raw Data'!$G$2:$G$10000,'Raw Data'!$Q$2:$Q$10000,"No",'Raw Data'!$A$2:$A$10000,$C$1,'Raw Data'!$N$2:$N$10000,"Superstore",'Raw Data'!$E$2:$E$10000,$B23),"") | F23: =IFERROR(AVERAGEIFS('Raw Data'!$H$2:$H$10000,'Raw Data'!$Q$2:$Q$10000,"No",'Raw Data'!$A$2:$A$10000,$C$1,'Raw Data'!$N$2:$N$10000,"Superstore",'Raw Data'!$E$2:$E$10000,$B23),"") | G23: =IFERROR(AVERAGEIFS('Raw Data'!$I$2:$I$10000,'Raw Data'!$Q$2:$Q$10000,"No",'Raw Data'!$A$2:$A$10000,$C$1,'Raw Data'!$N$2:$N$10000,"Superstore",'Raw Data'!$E$2:$E$10000,$B23),"") | H23: =IFERROR(AVERAGEIFS('Raw Data'!$J$2:$J$10000,'Raw Data'!$Q$2:$Q$10000,"No",'Raw Data'!$A$2:$A$10000,$C$1,'Raw Data'!$N$2:$N$10000,"Superstore",'Raw Data'!$E$2:$E$10000,$B23),"") | I23: =IFERROR(AVERAGEIFS('Raw Data'!$K$2:$K$10000,'Raw Data'!$Q$2:$Q$10000,"No",'Raw Data'!$A$2:$A$10000,$C$1,'Raw Data'!$N$2:$N$10000,"Superstore",'Raw Data'!$E$2:$E$10000,$B23),"") | J23: =IFERROR(AVERAGEIFS('Raw Data'!$L$2:$L$10000,'Raw Data'!$Q$2:$Q$10000,"No",'Raw Data'!$A$2:$A$10000,$C$1,'Raw Data'!$N$2:$N$10000,"Superstore",'Raw Data'!$E$2:$E$10000,$B23),"") | K23: =IFERROR(AVERAGEIFS('Raw Data'!$R$2:$R$10000,'Raw Data'!$Q$2:$Q$10000,"No",'Raw Data'!$A$2:$A$10000,$C$1,'Raw Data'!$N$2:$N$10000,"Superstore",'Raw Data'!$E$2:$E$10000,$B23),"") | L23: =IFERROR(AVERAGEIFS('Raw Data'!$S$2:$S$10000,'Raw Data'!$Q$2:$Q$10000,"No",'Raw Data'!$A$2:$A$10000,$C$1,'Raw Data'!$N$2:$N$10000,"Superstore",'Raw Data'!$E$2:$E$10000,$B23),"")
A24: Superstore | B24: Palakkad | C24: =COUNTIFS('Raw Data'!$Q$2:$Q$10000,"No",'Raw Data'!$A$2:$A$10000,$C$1,'Raw Data'!$N$2:$N$10000,"Superstore",'Raw Data'!$E$2:$E$10000,$B24) | D24: =SUMIFS('Raw Data'!$F$2:$F$10000,'Raw Data'!$Q$2:$Q$10000,"No",'Raw Data'!$A$2:$A$10000,$C$1,'Raw Data'!$N$2:$N$10000,"Superstore",'Raw Data'!$E$2:$E$10000,$B24) | E24: =IFERROR(AVERAGEIFS('Raw Data'!$G$2:$G$10000,'Raw Data'!$Q$2:$Q$10000,"No",'Raw Data'!$A$2:$A$10000,$C$1,'Raw Data'!$N$2:$N$10000,"Superstore",'Raw Data'!$E$2:$E$10000,$B24),"") | F24: =IFERROR(AVERAGEIFS('Raw Data'!$H$2:$H$10000,'Raw Data'!$Q$2:$Q$10000,"No",'Raw Data'!$A$2:$A$10000,$C$1,'Raw Data'!$N$2:$N$10000,"Superstore",'Raw Data'!$E$2:$E$10000,$B24),"") | G24: =IFERROR(AVERAGEIFS('Raw Data'!$I$2:$I$10000,'Raw Data'!$Q$2:$Q$10000,"No",'Raw Data'!$A$2:$A$10000,$C$1,'Raw Data'!$N$2:$N$10000,"Superstore",'Raw Data'!$E$2:$E$10000,$B24),"") | H24: =IFERROR(AVERAGEIFS('Raw Data'!$J$2:$J$10000,'Raw Data'!$Q$2:$Q$10000,"No",'Raw Data'!$A$2:$A$10000,$C$1,'Raw Data'!$N$2:$N$10000,"Superstore",'Raw Data'!$E$2:$E$10000,$B24),"") | I24: =IFERROR(AVERAGEIFS('Raw Data'!$K$2:$K$10000,'Raw Data'!$Q$2:$Q$10000,"No",'Raw Data'!$A$2:$A$10000,$C$1,'Raw Data'!$N$2:$N$10000,"Superstore",'Raw Data'!$E$2:$E$10000,$B24),"") | J24: =IFERROR(AVERAGEIFS('Raw Data'!$L$2:$L$10000,'Raw Data'!$Q$2:$Q$10000,"No",'Raw Data'!$A$2:$A$10000,$C$1,'Raw Data'!$N$2:$N$10000,"Superstore",'Raw Data'!$E$2:$E$10000,$B24),"") | K24: =IFERROR(AVERAGEIFS('Raw Data'!$R$2:$R$10000,'Raw Data'!$Q$2:$Q$10000,"No",'Raw Data'!$A$2:$A$10000,$C$1,'Raw Data'!$N$2:$N$10000,"Superstore",'Raw Data'!$E$2:$E$10000,$B24),"") | L24: =IFERROR(AVERAGEIFS('Raw Data'!$S$2:$S$10000,'Raw Data'!$Q$2:$Q$10000,"No",'Raw Data'!$A$2:$A$10000,$C$1,'Raw Data'!$N$2:$N$10000,"Superstore",'Raw Data'!$E$2:$E$10000,$B24),"")
A25: Superstore | B25: Belgavi | C25: =COUNTIFS('Raw Data'!$Q$2:$Q$10000,"No",'Raw Data'!$A$2:$A$10000,$C$1,'Raw Data'!$N$2:$N$10000,"Superstore",'Raw Data'!$E$2:$E$10000,$B25) | D25: =SUMIFS('Raw Data'!$F$2:$F$10000,'Raw Data'!$Q$2:$Q$10000,"No",'Raw Data'!$A$2:$A$10000,$C$1,'Raw Data'!$N$2:$N$10000,"Superstore",'Raw Data'!$E$2:$E$10000,$B25) | E25: =IFERROR(AVERAGEIFS('Raw Data'!$G$2:$G$10000,'Raw Data'!$Q$2:$Q$10000,"No",'Raw Data'!$A$2:$A$10000,$C$1,'Raw Data'!$N$2:$N$10000,"Superstore",'Raw Data'!$E$2:$E$10000,$B25),"") | F25: =IFERROR(AVERAGEIFS('Raw Data'!$H$2:$H$10000,'Raw Data'!$Q$2:$Q$10000,"No",'Raw Data'!$A$2:$A$10000,$C$1,'Raw Data'!$N$2:$N$10000,"Superstore",'Raw Data'!$E$2:$E$10000,$B25),"") | G25: =IFERROR(AVERAGEIFS('Raw Data'!$I$2:$I$10000,'Raw Data'!$Q$2:$Q$10000,"No",'Raw Data'!$A$2:$A$10000,$C$1,'Raw Data'!$N$2:$N$10000,"Superstore",'Raw Data'!$E$2:$E$10000,$B25),"") | H25: =IFERROR(AVERAGEIFS('Raw Data'!$J$2:$J$10000,'Raw Data'!$Q$2:$Q$10000,"No",'Raw Data'!$A$2:$A$10000,$C$1,'Raw Data'!$N$2:$N$10000,"Superstore",'Raw Data'!$E$2:$E$10000,$B25),"") | I25: =IFERROR(AVERAGEIFS('Raw Data'!$K$2:$K$10000,'Raw Data'!$Q$2:$Q$10000,"No",'Raw Data'!$A$2:$A$10000,$C$1,'Raw Data'!$N$2:$N$10000,"Superstore",'Raw Data'!$E$2:$E$10000,$B25),"") | J25: =IFERROR(AVERAGEIFS('Raw Data'!$L$2:$L$10000,'Raw Data'!$Q$2:$Q$10000,"No",'Raw Data'!$A$2:$A$10000,$C$1,'Raw Data'!$N$2:$N$10000,"Superstore",'Raw Data'!$E$2:$E$10000,$B25),"") | K25: =IFERROR(AVERAGEIFS('Raw Data'!$R$2:$R$10000,'Raw Data'!$Q$2:$Q$10000,"No",'Raw Data'!$A$2:$A$10000,$C$1,'Raw Data'!$N$2:$N$10000,"Superstore",'Raw Data'!$E$2:$E$10000,$B25),"") | L25: =IFERROR(AVERAGEIFS('Raw Data'!$S$2:$S$10000,'Raw Data'!$Q$2:$Q$10000,"No",'Raw Data'!$A$2:$A$10000,$C$1,'Raw Data'!$N$2:$N$10000,"Superstore",'Raw Data'!$E$2:$E$10000,$B25),"")
A26: Superstore | B26: Davanagere | C26: =COUNTIFS('Raw Data'!$Q$2:$Q$10000,"No",'Raw Data'!$A$2:$A$10000,$C$1,'Raw Data'!$N$2:$N$10000,"Superstore",'Raw Data'!$E$2:$E$10000,$B26) | D26: =SUMIFS('Raw Data'!$F$2:$F$10000,'Raw Data'!$Q$2:$Q$10000,"No",'Raw Data'!$A$2:$A$10000,$C$1,'Raw Data'!$N$2:$N$10000,"Superstore",'Raw Data'!$E$2:$E$10000,$B26) | E26: =IFERROR(AVERAGEIFS('Raw Data'!$G$2:$G$10000,'Raw Data'!$Q$2:$Q$10000,"No",'Raw Data'!$A$2:$A$10000,$C$1,'Raw Data'!$N$2:$N$10000,"Superstore",'Raw Data'!$E$2:$E$10000,$B26),"") | F26: =IFERROR(AVERAGEIFS('Raw Data'!$H$2:$H$10000,'Raw Data'!$Q$2:$Q$10000,"No",'Raw Data'!$A$2:$A$10000,$C$1,'Raw Data'!$N$2:$N$10000,"Superstore",'Raw Data'!$E$2:$E$10000,$B26),"") | G26: =IFERROR(AVERAGEIFS('Raw Data'!$I$2:$I$10000,'Raw Data'!$Q$2:$Q$10000,"No",'Raw Data'!$A$2:$A$10000,$C$1,'Raw Data'!$N$2:$N$10000,"Superstore",'Raw Data'!$E$2:$E$10000,$B26),"") | H26: =IFERROR(AVERAGEIFS('Raw Data'!$J$2:$J$10000,'Raw Data'!$Q$2:$Q$10000,"No",'Raw Data'!$A$2:$A$10000,$C$1,'Raw Data'!$N$2:$N$10000,"Superstore",'Raw Data'!$E$2:$E$10000,$B26),"") | I26: =IFERROR(AVERAGEIFS('Raw Data'!$K$2:$K$10000,'Raw Data'!$Q$2:$Q$10000,"No",'Raw Data'!$A$2:$A$10000,$C$1,'Raw Data'!$N$2:$N$10000,"Superstore",'Raw Data'!$E$2:$E$10000,$B26),"") | J26: =IFERROR(AVERAGEIFS('Raw Data'!$L$2:$L$10000,'Raw Data'!$Q$2:$Q$10000,"No",'Raw Data'!$A$2:$A$10000,$C$1,'Raw Data'!$N$2:$N$10000,"Superstore",'Raw Data'!$E$2:$E$10000,$B26),"") | K26: =IFERROR(AVERAGEIFS('Raw Data'!$R$2:$R$10000,'Raw Data'!$Q$2:$Q$10000,"No",'Raw Data'!$A$2:$A$10000,$C$1,'Raw Data'!$N$2:$N$10000,"Superstore",'Raw Data'!$E$2:$E$10000,$B26),"") | L26: =IFERROR(AVERAGEIFS('Raw Data'!$S$2:$S$10000,'Raw Data'!$Q$2:$Q$10000,"No",'Raw Data'!$A$2:$A$10000,$C$1,'Raw Data'!$N$2:$N$10000,"Superstore",'Raw Data'!$E$2:$E$10000,$B26),"")
A27: Superstore | B27: Hosur | C27: =COUNTIFS('Raw Data'!$Q$2:$Q$10000,"No",'Raw Data'!$A$2:$A$10000,$C$1,'Raw Data'!$N$2:$N$10000,"Superstore",'Raw Data'!$E$2:$E$10000,$B27) | D27: =SUMIFS('Raw Data'!$F$2:$F$10000,'Raw Data'!$Q$2:$Q$10000,"No",'Raw Data'!$A$2:$A$10000,$C$1,'Raw Data'!$N$2:$N$10000,"Superstore",'Raw Data'!$E$2:$E$10000,$B27) | E27: =IFERROR(AVERAGEIFS('Raw Data'!$G$2:$G$10000,'Raw Data'!$Q$2:$Q$10000,"No",'Raw Data'!$A$2:$A$10000,$C$1,'Raw Data'!$N$2:$N$10000,"Superstore",'Raw Data'!$E$2:$E$10000,$B27),"") | F27: =IFERROR(AVERAGEIFS('Raw Data'!$H$2:$H$10000,'Raw Data'!$Q$2:$Q$10000,"No",'Raw Data'!$A$2:$A$10000,$C$1,'Raw Data'!$N$2:$N$10000,"Superstore",'Raw Data'!$E$2:$E$10000,$B27),"") | G27: =IFERROR(AVERAGEIFS('Raw Data'!$I$2:$I$10000,'Raw Data'!$Q$2:$Q$10000,"No",'Raw Data'!$A$2:$A$10000,$C$1,'Raw Data'!$N$2:$N$10000,"Superstore",'Raw Data'!$E$2:$E$10000,$B27),"") | H27: =IFERROR(AVERAGEIFS('Raw Data'!$J$2:$J$10000,'Raw Data'!$Q$2:$Q$10000,"No",'Raw Data'!$A$2:$A$10000,$C$1,'Raw Data'!$N$2:$N$10000,"Superstore",'Raw Data'!$E$2:$E$10000,$B27),"") | I27: =IFERROR(AVERAGEIFS('Raw Data'!$K$2:$K$10000,'Raw Data'!$Q$2:$Q$10000,"No",'Raw Data'!$A$2:$A$10000,$C$1,'Raw Data'!$N$2:$N$10000,"Superstore",'Raw Data'!$E$2:$E$10000,$B27),"") | J27: =IFERROR(AVERAGEIFS('Raw Data'!$L$2:$L$10000,'Raw Data'!$Q$2:$Q$10000,"No",'Raw Data'!$A$2:$A$10000,$C$1,'Raw Data'!$N$2:$N$10000,"Superstore",'Raw Data'!$E$2:$E$10000,$B27),"") | K27: =IFERROR(AVERAGEIFS('Raw Data'!$R$2:$R$10000,'Raw Data'!$Q$2:$Q$10000,"No",'Raw Data'!$A$2:$A$10000,$C$1,'Raw Data'!$N$2:$N$10000,"Superstore",'Raw Data'!$E$2:$E$10000,$B27),"") | L27: =IFERROR(AVERAGEIFS('Raw Data'!$S$2:$S$10000,'Raw Data'!$Q$2:$Q$10000,"No",'Raw Data'!$A$2:$A$10000,$C$1,'Raw Data'!$N$2:$N$10000,"Superstore",'Raw Data'!$E$2:$E$10000,$B27),"")
A28: Superstore | B28: Tumkuru | C28: =COUNTIFS('Raw Data'!$Q$2:$Q$10000,"No",'Raw Data'!$A$2:$A$10000,$C$1,'Raw Data'!$N$2:$N$10000,"Superstore",'Raw Data'!$E$2:$E$10000,$B28) | D28: =SUMIFS('Raw Data'!$F$2:$F$10000,'Raw Data'!$Q$2:$Q$10000,"No",'Raw Data'!$A$2:$A$10000,$C$1,'Raw Data'!$N$2:$N$10000,"Superstore",'Raw Data'!$E$2:$E$10000,$B28) | E28: =IFERROR(AVERAGEIFS('Raw Data'!$G$2:$G$10000,'Raw Data'!$Q$2:$Q$10000,"No",'Raw Data'!$A$2:$A$10000,$C$1,'Raw Data'!$N$2:$N$10000,"Superstore",'Raw Data'!$E$2:$E$10000,$B28),"") | F28: =IFERROR(AVERAGEIFS('Raw Data'!$H$2:$H$10000,'Raw Data'!$Q$2:$Q$10000,"No",'Raw Data'!$A$2:$A$10000,$C$1,'Raw Data'!$N$2:$N$10000,"Superstore",'Raw Data'!$E$2:$E$10000,$B28),"") | G28: =IFERROR(AVERAGEIFS('Raw Data'!$I$2:$I$10000,'Raw Data'!$Q$2:$Q$10000,"No",'Raw Data'!$A$2:$A$10000,$C$1,'Raw Data'!$N$2:$N$10000,"Superstore",'Raw Data'!$E$2:$E$10000,$B28),"") | H28: =IFERROR(AVERAGEIFS('Raw Data'!$J$2:$J$10000,'Raw Data'!$Q$2:$Q$10000,"No",'Raw Data'!$A$2:$A$10000,$C$1,'Raw Data'!$N$2:$N$10000,"Superstore",'Raw Data'!$E$2:$E$10000,$B28),"") | I28: =IFERROR(AVERAGEIFS('Raw Data'!$K$2:$K$10000,'Raw Data'!$Q$2:$Q$10000,"No",'Raw Data'!$A$2:$A$10000,$C$1,'Raw Data'!$N$2:$N$10000,"Superstore",'Raw Data'!$E$2:$E$10000,$B28),"") | J28: =IFERROR(AVERAGEIFS('Raw Data'!$L$2:$L$10000,'Raw Data'!$Q$2:$Q$10000,"No",'Raw Data'!$A$2:$A$10000,$C$1,'Raw Data'!$N$2:$N$10000,"Superstore",'Raw Data'!$E$2:$E$10000,$B28),"") | K28: =IFERROR(AVERAGEIFS('Raw Data'!$R$2:$R$10000,'Raw Data'!$Q$2:$Q$10000,"No",'Raw Data'!$A$2:$A$10000,$C$1,'Raw Data'!$N$2:$N$10000,"Superstore",'Raw Data'!$E$2:$E$10000,$B28),"") | L28: =IFERROR(AVERAGEIFS('Raw Data'!$S$2:$S$10000,'Raw Data'!$Q$2:$Q$10000,"No",'Raw Data'!$A$2:$A$10000,$C$1,'Raw Data'!$N$2:$N$10000,"Superstore",'Raw Data'!$E$2:$E$10000,$B28),"")
A29: Superstore | B29: Grand Total | C29: =COUNTIFS('Raw Data'!$Q$2:$Q$10000,"No",'Raw Data'!$A$2:$A$10000,$C$1,'Raw Data'!$N$2:$N$10000,"Superstore",'Raw Data'!$E$2:$E$10000,"<>") | D29: =SUMIFS('Raw Data'!$F$2:$F$10000,'Raw Data'!$Q$2:$Q$10000,"No",'Raw Data'!$A$2:$A$10000,$C$1,'Raw Data'!$N$2:$N$10000,"Superstore",'Raw Data'!$E$2:$E$10000,"<>") | E29: =IFERROR(AVERAGEIFS('Raw Data'!$G$2:$G$10000,'Raw Data'!$Q$2:$Q$10000,"No",'Raw Data'!$A$2:$A$10000,$C$1,'Raw Data'!$N$2:$N$10000,"Superstore",'Raw Data'!$E$2:$E$10000,"<>"),"") | F29: =IFERROR(AVERAGEIFS('Raw Data'!$H$2:$H$10000,'Raw Data'!$Q$2:$Q$10000,"No",'Raw Data'!$A$2:$A$10000,$C$1,'Raw Data'!$N$2:$N$10000,"Superstore",'Raw Data'!$E$2:$E$10000,"<>"),"") | G29: =IFERROR(AVERAGEIFS('Raw Data'!$I$2:$I$10000,'Raw Data'!$Q$2:$Q$10000,"No",'Raw Data'!$A$2:$A$10000,$C$1,'Raw Data'!$N$2:$N$10000,"Superstore",'Raw Data'!$E$2:$E$10000,"<>"),"") | H29: =IFERROR(AVERAGEIFS('Raw Data'!$J$2:$J$10000,'Raw Data'!$Q$2:$Q$10000,"No",'Raw Data'!$A$2:$A$10000,$C$1,'Raw Data'!$N$2:$N$10000,"Superstore",'Raw Data'!$E$2:$E$10000,"<>"),"") | I29: =IFERROR(AVERAGEIFS('Raw Data'!$K$2:$K$10000,'Raw Data'!$Q$2:$Q$10000,"No",'Raw Data'!$A$2:$A$10000,$C$1,'Raw Data'!$N$2:$N$10000,"Superstore",'Raw Data'!$E$2:$E$10000,"<>"),"") | J29: =IFERROR(AVERAGEIFS('Raw Data'!$L$2:$L$10000,'Raw Data'!$Q$2:$Q$10000,"No",'Raw Data'!$A$2:$A$10000,$C$1,'Raw Data'!$N$2:$N$10000,"Superstore",'Raw Data'!$E$2:$E$10000,"<>"),"") | K29: =IFERROR(AVERAGEIFS('Raw Data'!$R$2:$R$10000,'Raw Data'!$Q$2:$Q$10000,"No",'Raw Data'!$A$2:$A$10000,$C$1,'Raw Data'!$N$2:$N$10000,"Superstore",'Raw Data'!$E$2:$E$10000,"<>"),"") | L29: =IFERROR(AVERAGEIFS('Raw Data'!$S$2:$S$10000,'Raw Data'!$Q$2:$Q$10000,"No",'Raw Data'!$A$2:$A$10000,$C$1,'Raw Data'!$N$2:$N$10000,"Superstore",'Raw Data'!$E$2:$E$10000,"<>"),"")
A31: Combined - City Split
A32: Type | B32: City | C32: Store Count | D32: Total Bins | E32: CC MTD % | F32: BA MTD % | G32: IA MTD % | H32: CC ACC % | I32: PD % | J32: Inv Health | K32: CC MTD Target | L32: CC MTD Achieved %
A33: Combined | B33: Bengaluru | C33: =COUNTIFS('Raw Data'!$Q$2:$Q$10000,"No",'Raw Data'!$A$2:$A$10000,$C$1,'Raw Data'!$N$2:$N$10000,"<>",'Raw Data'!$E$2:$E$10000,$B33) | D33: =SUMIFS('Raw Data'!$F$2:$F$10000,'Raw Data'!$Q$2:$Q$10000,"No",'Raw Data'!$A$2:$A$10000,$C$1,'Raw Data'!$N$2:$N$10000,"<>",'Raw Data'!$E$2:$E$10000,$B33) | E33: =IFERROR(AVERAGEIFS('Raw Data'!$G$2:$G$10000,'Raw Data'!$Q$2:$Q$10000,"No",'Raw Data'!$A$2:$A$10000,$C$1,'Raw Data'!$N$2:$N$10000,"<>",'Raw Data'!$E$2:$E$10000,$B33),"") | F33: =IFERROR(AVERAGEIFS('Raw Data'!$H$2:$H$10000,'Raw Data'!$Q$2:$Q$10000,"No",'Raw Data'!$A$2:$A$10000,$C$1,'Raw Data'!$N$2:$N$10000,"<>",'Raw Data'!$E$2:$E$10000,$B33),"") | G33: =IFERROR(AVERAGEIFS('Raw Data'!$I$2:$I$10000,'Raw Data'!$Q$2:$Q$10000,"No",'Raw Data'!$A$2:$A$10000,$C$1,'Raw Data'!$N$2:$N$10000,"<>",'Raw Data'!$E$2:$E$10000,$B33),"") | H33: =IFERROR(AVERAGEIFS('Raw Data'!$J$2:$J$10000,'Raw Data'!$Q$2:$Q$10000,"No",'Raw Data'!$A$2:$A$10000,$C$1,'Raw Data'!$N$2:$N$10000,"<>",'Raw Data'!$E$2:$E$10000,$B33),"") | I33: =IFERROR(AVERAGEIFS('Raw Data'!$K$2:$K$10000,'Raw Data'!$Q$2:$Q$10000,"No",'Raw Data'!$A$2:$A$10000,$C$1,'Raw Data'!$N$2:$N$10000,"<>",'Raw Data'!$E$2:$E$10000,$B33),"") | J33: =IFERROR(AVERAGEIFS('Raw Data'!$L$2:$L$10000,'Raw Data'!$Q$2:$Q$10000,"No",'Raw Data'!$A$2:$A$10000,$C$1,'Raw Data'!$N$2:$N$10000,"<>",'Raw Data'!$E$2:$E$10000,$B33),"") | K33: =IFERROR(AVERAGEIFS('Raw Data'!$R$2:$R$10000,'Raw Data'!$Q$2:$Q$10000,"No",'Raw Data'!$A$2:$A$10000,$C$1,'Raw Data'!$N$2:$N$10000,"<>",'Raw Data'!$E$2:$E$10000,$B33),"") | L33: =IFERROR(AVERAGEIFS('Raw Data'!$S$2:$S$10000,'Raw Data'!$Q$2:$Q$10000,"No",'Raw Data'!$A$2:$A$10000,$C$1,'Raw Data'!$N$2:$N$10000,"<>",'Raw Data'!$E$2:$E$10000,$B33),"")
A34: Combined | B34: Kochi | C34: =COUNTIFS('Raw Data'!$Q$2:$Q$10000,"No",'Raw Data'!$A$2:$A$10000,$C$1,'Raw Data'!$N$2:$N$10000,"<>",'Raw Data'!$E$2:$E$10000,$B34) | D34: =SUMIFS('Raw Data'!$F$2:$F$10000,'Raw Data'!$Q$2:$Q$10000,"No",'Raw Data'!$A$2:$A$10000,$C$1,'Raw Data'!$N$2:$N$10000,"<>",'Raw Data'!$E$2:$E$10000,$B34) | E34: =IFERROR(AVERAGEIFS('Raw Data'!$G$2:$G$10000,'Raw Data'!$Q$2:$Q$10000,"No",'Raw Data'!$A$2:$A$10000,$C$1,'Raw Data'!$N$2:$N$10000,"<>",'Raw Data'!$E$2:$E$10000,$B34),"") | F34: =IFERROR(AVERAGEIFS('Raw Data'!$H$2:$H$10000,'Raw Data'!$Q$2:$Q$10000,"No",'Raw Data'!$A$2:$A$10000,$C$1,'Raw Data'!$N$2:$N$10000,"<>",'Raw Data'!$E$2:$E$10000,$B34),"") | G34: =IFERROR(AVERAGEIFS('Raw Data'!$I$2:$I$10000,'Raw Data'!$Q$2:$Q$10000,"No",'Raw Data'!$A$2:$A$10000,$C$1,'Raw Data'!$N$2:$N$10000,"<>",'Raw Data'!$E$2:$E$10000,$B34),"") | H34: =IFERROR(AVERAGEIFS('Raw Data'!$J$2:$J$10000,'Raw Data'!$Q$2:$Q$10000,"No",'Raw Data'!$A$2:$A$10000,$C$1,'Raw Data'!$N$2:$N$10000,"<>",'Raw Data'!$E$2:$E$10000,$B34),"") | I34: =IFERROR(AVERAGEIFS('Raw Data'!$K$2:$K$10000,'Raw Data'!$Q$2:$Q$10000,"No",'Raw Data'!$A$2:$A$10000,$C$1,'Raw Data'!$N$2:$N$10000,"<>",'Raw Data'!$E$2:$E$10000,$B34),"") | J34: =IFERROR(AVERAGEIFS('Raw Data'!$L$2:$L$10000,'Raw Data'!$Q$2:$Q$10000,"No",'Raw Data'!$A$2:$A$10000,$C$1,'Raw Data'!$N$2:$N$10000,"<>",'Raw Data'!$E$2:$E$10000,$B34),"") | K34: =IFERROR(AVERAGEIFS('Raw Data'!$R$2:$R$10000,'Raw Data'!$Q$2:$Q$10000,"No",'Raw Data'!$A$2:$A$10000,$C$1,'Raw Data'!$N$2:$N$10000,"<>",'Raw Data'!$E$2:$E$10000,$B34),"") | L34: =IFERROR(AVERAGEIFS('Raw Data'!$S$2:$S$10000,'Raw Data'!$Q$2:$Q$10000,"No",'Raw Data'!$A$2:$A$10000,$C$1,'Raw Data'!$N$2:$N$10000,"<>",'Raw Data'!$E$2:$E$10000,$B34),"")
A35: Combined | B35: Coimbatore | C35: =COUNTIFS('Raw Data'!$Q$2:$Q$10000,"No",'Raw Data'!$A$2:$A$10000,$C$1,'Raw Data'!$N$2:$N$10000,"<>",'Raw Data'!$E$2:$E$10000,$B35) | D35: =SUMIFS('Raw Data'!$F$2:$F$10000,'Raw Data'!$Q$2:$Q$10000,"No",'Raw Data'!$A$2:$A$10000,$C$1,'Raw Data'!$N$2:$N$10000,"<>",'Raw Data'!$E$2:$E$10000,$B35) | E35: =IFERROR(AVERAGEIFS('Raw Data'!$G$2:$G$10000,'Raw Data'!$Q$2:$Q$10000,"No",'Raw Data'!$A$2:$A$10000,$C$1,'Raw Data'!$N$2:$N$10000,"<>",'Raw Data'!$E$2:$E$10000,$B35),"") | F35: =IFERROR(AVERAGEIFS('Raw Data'!$H$2:$H$10000,'Raw Data'!$Q$2:$Q$10000,"No",'Raw Data'!$A$2:$A$10000,$C$1,'Raw Data'!$N$2:$N$10000,"<>",'Raw Data'!$E$2:$E$10000,$B35),"") | G35: =IFERROR(AVERAGEIFS('Raw Data'!$I$2:$I$10000,'Raw Data'!$Q$2:$Q$10000,"No",'Raw Data'!$A$2:$A$10000,$C$1,'Raw Data'!$N$2:$N$10000,"<>",'Raw Data'!$E$2:$E$10000,$B35),"") | H35: =IFERROR(AVERAGEIFS('Raw Data'!$J$2:$J$10000,'Raw Data'!$Q$2:$Q$10000,"No",'Raw Data'!$A$2:$A$10000,$C$1,'Raw Data'!$N$2:$N$10000,"<>",'Raw Data'!$E$2:$E$10000,$B35),"") | I35: =IFERROR(AVERAGEIFS('Raw Data'!$K$2:$K$10000,'Raw Data'!$Q$2:$Q$10000,"No",'Raw Data'!$A$2:$A$10000,$C$1,'Raw Data'!$N$2:$N$10000,"<>",'Raw Data'!$E$2:$E$10000,$B35),"") | J35: =IFERROR(AVERAGEIFS('Raw Data'!$L$2:$L$10000,'Raw Data'!$Q$2:$Q$10000,"No",'Raw Data'!$A$2:$A$10000,$C$1,'Raw Data'!$N$2:$N$10000,"<>",'Raw Data'!$E$2:$E$10000,$B35),"") | K35: =IFERROR(AVERAGEIFS('Raw Data'!$R$2:$R$10000,'Raw Data'!$Q$2:$Q$10000,"No",'Raw Data'!$A$2:$A$10000,$C$1,'Raw Data'!$N$2:$N$10000,"<>",'Raw Data'!$E$2:$E$10000,$B35),"") | L35: =IFERROR(AVERAGEIFS('Raw Data'!$S$2:$S$10000,'Raw Data'!$Q$2:$Q$10000,"No",'Raw Data'!$A$2:$A$10000,$C$1,'Raw Data'!$N$2:$N$10000,"<>",'Raw Data'!$E$2:$E$10000,$B35),"")
A36: Combined | B36: Mysuru | C36: =COUNTIFS('Raw Data'!$Q$2:$Q$10000,"No",'Raw Data'!$A$2:$A$10000,$C$1,'Raw Data'!$N$2:$N$10000,"<>",'Raw Data'!$E$2:$E$10000,$B36) | D36: =SUMIFS('Raw Data'!$F$2:$F$10000,'Raw Data'!$Q$2:$Q$10000,"No",'Raw Data'!$A$2:$A$10000,$C$1,'Raw Data'!$N$2:$N$10000,"<>",'Raw Data'!$E$2:$E$10000,$B36) | E36: =IFERROR(AVERAGEIFS('Raw Data'!$G$2:$G$10000,'Raw Data'!$Q$2:$Q$10000,"No",'Raw Data'!$A$2:$A$10000,$C$1,'Raw Data'!$N$2:$N$10000,"<>",'Raw Data'!$E$2:$E$10000,$B36),"") | F36: =IFERROR(AVERAGEIFS('Raw Data'!$H$2:$H$10000,'Raw Data'!$Q$2:$Q$10000,"No",'Raw Data'!$A$2:$A$10000,$C$1,'Raw Data'!$N$2:$N$10000,"<>",'Raw Data'!$E$2:$E$10000,$B36),"") | G36: =IFERROR(AVERAGEIFS('Raw Data'!$I$2:$I$10000,'Raw Data'!$Q$2:$Q$10000,"No",'Raw Data'!$A$2:$A$10000,$C$1,'Raw Data'!$N$2:$N$10000,"<>",'Raw Data'!$E$2:$E$10000,$B36),"") | H36: =IFERROR(AVERAGEIFS('Raw Data'!$J$2:$J$10000,'Raw Data'!$Q$2:$Q$10000,"No",'Raw Data'!$A$2:$A$10000,$C$1,'Raw Data'!$N$2:$N$10000,"<>",'Raw Data'!$E$2:$E$10000,$B36),"") | I36: =IFERROR(AVERAGEIFS('Raw Data'!$K$2:$K$10000,'Raw Data'!$Q$2:$Q$10000,"No",'Raw Data'!$A$2:$A$10000,$C$1,'Raw Data'!$N$2:$N$10000,"<>",'Raw Data'!$E$2:$E$10000,$B36),"") | J36: =IFERROR(AVERAGEIFS('Raw Data'!$L$2:$L$10000,'Raw Data'!$Q$2:$Q$10000,"No",'Raw Data'!$A$2:$A$10000,$C$1,'Raw Data'!$N$2:$N$10000,"<>",'Raw Data'!$E$2:$E$10000,$B36),"") | K36: =IFERROR(AVERAGEIFS('Raw Data'!$R$2:$R$10000,'Raw Data'!$Q$2:$Q$10000,"No",'Raw Data'!$A$2:$A$10000,$C$1,'Raw Data'!$N$2:$N$10000,"<>",'Raw Data'!$E$2:$E$10000,$B36),"") | L36: =IFERROR(AVERAGEIFS('Raw Data'!$S$2:$S$10000,'Raw Data'!$Q$2:$Q$10000,"No",'Raw Data'!$A$2:$A$10000,$C$1,'Raw Data'!$N$2:$N$10000,"<>",'Raw Data'!$E$2:$E$10000,$B36),"")
A37: Combined | B37: Hubballi | C37: =COUNTIFS('Raw Data'!$Q$2:$Q$10000,"No",'Raw Data'!$A$2:$A$10000,$C$1,'Raw Data'!$N$2:$N$10000,"<>",'Raw Data'!$E$2:$E$10000,$B37) | D37: =SUMIFS('Raw Data'!$F$2:$F$10000,'Raw Data'!$Q$2:$Q$10000,"No",'Raw Data'!$A$2:$A$10000,$C$1,'Raw Data'!$N$2:$N$10000,"<>",'Raw Data'!$E$2:$E$10000,$B37) | E37: =IFERROR(AVERAGEIFS('Raw Data'!$G$2:$G$10000,'Raw Data'!$Q$2:$Q$10000,"No",'Raw Data'!$A$2:$A$10000,$C$1,'Raw Data'!$N$2:$N$10000,"<>",'Raw Data'!$E$2:$E$10000,$B37),"") | F37: =IFERROR(AVERAGEIFS('Raw Data'!$H$2:$H$10000,'Raw Data'!$Q$2:$Q$10000,"No",'Raw Data'!$A$2:$A$10000,$C$1,'Raw Data'!$N$2:$N$10000,"<>",'Raw Data'!$E$2:$E$10000,$B37),"") | G37: =IFERROR(AVERAGEIFS('Raw Data'!$I$2:$I$10000,'Raw Data'!$Q$2:$Q$10000,"No",'Raw Data'!$A$2:$A$10000,$C$1,'Raw Data'!$N$2:$N$10000,"<>",'Raw Data'!$E$2:$E$10000,$B37),"") | H37: =IFERROR(AVERAGEIFS('Raw Data'!$J$2:$J$10000,'Raw Data'!$Q$2:$Q$10000,"No",'Raw Data'!$A$2:$A$10000,$C$1,'Raw Data'!$N$2:$N$10000,"<>",'Raw Data'!$E$2:$E$10000,$B37),"") | I37: =IFERROR(AVERAGEIFS('Raw Data'!$K$2:$K$10000,'Raw Data'!$Q$2:$Q$10000,"No",'Raw Data'!$A$2:$A$10000,$C$1,'Raw Data'!$N$2:$N$10000,"<>",'Raw Data'!$E$2:$E$10000,$B37),"") | J37: =IFERROR(AVERAGEIFS('Raw Data'!$L$2:$L$10000,'Raw Data'!$Q$2:$Q$10000,"No",'Raw Data'!$A$2:$A$10000,$C$1,'Raw Data'!$N$2:$N$10000,"<>",'Raw Data'!$E$2:$E$10000,$B37),"") | K37: =IFERROR(AVERAGEIFS('Raw Data'!$R$2:$R$10000,'Raw Data'!$Q$2:$Q$10000,"No",'Raw Data'!$A$2:$A$10000,$C$1,'Raw Data'!$N$2:$N$10000,"<>",'Raw Data'!$E$2:$E$10000,$B37),"") | L37: =IFERROR(AVERAGEIFS('Raw Data'!$S$2:$S$10000,'Raw Data'!$Q$2:$Q$10000,"No",'Raw Data'!$A$2:$A$10000,$C$1,'Raw Data'!$N$2:$N$10000,"<>",'Raw Data'!$E$2:$E$10000,$B37),"")
A38: Combined | B38: Palakkad | C38: =COUNTIFS('Raw Data'!$Q$2:$Q$10000,"No",'Raw Data'!$A$2:$A$10000,$C$1,'Raw Data'!$N$2:$N$10000,"<>",'Raw Data'!$E$2:$E$10000,$B38) | D38: =SUMIFS('Raw Data'!$F$2:$F$10000,'Raw Data'!$Q$2:$Q$10000,"No",'Raw Data'!$A$2:$A$10000,$C$1,'Raw Data'!$N$2:$N$10000,"<>",'Raw Data'!$E$2:$E$10000,$B38) | E38: =IFERROR(AVERAGEIFS('Raw Data'!$G$2:$G$10000,'Raw Data'!$Q$2:$Q$10000,"No",'Raw Data'!$A$2:$A$10000,$C$1,'Raw Data'!$N$2:$N$10000,"<>",'Raw Data'!$E$2:$E$10000,$B38),"") | F38: =IFERROR(AVERAGEIFS('Raw Data'!$H$2:$H$10000,'Raw Data'!$Q$2:$Q$10000,"No",'Raw Data'!$A$2:$A$10000,$C$1,'Raw Data'!$N$2:$N$10000,"<>",'Raw Data'!$E$2:$E$10000,$B38),"") | G38: =IFERROR(AVERAGEIFS('Raw Data'!$I$2:$I$10000,'Raw Data'!$Q$2:$Q$10000,"No",'Raw Data'!$A$2:$A$10000,$C$1,'Raw Data'!$N$2:$N$10000,"<>",'Raw Data'!$E$2:$E$10000,$B38),"") | H38: =IFERROR(AVERAGEIFS('Raw Data'!$J$2:$J$10000,'Raw Data'!$Q$2:$Q$10000,"No",'Raw Data'!$A$2:$A$10000,$C$1,'Raw Data'!$N$2:$N$10000,"<>",'Raw Data'!$E$2:$E$10000,$B38),"") | I38: =IFERROR(AVERAGEIFS('Raw Data'!$K$2:$K$10000,'Raw Data'!$Q$2:$Q$10000,"No",'Raw Data'!$A$2:$A$10000,$C$1,'Raw Data'!$N$2:$N$10000,"<>",'Raw Data'!$E$2:$E$10000,$B38),"") | J38: =IFERROR(AVERAGEIFS('Raw Data'!$L$2:$L$10000,'Raw Data'!$Q$2:$Q$10000,"No",'Raw Data'!$A$2:$A$10000,$C$1,'Raw Data'!$N$2:$N$10000,"<>",'Raw Data'!$E$2:$E$10000,$B38),"") | K38: =IFERROR(AVERAGEIFS('Raw Data'!$R$2:$R$10000,'Raw Data'!$Q$2:$Q$10000,"No",'Raw Data'!$A$2:$A$10000,$C$1,'Raw Data'!$N$2:$N$10000,"<>",'Raw Data'!$E$2:$E$10000,$B38),"") | L38: =IFERROR(AVERAGEIFS('Raw Data'!$S$2:$S$10000,'Raw Data'!$Q$2:$Q$10000,"No",'Raw Data'!$A$2:$A$10000,$C$1,'Raw Data'!$N$2:$N$10000,"<>",'Raw Data'!$E$2:$E$10000,$B38),"")
A39: Combined | B39: Belgavi | C39: =COUNTIFS('Raw Data'!$Q$2:$Q$10000,"No",'Raw Data'!$A$2:$A$10000,$C$1,'Raw Data'!$N$2:$N$10000,"<>",'Raw Data'!$E$2:$E$10000,$B39) | D39: =SUMIFS('Raw Data'!$F$2:$F$10000,'Raw Data'!$Q$2:$Q$10000,"No",'Raw Data'!$A$2:$A$10000,$C$1,'Raw Data'!$N$2:$N$10000,"<>",'Raw Data'!$E$2:$E$10000,$B39) | E39: =IFERROR(AVERAGEIFS('Raw Data'!$G$2:$G$10000,'Raw Data'!$Q$2:$Q$10000,"No",'Raw Data'!$A$2:$A$10000,$C$1,'Raw Data'!$N$2:$N$10000,"<>",'Raw Data'!$E$2:$E$10000,$B39),"") | F39: =IFERROR(AVERAGEIFS('Raw Data'!$H$2:$H$10000,'Raw Data'!$Q$2:$Q$10000,"No",'Raw Data'!$A$2:$A$10000,$C$1,'Raw Data'!$N$2:$N$10000,"<>",'Raw Data'!$E$2:$E$10000,$B39),"") | G39: =IFERROR(AVERAGEIFS('Raw Data'!$I$2:$I$10000,'Raw Data'!$Q$2:$Q$10000,"No",'Raw Data'!$A$2:$A$10000,$C$1,'Raw Data'!$N$2:$N$10000,"<>",'Raw Data'!$E$2:$E$10000,$B39),"") | H39: =IFERROR(AVERAGEIFS('Raw Data'!$J$2:$J$10000,'Raw Data'!$Q$2:$Q$10000,"No",'Raw Data'!$A$2:$A$10000,$C$1,'Raw Data'!$N$2:$N$10000,"<>",'Raw Data'!$E$2:$E$10000,$B39),"") | I39: =IFERROR(AVERAGEIFS('Raw Data'!$K$2:$K$10000,'Raw Data'!$Q$2:$Q$10000,"No",'Raw Data'!$A$2:$A$10000,$C$1,'Raw Data'!$N$2:$N$10000,"<>",'Raw Data'!$E$2:$E$10000,$B39),"") | J39: =IFERROR(AVERAGEIFS('Raw Data'!$L$2:$L$10000,'Raw Data'!$Q$2:$Q$10000,"No",'Raw Data'!$A$2:$A$10000,$C$1,'Raw Data'!$N$2:$N$10000,"<>",'Raw Data'!$E$2:$E$10000,$B39),"") | K39: =IFERROR(AVERAGEIFS('Raw Data'!$R$2:$R$10000,'Raw Data'!$Q$2:$Q$10000,"No",'Raw Data'!$A$2:$A$10000,$C$1,'Raw Data'!$N$2:$N$10000,"<>",'Raw Data'!$E$2:$E$10000,$B39),"") | L39: =IFERROR(AVERAGEIFS('Raw Data'!$S$2:$S$10000,'Raw Data'!$Q$2:$Q$10000,"No",'Raw Data'!$A$2:$A$10000,$C$1,'Raw Data'!$N$2:$N$10000,"<>",'Raw Data'!$E$2:$E$10000,$B39),"")
A40: Combined | B40: Davanagere | C40: =COUNTIFS('Raw Data'!$Q$2:$Q$10000,"No",'Raw Data'!$A$2:$A$10000,$C$1,'Raw Data'!$N$2:$N$10000,"<>",'Raw Data'!$E$2:$E$10000,$B40) | D40: =SUMIFS('Raw Data'!$F$2:$F$10000,'Raw Data'!$Q$2:$Q$10000,"No",'Raw Data'!$A$2:$A$10000,$C$1,'Raw Data'!$N$2:$N$10000,"<>",'Raw Data'!$E$2:$E$10000,$B40) | E40: =IFERROR(AVERAGEIFS('Raw Data'!$G$2:$G$10000,'Raw Data'!$Q$2:$Q$10000,"No",'Raw Data'!$A$2:$A$10000,$C$1,'Raw Data'!$N$2:$N$10000,"<>",'Raw Data'!$E$2:$E$10000,$B40),"") | F40: =IFERROR(AVERAGEIFS('Raw Data'!$H$2:$H$10000,'Raw Data'!$Q$2:$Q$10000,"No",'Raw Data'!$A$2:$A$10000,$C$1,'Raw Data'!$N$2:$N$10000,"<>",'Raw Data'!$E$2:$E$10000,$B40),"") | G40: =IFERROR(AVERAGEIFS('Raw Data'!$I$2:$I$10000,'Raw Data'!$Q$2:$Q$10000,"No",'Raw Data'!$A$2:$A$10000,$C$1,'Raw Data'!$N$2:$N$10000,"<>",'Raw Data'!$E$2:$E$10000,$B40),"") | H40: =IFERROR(AVERAGEIFS('Raw Data'!$J$2:$J$10000,'Raw Data'!$Q$2:$Q$10000,"No",'Raw Data'!$A$2:$A$10000,$C$1,'Raw Data'!$N$2:$N$10000,"<>",'Raw Data'!$E$2:$E$10000,$B40),"") | I40: =IFERROR(AVERAGEIFS('Raw Data'!$K$2:$K$10000,'Raw Data'!$Q$2:$Q$10000,"No",'Raw Data'!$A$2:$A$10000,$C$1,'Raw Data'!$N$2:$N$10000,"<>",'Raw Data'!$E$2:$E$10000,$B40),"") | J40: =IFERROR(AVERAGEIFS('Raw Data'!$L$2:$L$10000,'Raw Data'!$Q$2:$Q$10000,"No",'Raw Data'!$A$2:$A$10000,$C$1,'Raw Data'!$N$2:$N$10000,"<>",'Raw Data'!$E$2:$E$10000,$B40),"") | K40: =IFERROR(AVERAGEIFS('Raw Data'!$R$2:$R$10000,'Raw Data'!$Q$2:$Q$10000,"No",'Raw Data'!$A$2:$A$10000,$C$1,'Raw Data'!$N$2:$N$10000,"<>",'Raw Data'!$E$2:$E$10000,$B40),"") | L40: =IFERROR(AVERAGEIFS('Raw Data'!$S$2:$S$10000,'Raw Data'!$Q$2:$Q$10000,"No",'Raw Data'!$A$2:$A$10000,$C$1,'Raw Data'!$N$2:$N$10000,"<>",'Raw Data'!$E$2:$E$10000,$B40),"")
A41: Combined | B41: Hosur | C41: =COUNTIFS('Raw Data'!$Q$2:$Q$10000,"No",'Raw Data'!$A$2:$A$10000,$C$1,'Raw Data'!$N$2:$N$10000,"<>",'Raw Data'!$E$2:$E$10000,$B41) | D41: =SUMIFS('Raw Data'!$F$2:$F$10000,'Raw Data'!$Q$2:$Q$10000,"No",'Raw Data'!$A$2:$A$10000,$C$1,'Raw Data'!$N$2:$N$10000,"<>",'Raw Data'!$E$2:$E$10000,$B41) | E41: =IFERROR(AVERAGEIFS('Raw Data'!$G$2:$G$10000,'Raw Data'!$Q$2:$Q$10000,"No",'Raw Data'!$A$2:$A$10000,$C$1,'Raw Data'!$N$2:$N$10000,"<>",'Raw Data'!$E$2:$E$10000,$B41),"") | F41: =IFERROR(AVERAGEIFS('Raw Data'!$H$2:$H$10000,'Raw Data'!$Q$2:$Q$10000,"No",'Raw Data'!$A$2:$A$10000,$C$1,'Raw Data'!$N$2:$N$10000,"<>",'Raw Data'!$E$2:$E$10000,$B41),"") | G41: =IFERROR(AVERAGEIFS('Raw Data'!$I$2:$I$10000,'Raw Data'!$Q$2:$Q$10000,"No",'Raw Data'!$A$2:$A$10000,$C$1,'Raw Data'!$N$2:$N$10000,"<>",'Raw Data'!$E$2:$E$10000,$B41),"") | H41: =IFERROR(AVERAGEIFS('Raw Data'!$J$2:$J$10000,'Raw Data'!$Q$2:$Q$10000,"No",'Raw Data'!$A$2:$A$10000,$C$1,'Raw Data'!$N$2:$N$10000,"<>",'Raw Data'!$E$2:$E$10000,$B41),"") | I41: =IFERROR(AVERAGEIFS('Raw Data'!$K$2:$K$10000,'Raw Data'!$Q$2:$Q$10000,"No",'Raw Data'!$A$2:$A$10000,$C$1,'Raw Data'!$N$2:$N$10000,"<>",'Raw Data'!$E$2:$E$10000,$B41),"") | J41: =IFERROR(AVERAGEIFS('Raw Data'!$L$2:$L$10000,'Raw Data'!$Q$2:$Q$10000,"No",'Raw Data'!$A$2:$A$10000,$C$1,'Raw Data'!$N$2:$N$10000,"<>",'Raw Data'!$E$2:$E$10000,$B41),"") | K41: =IFERROR(AVERAGEIFS('Raw Data'!$R$2:$R$10000,'Raw Data'!$Q$2:$Q$10000,"No",'Raw Data'!$A$2:$A$10000,$C$1,'Raw Data'!$N$2:$N$10000,"<>",'Raw Data'!$E$2:$E$10000,$B41),"") | L41: =IFERROR(AVERAGEIFS('Raw Data'!$S$2:$S$10000,'Raw Data'!$Q$2:$Q$10000,"No",'Raw Data'!$A$2:$A$10000,$C$1,'Raw Data'!$N$2:$N$10000,"<>",'Raw Data'!$E$2:$E$10000,$B41),"")
A42: Combined | B42: Tumkuru | C42: =COUNTIFS('Raw Data'!$Q$2:$Q$10000,"No",'Raw Data'!$A$2:$A$10000,$C$1,'Raw Data'!$N$2:$N$10000,"<>",'Raw Data'!$E$2:$E$10000,$B42) | D42: =SUMIFS('Raw Data'!$F$2:$F$10000,'Raw Data'!$Q$2:$Q$10000,"No",'Raw Data'!$A$2:$A$10000,$C$1,'Raw Data'!$N$2:$N$10000,"<>",'Raw Data'!$E$2:$E$10000,$B42) | E42: =IFERROR(AVERAGEIFS('Raw Data'!$G$2:$G$10000,'Raw Data'!$Q$2:$Q$10000,"No",'Raw Data'!$A$2:$A$10000,$C$1,'Raw Data'!$N$2:$N$10000,"<>",'Raw Data'!$E$2:$E$10000,$B42),"") | F42: =IFERROR(AVERAGEIFS('Raw Data'!$H$2:$H$10000,'Raw Data'!$Q$2:$Q$10000,"No",'Raw Data'!$A$2:$A$10000,$C$1,'Raw Data'!$N$2:$N$10000,"<>",'Raw Data'!$E$2:$E$10000,$B42),"") | G42: =IFERROR(AVERAGEIFS('Raw Data'!$I$2:$I$10000,'Raw Data'!$Q$2:$Q$10000,"No",'Raw Data'!$A$2:$A$10000,$C$1,'Raw Data'!$N$2:$N$10000,"<>",'Raw Data'!$E$2:$E$10000,$B42),"") | H42: =IFERROR(AVERAGEIFS('Raw Data'!$J$2:$J$10000,'Raw Data'!$Q$2:$Q$10000,"No",'Raw Data'!$A$2:$A$10000,$C$1,'Raw Data'!$N$2:$N$10000,"<>",'Raw Data'!$E$2:$E$10000,$B42),"") | I42: =IFERROR(AVERAGEIFS('Raw Data'!$K$2:$K$10000,'Raw Data'!$Q$2:$Q$10000,"No",'Raw Data'!$A$2:$A$10000,$C$1,'Raw Data'!$N$2:$N$10000,"<>",'Raw Data'!$E$2:$E$10000,$B42),"") | J42: =IFERROR(AVERAGEIFS('Raw Data'!$L$2:$L$10000,'Raw Data'!$Q$2:$Q$10000,"No",'Raw Data'!$A$2:$A$10000,$C$1,'Raw Data'!$N$2:$N$10000,"<>",'Raw Data'!$E$2:$E$10000,$B42),"") | K42: =IFERROR(AVERAGEIFS('Raw Data'!$R$2:$R$10000,'Raw Data'!$Q$2:$Q$10000,"No",'Raw Data'!$A$2:$A$10000,$C$1,'Raw Data'!$N$2:$N$10000,"<>",'Raw Data'!$E$2:$E$10000,$B42),"") | L42: =IFERROR(AVERAGEIFS('Raw Data'!$S$2:$S$10000,'Raw Data'!$Q$2:$Q$10000,"No",'Raw Data'!$A$2:$A$10000,$C$1,'Raw Data'!$N$2:$N$10000,"<>",'Raw Data'!$E$2:$E$10000,$B42),"")
A43: Combined | B43: Grand Total | C43: =COUNTIFS('Raw Data'!$Q$2:$Q$10000,"No",'Raw Data'!$A$2:$A$10000,$C$1,'Raw Data'!$N$2:$N$10000,"<>",'Raw Data'!$E$2:$E$10000,"<>") | D43: =SUMIFS('Raw Data'!$F$2:$F$10000,'Raw Data'!$Q$2:$Q$10000,"No",'Raw Data'!$A$2:$A$10000,$C$1,'Raw Data'!$N$2:$N$10000,"<>",'Raw Data'!$E$2:$E$10000,"<>") | E43: =IFERROR(AVERAGEIFS('Raw Data'!$G$2:$G$10000,'Raw Data'!$Q$2:$Q$10000,"No",'Raw Data'!$A$2:$A$10000,$C$1,'Raw Data'!$N$2:$N$10000,"<>",'Raw Data'!$E$2:$E$10000,"<>"),"") | F43: =IFERROR(AVERAGEIFS('Raw Data'!$H$2:$H$10000,'Raw Data'!$Q$2:$Q$10000,"No",'Raw Data'!$A$2:$A$10000,$C$1,'Raw Data'!$N$2:$N$10000,"<>",'Raw Data'!$E$2:$E$10000,"<>"),"") | G43: =IFERROR(AVERAGEIFS('Raw Data'!$I$2:$I$10000,'Raw Data'!$Q$2:$Q$10000,"No",'Raw Data'!$A$2:$A$10000,$C$1,'Raw Data'!$N$2:$N$10000,"<>",'Raw Data'!$E$2:$E$10000,"<>"),"") | H43: =IFERROR(AVERAGEIFS('Raw Data'!$J$2:$J$10000,'Raw Data'!$Q$2:$Q$10000,"No",'Raw Data'!$A$2:$A$10000,$C$1,'Raw Data'!$N$2:$N$10000,"<>",'Raw Data'!$E$2:$E$10000,"<>"),"") | I43: =IFERROR(AVERAGEIFS('Raw Data'!$K$2:$K$10000,'Raw Data'!$Q$2:$Q$10000,"No",'Raw Data'!$A$2:$A$10000,$C$1,'Raw Data'!$N$2:$N$10000,"<>",'Raw Data'!$E$2:$E$10000,"<>"),"") | J43: =IFERROR(AVERAGEIFS('Raw Data'!$L$2:$L$10000,'Raw Data'!$Q$2:$Q$10000,"No",'Raw Data'!$A$2:$A$10000,$C$1,'Raw Data'!$N$2:$N$10000,"<>",'Raw Data'!$E$2:$E$10000,"<>"),"") | K43: =IFERROR(AVERAGEIFS('Raw Data'!$R$2:$R$10000,'Raw Data'!$Q$2:$Q$10000,"No",'Raw Data'!$A$2:$A$10000,$C$1,'Raw Data'!$N$2:$N$10000,"<>",'Raw Data'!$E$2:$E$10000,"<>"),"") | L43: =IFERROR(AVERAGEIFS('Raw Data'!$S$2:$S$10000,'Raw Data'!$Q$2:$Q$10000,"No",'Raw Data'!$A$2:$A$10000,$C$1,'Raw Data'!$N$2:$N$10000,"<>",'Raw Data'!$E$2:$E$10000,"<>"),"")

Sheet City Cuts
A1: Select Date ▶ | B1: 46304 | C1: =IF($B$1="All","<>",$B$1) | D1: (pick a date or "All" from the dropdown)
A2: Select Store Type ▶ | B2: All | C2: =IF($B$2="All","<>",$B$2) | D2: (All / DH / Superstore)
A4: City level - CC MTD %: store count by band
A5: City | B5: <20% | C5: 20-40% | D5: 40-50% | E5: 50-60% | F5: 60-70% | G5: 70-85% | H5: 85-95% | I5: >=95% | J5: Total Stores | K5: Avg CC MTD %
