Workbook

Sheet Raw Data
A1: Date | B1: Store Name | C1: Sub Store Type | D1: Planogram Enabled | E1: City | F1: Total Bins | G1: CC MTD % | H1: BA MTD % | I1: IA MTD % | J1: CC ACC % | K1: PD % | L1: Inv Health | M1: CC Associate Count | N1: Store Type | O1: CLM | P1: IM | Q1: Leader | R1: Exclude | S1: CC MTD Target | T1: CC MTD Achieved % | U1: CC MTD Status | V1: RCA | W1: POA | X1: ETA | Y1: Additional Remarks | Z1: Planned CC Associate | AA1: Delta | AB1: Delta HC | AC1: MTD Avg Util % | AD1: Util Bucket | AE1: CC MTD & Util Status
A2: 46304 | B2: BEL-Khanapur Road | C2: RETAIL_STORE | D2: No | E2: Belgavi | F2: 6826 | G2: 0.52988573 | H2: 0.94747028 | I2: 0.975021 | J2: 0.94747028 | K2: 0 | L2: 0.99893485 | M2: 2 | N2: =IF($B2="","",IF($C2="SUPERSTORE","Superstore","DH")) | O2: =IF($B2="","",IFERROR(VLOOKUP($B2,Mapping!$A:$C,2,0),"Not Mapped")) | P2: =IF($B2="","",IFERROR(VLOOKUP($B2,Mapping!$A:$C,3,0),"Not Mapped")) | Q2: =IF($B2="","",IFERROR(VLOOKUP($O2,Leaders!$A:$B,2,0),"Not Mapped")) | R2: =IF($B2="","",IF(COUNTIF(Exclusions!$A:$A,$B2)>0,"Yes","No")) | S2: =IF($B2="","",MIN(1,DAY($A2)/IF($N2="Superstore",Settings!$B$5,Settings!$B$4))) | T2: =IF(OR($B2="",$G2="",$S2=0),"",$G2/$S2) | U2: =IF($T2="","",IF($T2<Settings!$B$8,"Critical",IF($T2<Settings!$B$9,"Semi Critical","Non Critical"))) | Z2: =IF($B2="","",IFERROR(VLOOKUP($B2,'Plan HC for CCA'!$A:$B,2,0),"")) | AA2: =IF(OR($B2="",$Z2=""),"",IF(N($M2)<$Z2,"Delta","No Delta")) | AB2: =IF(OR($B2="",$Z2=""),"",MAX(0,$Z2-N($M2))) | AC2: =IF($B2="","",IFERROR(INDEX('CCA Util %'!$H:$H,MATCH($B2,'CCA Util %'!$E:$E,0)),"")) | AD2: =IF($B2="","",IFERROR(INDEX('CCA Util %'!$G:$G,MATCH($B2,'CCA Util %'!$E:$E,0)),"")) | AE2: =IF(OR($B2="",$U2=""),"",$U2&" & "&IF(OR($AD2="",$AD2=0),"Util NA",$AD2&" Util"))
A3: 46304 | B3: BEL-Sector 12 | C3: RETAIL_STORE | D3: No | E3: Belgavi | F3: 6127 | G3: 0.7976171 | H3: 0.99447514 | I3: 0.998408 | J3: 0.99447514 | K3: 0 | L3: 1 | M3: 3 | N3: =IF($B3="","",IF($C3="SUPERSTORE","Superstore","DH")) | O3: =IF($B3="","",IFERROR(VLOOKUP($B3,Mapping!$A:$C,2,0),"Not Mapped")) | P3: =IF($B3="","",IFERROR(VLOOKUP($B3,Mapping!$A:$C,3,0),"Not Mapped")) | Q3: =IF($B3="","",IFERROR(VLOOKUP($O3,Leaders!$A:$B,2,0),"Not Mapped")) | R3: =IF($B3="","",IF(COUNTIF(Exclusions!$A:$A,$B3)>0,"Yes","No")) | S3: =IF($B3="","",MIN(1,DAY($A3)/IF($N3="Superstore",Settings!$B$5,Settings!$B$4))) | T3: =IF(OR($B3="",$G3="",$S3=0),"",$G3/$S3) | U3: =IF($T3="","",IF($T3<Settings!$B$8,"Critical",IF($T3<Settings!$B$9,"Semi Critical","Non Critical"))) | Z3: =IF($B3="","",IFERROR(VLOOKUP($B3,'Plan HC for CCA'!$A:$B,2,0),"")) | AA3: =IF(OR($B3="",$Z3=""),"",IF(N($M3)<$Z3,"Delta","No Delta")) | AB3: =IF(OR($B3="",$Z3=""),"",MAX(0,$Z3-N($M3))) | AC3: =IF($B3="","",IFERROR(INDEX('CCA Util %'!$H:$H,MATCH($B3,'CCA Util %'!$E:$E,0)),"")) | AD3: =IF($B3="","",IFERROR(INDEX('CCA Util %'!$G:$G,MATCH($B3,'CCA Util %'!$E:$E,0)),"")) | AE3: =IF(OR($B3="",$U3=""),"",$U3&" & "&IF(OR($AD3="",$AD3=0),"Util NA",$AD3&" Util"))
A4: 46304 | B4: BLR - Bhadrappa Layout | C4: RETAIL_STORE | D4: Yes | E4: Bengaluru | F4: 4463 | G4: 0.99977594 | H4: 0.92783505 | I4: 0.983748 | J4: 0.92783505 | K4: 0 | L4: 0.99066739 | M4: 4 | N4: =IF($B4="","",IF($C4="SUPERSTORE","Superstore","DH")) | O4: =IF($B4="","",IFERROR(VLOOKUP($B4,Mapping!$A:$C,2,0),"Not Mapped")) | P4: =IF($B4="","",IFERROR(VLOOKUP($B4,Mapping!$A:$C,3,0),"Not Mapped")) | Q4: =IF($B4="","",IFERROR(VLOOKUP($O4,Leaders!$A:$B,2,0),"Not Mapped")) | R4: =IF($B4="","",IF(COUNTIF(Exclusions!$A:$A,$B4)>0,"Yes","No")) | S4: =IF($B4="","",MIN(1,DAY($A4)/IF($N4="Superstore",Settings!$B$5,Settings!$B$4))) | T4: =IF(OR($B4="",$G4="",$S4=0),"",$G4/$S4) | U4: =IF($T4="","",IF($T4<Settings!$B$8,"Critical",IF($T4<Settings!$B$9,"Semi Critical","Non Critical"))) | Z4: =IF($B4="","",IFERROR(VLOOKUP($B4,'Plan HC for CCA'!$A:$B,2,0),"")) | AA4: =IF(OR($B4="",$Z4=""),"",IF(N($M4)<$Z4,"Delta","No Delta")) | AB4: =IF(OR($B4="",$Z4=""),"",MAX(0,$Z4-N($M4))) | AC4: =IF($B4="","",IFERROR(INDEX('CCA Util %'!$H:$H,MATCH($B4,'CCA Util %'!$E:$E,0)),"")) | AD4: =IF($B4="","",IFERROR(INDEX('CCA Util %'!$G:$G,MATCH($B4,'CCA Util %'!$E:$E,0)),"")) | AE4: =IF(OR($B4="",$U4=""),"",$U4&" & "&IF(OR($AD4="",$AD4=0),"Util NA",$AD4&" Util"))
A5: 46304 | B5: BLR- Brookefield SS | C5: SUPERSTORE | D5: No | E5: Bengaluru | F5: 11768 | G5: 0.39488443 | H5: 0.95588552 | I5: 0.987703 | J5: 0.95588552 | K5: 0 | L5: 1 | M5: 2 | N5: =IF($B5="","",IF($C5="SUPERSTORE","Superstore","DH")) | O5: =IF($B5="","",IFERROR(VLOOKUP($B5,Mapping!$A:$C,2,0),"Not Mapped")) | P5: =IF($B5="","",IFERROR(VLOOKUP($B5,Mapping!$A:$C,3,0),"Not Mapped")) | Q5: =IF($B5="","",IFERROR(VLOOKUP($O5,Leaders!$A:$B,2,0),"Not Mapped")) | R5: =IF($B5="","",IF(COUNTIF(Exclusions!$A:$A,$B5)>0,"Yes","No")) | S5: =IF($B5="","",MIN(1,DAY($A5)/IF($N5="Superstore",Settings!$B$5,Settings!$B$4))) | T5: =IF(OR($B5="",$G5="",$S5=0),"",$G5/$S5) | U5: =IF($T5="","",IF($T5<Settings!$B$8,"Critical",IF($T5<Settings!$B$9,"Semi Critical","Non Critical"))) | Z5: =IF($B5="","",IFERROR(VLOOKUP($B5,'Plan HC for CCA'!$A:$B,2,0),"")) | AA5: =IF(OR($B5="",$Z5=""),"",IF(N($M5)<$Z5,"Delta","No Delta")) | AB5: =IF(OR($B5="",$Z5=""),"",MAX(0,$Z5-N($M5))) | AC5: =IF($B5="","",IFERROR(INDEX('CCA Util %'!$H:$H,MATCH($B5,'CCA Util %'!$E:$E,0)),"")) | AD5: =IF($B5="","",IFERROR(INDEX('CCA Util %'!$G:$G,MATCH($B5,'CCA Util %'!$E:$E,0)),"")) | AE5: =IF(OR($B5="",$U5=""),"",$U5&" & "&IF(OR($AD5="",$AD5=0),"Util NA",$AD5&" Util"))
A6: 46304 | B6: BLR- Sonnenahalli New | C6: RETAIL_STORE | D6: Yes | E6: Bengaluru | F6: 5305 | G6: 0.45259189 | H6: 0.99250312 | I6: 0.977826 | J6: 0.99250312 | K6: 0 | L6: 1 | M6: 2 | N6: =IF($B6="","",IF($C6="SUPERSTORE","Superstore","DH")) | O6: =IF($B6="","",IFERROR(VLOOKUP($B6,Mapping!$A:$C,2,0),"Not Mapped")) | P6: =IF($B6="","",IFERROR(VLOOKUP($B6,Mapping!$A:$C,3,0),"Not Mapped")) | Q6: =IF($B6="","",IFERROR(VLOOKUP($O6,Leaders!$A:$B,2,0),"Not Mapped")) | R6: =IF($B6="","",IF(COUNTIF(Exclusions!$A:$A,$B6)>0,"Yes","No")) | S6: =IF($B6="","",MIN(1,DAY($A6)/IF($N6="Superstore",Settings!$B$5,Settings!$B$4))) | T6: =IF(OR($B6="",$G6="",$S6=0),"",$G6/$S6) | U6: =IF($T6="","",IF($T6<Settings!$B$8,"Critical",IF($T6<Settings!$B$9,"Semi Critical","Non Critical"))) | Z6: =IF($B6="","",IFERROR(VLOOKUP($B6,'Plan HC for CCA'!$A:$B,2,0),"")) | AA6: =IF(OR($B6="",$Z6=""),"",IF(N($M6)<$Z6,"Delta","No Delta")) | AB6: =IF(OR($B6="",$Z6=""),"",MAX(0,$Z6-N($M6))) | AC6: =IF($B6="","",IFERROR(INDEX('CCA Util %'!$H:$H,MATCH($B6,'CCA Util %'!$E:$E,0)),"")) | AD6: =IF($B6="","",IFERROR(INDEX('CCA Util %'!$G:$G,MATCH($B6,'CCA Util %'!$E:$E,0)),"")) | AE6: =IF(OR($B6="",$U6=""),"",$U6&" & "&IF(OR($AD6="",$AD6=0),"Util NA",$AD6&" Util"))
A7: 46304 | B7: BLR-27th Main Road | C7: RETAIL_STORE | D7: No | E7: Bengaluru | F7: 4212 | G7: 0.80104463 | H7: 0.80082988 | I7: 0.977275 | J7: 0.80082988 | K7: 0 | L7: 0.93719153 | M7: 3 | N7: =IF($B7="","",IF($C7="SUPERSTORE","Superstore","DH")) | O7: =IF($B7="","",IFERROR(VLOOKUP($B7,Mapping!$A:$C,2,0),"Not Mapped")) | P7: =IF($B7="","",IFERROR(VLOOKUP($B7,Mapping!$A:$C,3,0),"Not Mapped")) | Q7: =IF($B7="","",IFERROR(VLOOKUP($O7,Leaders!$A:$B,2,0),"Not Mapped")) | R7: =IF($B7="","",IF(COUNTIF(Exclusions!$A:$A,$B7)>0,"Yes","No")) | S7: =IF($B7="","",MIN(1,DAY($A7)/IF($N7="Superstore",Settings!$B$5,Settings!$B$4))) | T7: =IF(OR($B7="",$G7="",$S7=0),"",$G7/$S7) | U7: =IF($T7="","",IF($T7<Settings!$B$8,"Critical",IF($T7<Settings!$B$9,"Semi Critical","Non Critical"))) | Z7: =IF($B7="","",IFERROR(VLOOKUP($B7,'Plan HC for CCA'!$A:$B,2,0),"")) | AA7: =IF(OR($B7="",$Z7=""),"",IF(N($M7)<$Z7,"Delta","No Delta")) | AB7: =IF(OR($B7="",$Z7=""),"",MAX(0,$Z7-N($M7))) | AC7: =IF($B7="","",IFERROR(INDEX('CCA Util %'!$H:$H,MATCH($B7,'CCA Util %'!$E:$E,0)),"")) | AD7: =IF($B7="","",IFERROR(INDEX('CCA Util %'!$G:$G,MATCH($B7,'CCA Util %'!$E:$E,0)),"")) | AE7: =IF(OR($B7="",$U7=""),"",$U7&" & "&IF(OR($AD7="",$AD7=0),"Util NA",$AD7&" Util"))
A8: 46304 | B8: BLR-Abbigere | C8: RETAIL_STORE | D8: Yes | E8: Bengaluru | F8: 6102 | G8: 0.99754179 | H8: 0.95334319 | I8: 0.988139 | J8: 0.95334319 | K8: 0 | L8: 1 | M8: 4 | N8: =IF($B8="","",IF($C8="SUPERSTORE","Superstore","DH")) | O8: =IF($B8="","",IFERROR(VLOOKUP($B8,Mapping!$A:$C,2,0),"Not Mapped")) | P8: =IF($B8="","",IFERROR(VLOOKUP($B8,Mapping!$A:$C,3,0),"Not Mapped")) | Q8: =IF($B8="","",IFERROR(VLOOKUP($O8,Leaders!$A:$B,2,0),"Not Mapped")) | R8: =IF($B8="","",IF(COUNTIF(Exclusions!$A:$A,$B8)>0,"Yes","No")) | S8: =IF($B8="","",MIN(1,DAY($A8)/IF($N8="Superstore",Settings!$B$5,Settings!$B$4))) | T8: =IF(OR($B8="",$G8="",$S8=0),"",$G8/$S8) | U8: =IF($T8="","",IF($T8<Settings!$B$8,"Critical",IF($T8<Settings!$B$9,"Semi Critical","Non Critical"))) | Z8: =IF($B8="","",IFERROR(VLOOKUP($B8,'Plan HC for CCA'!$A:$B,2,0),"")) | AA8: =IF(OR($B8="",$Z8=""),"",IF(N($M8)<$Z8,"Delta","No Delta")) | AB8: =IF(OR($B8="",$Z8=""),"",MAX(0,$Z8-N($M8))) | AC8: =IF($B8="","",IFERROR(INDEX('CCA Util %'!$H:$H,MATCH($B8,'CCA Util %'!$E:$E,0)),"")) | AD8: =IF($B8="","",IFERROR(INDEX('CCA Util %'!$G:$G,MATCH($B8,'CCA Util %'!$E:$E,0)),"")) | AE8: =IF(OR($B8="",$U8=""),"",$U8&" & "&IF(OR($AD8="",$AD8=0),"Util NA",$AD8&" Util"))
A9: 46304 | B9: BLR-Agrahara Road | C9: RETAIL_STORE | D9: Yes | E9: Bengaluru | F9: 5194 | G9: 0.97593377 | H9: 0.93983034 | I9: 0.984343 | J9: 0.93983034 | K9: 0 | L9: 0.99571804 | M9: 3 | N9: =IF($B9="","",IF($C9="SUPERSTORE","Superstore","DH")) | O9: =IF($B9="","",IFERROR(VLOOKUP($B9,Mapping!$A:$C,2,0),"Not Mapped")) | P9: =IF($B9="","",IFERROR(VLOOKUP($B9,Mapping!$A:$C,3,0),"Not Mapped")) | Q9: =IF($B9="","",IFERROR(VLOOKUP($O9,Leaders!$A:$B,2,0),"Not Mapped")) | R9: =IF($B9="","",IF(COUNTIF(Exclusions!$A:$A,$B9)>0,"Yes","No")) | S9: =IF($B9="","",MIN(1,DAY($A9)/IF($N9="Superstore",Settings!$B$5,Settings!$B$4))) | T9: =IF(OR($B9="",$G9="",$S9=0),"",$G9/$S9) | U9: =IF($T9="","",IF($T9<Settings!$B$8,"Critical",IF($T9<Settings!$B$9,"Semi Critical","Non Critical"))) | Z9: =IF($B9="","",IFERROR(VLOOKUP($B9,'Plan HC for CCA'!$A:$B,2,0),"")) | AA9: =IF(OR($B9="",$Z9=""),"",IF(N($M9)<$Z9,"Delta","No Delta")) | AB9: =IF(OR($B9="",$Z9=""),"",MAX(0,$Z9-N($M9))) | AC9: =IF($B9="","",IFERROR(INDEX('CCA Util %'!$H:$H,MATCH($B9,'CCA Util %'!$E:$E,0)),"")) | AD9: =IF($B9="","",IFERROR(INDEX('CCA Util %'!$G:$G,MATCH($B9,'CCA Util %'!$E:$E,0)),"")) | AE9: =IF(OR($B9="",$U9=""),"",$U9&" & "&IF(OR($AD9="",$AD9=0),"Util NA",$AD9&" Util"))
A10: 46304 | B10: BLR-Anjanapura | C10: RETAIL_STORE | D10: Yes | E10: Bengaluru | F10: 7332 | G10: 0.60351882 | H10: 0.97310734 | I10: 0.990094 | J10: 0.97310734 | K10: 0 | L10: 1 | M10: 1 | N10: =IF($B10="","",IF($C10="SUPERSTORE","Superstore","DH")) | O10: =IF($B10="","",IFERROR(VLOOKUP($B10,Mapping!$A:$C,2,0),"Not Mapped")) | P10: =IF($B10="","",IFERROR(VLOOKUP($B10,Mapping!$A:$C,3,0),"Not Mapped")) | Q10: =IF($B10="","",IFERROR(VLOOKUP($O10,Leaders!$A:$B,2,0),"Not Mapped")) | R10: =IF($B10="","",IF(COUNTIF(Exclusions!$A:$A,$B10)>0,"Yes","No")) | S10: =IF($B10="","",MIN(1,DAY($A10)/IF($N10="Superstore",Settings!$B$5,Settings!$B$4))) | T10: =IF(OR($B10="",$G10="",$S10=0),"",$G10/$S10) | U10: =IF($T10="","",IF($T10<Settings!$B$8,"Critical",IF($T10<Settings!$B$9,"Semi Critical","Non Critical"))) | Z10: =IF($B10="","",IFERROR(VLOOKUP($B10,'Plan HC for CCA'!$A:$B,2,0),"")) | AA10: =IF(OR($B10="",$Z10=""),"",IF(N($M10)<$Z10,"Delta","No Delta")) | AB10: =IF(OR($B10="",$Z10=""),"",MAX(0,$Z10-N($M10))) | AC10: =IF($B10="","",IFERROR(INDEX('CCA Util %'!$H:$H,MATCH($B10,'CCA Util %'!$E:$E,0)),"")) | AD10: =IF($B10="","",IFERROR(INDEX('CCA Util %'!$G:$G,MATCH($B10,'CCA Util %'!$E:$E,0)),"")) | AE10: =IF(OR($B10="",$U10=""),"",$U10&" & "&IF(OR($AD10="",$AD10=0),"Util NA",$AD10&" Util"))
A11: 46304 | B11: BLR-Arekere | C11: RETAIL_STORE | D11: Yes | E11: Bengaluru | F11: 6055 | G11: 0.81420314 | H11: 0.80649087 | I11: 0.940736 | J11: 0.80649087 | K11: 0 | L11: 0.9395751 | M11: 6 | N11: =IF($B11="","",IF($C11="SUPERSTORE","Superstore","DH")) | O11: =IF($B11="","",IFERROR(VLOOKUP($B11,Mapping!$A:$C,2,0),"Not Mapped")) | P11: =IF($B11="","",IFERROR(VLOOKUP($B11,Mapping!$A:$C,3,0),"Not Mapped")) | Q11: =IF($B11="","",IFERROR(VLOOKUP($O11,Leaders!$A:$B,2,0),"Not Mapped")) | R11: =IF($B11="","",IF(COUNTIF(Exclusions!$A:$A,$B11)>0,"Yes","No")) | S11: =IF($B11="","",MIN(1,DAY($A11)/IF($N11="Superstore",Settings!$B$5,Settings!$B$4))) | T11: =IF(OR($B11="",$G11="",$S11=0),"",$G11/$S11) | U11: =IF($T11="","",IF($T11<Settings!$B$8,"Critical",IF($T11<Settings!$B$9,"Semi Critical","Non Critical"))) | Z11: =IF($B11="","",IFERROR(VLOOKUP($B11,'Plan HC for CCA'!$A:$B,2,0),"")) | AA11: =IF(OR($B11="",$Z11=""),"",IF(N($M11)<$Z11,"Delta","No Delta")) | AB11: =IF(OR($B11="",$Z11=""),"",MAX(0,$Z11-N($M11))) | AC11: =IF($B11="","",IFERROR(INDEX('CCA Util %'!$H:$H,MATCH($B11,'CCA Util %'!$E:$E,0)),"")) | AD11: =IF($B11="","",IFERROR(INDEX('CCA Util %'!$G:$G,MATCH($B11,'CCA Util %'!$E:$E,0)),"")) | AE11: =IF(OR($B11="",$U11=""),"",$U11&" & "&IF(OR($AD11="",$AD11=0),"Util NA",$AD11&" Util"))
A12: 46304 | B12: BLR-Aswath Nagar | C12: RETAIL_STORE | D12: Yes | E12: Bengaluru | F12: 5167 | G12: 0.93342365 | H12: 0.87186399 | I12: 0.964062 | J12: 0.87186399 | K12: 0 | L12: 0.96710063 | M12: 3 | N12: =IF($B12="","",IF($C12="SUPERSTORE","Superstore","DH")) | O12: =IF($B12="","",IFERROR(VLOOKUP($B12,Mapping!$A:$C,2,0),"Not Mapped")) | P12: =IF($B12="","",IFERROR(VLOOKUP($B12,Mapping!$A:$C,3,0),"Not Mapped")) | Q12: =IF($B12="","",IFERROR(VLOOKUP($O12,Leaders!$A:$B,2,0),"Not Mapped")) | R12: =IF($B12="","",IF(COUNTIF(Exclusions!$A:$A,$B12)>0,"Yes","No")) | S12: =IF($B12="","",MIN(1,DAY($A12)/IF($N12="Superstore",Settings!$B$5,Settings!$B$4))) | T12: =IF(OR($B12="",$G12="",$S12=0),"",$G12/$S12) | U12: =IF($T12="","",IF($T12<Settings!$B$8,"Critical",IF($T12<Settings!$B$9,"Semi Critical","Non Critical"))) | Z12: =IF($B12="","",IFERROR(VLOOKUP($B12,'Plan HC for CCA'!$A:$B,2,0),"")) | AA12: =IF(OR($B12="",$Z12=""),"",IF(N($M12)<$Z12,"Delta","No Delta")) | AB12: =IF(OR($B12="",$Z12=""),"",MAX(0,$Z12-N($M12))) | AC12: =IF($B12="","",IFERROR(INDEX('CCA Util %'!$H:$H,MATCH($B12,'CCA Util %'!$E:$E,0)),"")) | AD12: =IF($B12="","",IFERROR(INDEX('CCA Util %'!$G:$G,MATCH($B12,'CCA Util %'!$E:$E,0)),"")) | AE12: =IF(OR($B12="",$U12=""),"",$U12&" & "&IF(OR($AD12="",$AD12=0),"Util NA",$AD12&" Util"))
A13: 46304 | B13: BLR-Attibele | C13: RETAIL_STORE | D13: Yes | E13: Bengaluru | F13: 7445 | G13: 0.95446608 | H13: 0.93653251 | I13: 0.970763 | K13: 0 | L13: 0.99432948 | M13: 1 | N13: =IF($B13="","",IF($C13="SUPERSTORE","Superstore","DH")) | O13: =IF($B13="","",IFERROR(VLOOKUP($B13,Mapping!$A:$C,2,0),"Not Mapped")) | P13: =IF($B13="","",IFERROR(VLOOKUP($B13,Mapping!$A:$C,3,0),"Not Mapped")) | Q13: =IF($B13="","",IFERROR(VLOOKUP($O13,Leaders!$A:$B,2,0),"Not Mapped")) | R13: =IF($B13="","",IF(COUNTIF(Exclusions!$A:$A,$B13)>0,"Yes","No")) | S13: =IF($B13="","",MIN(1,DAY($A13)/IF($N13="Superstore",Settings!$B$5,Settings!$B$4))) | T13: =IF(OR($B13="",$G13="",$S13=0),"",$G13/$S13) | U13: =IF($T13="","",IF($T13<Settings!$B$8,"Critical",IF($T13<Settings!$B$9,"Semi Critical","Non Critical"))) | Z13: =IF($B13="","",IFERROR(VLOOKUP($B13,'Plan HC for CCA'!$A:$B,2,0),"")) | AA13: =IF(OR($B13="",$Z13=""),"",IF(N($M13)<$Z13,"Delta","No Delta")) | AB13: =IF(OR($B13="",$Z13=""),"",MAX(0,$Z13-N($M13))) | AC13: =IF($B13="","",IFERROR(INDEX('CCA Util %'!$H:$H,MATCH($B13,'CCA Util %'!$E:$E,0)),"")) | AD13: =IF($B13="","",IFERROR(INDEX('CCA Util %'!$G:$G,MATCH($B13,'CCA Util %'!$E:$E,0)),"")) | AE13: =IF(OR($B13="",$U13=""),"",$U13&" & "&IF(OR($AD13="",$AD13=0),"Util NA",$AD13&" Util"))
A14: 46304 | B14: BLR-Avalahalli Main | C14: RETAIL_STORE | D14: Yes | E14: Bengaluru | F14: 6396 | G14: 0.3388055 | H14: 0.73834795 | I14: 0.86305 | J14: 0.73834795 | K14: 0 | L14: 0.91088335 | M14: 4 | N14: =IF($B14="","",IF($C14="SUPERSTORE","Superstore","DH")) | O14: =IF($B14="","",IFERROR(VLOOKUP($B14,Mapping!$A:$C,2,0),"Not Mapped")) | P14: =IF($B14="","",IFERROR(VLOOKUP($B14,Mapping!$A:$C,3,0),"Not Mapped")) | Q14: =IF($B14="","",IFERROR(VLOOKUP($O14,Leaders!$A:$B,2,0),"Not Mapped")) | R14: =IF($B14="","",IF(COUNTIF(Exclusions!$A:$A,$B14)>0,"Yes","No")) | S14: =IF($B14="","",MIN(1,DAY($A14)/IF($N14="Superstore",Settings!$B$5,Settings!$B$4))) | T14: =IF(OR($B14="",$G14="",$S14=0),"",$G14/$S14) | U14: =IF($T14="","",IF($T14<Settings!$B$8,"Critical",IF($T14<Settings!$B$9,"Semi Critical","Non Critical"))) | Z14: =IF($B14="","",IFERROR(VLOOKUP($B14,'Plan HC for CCA'!$A:$B,2,0),"")) | AA14: =IF(OR($B14="",$Z14=""),"",IF(N($M14)<$Z14,"Delta","No Delta")) | AB14: =IF(OR($B14="",$Z14=""),"",MAX(0,$Z14-N($M14))) | AC14: =IF($B14="","",IFERROR(INDEX('CCA Util %'!$H:$H,MATCH($B14,'CCA Util %'!$E:$E,0)),"")) | AD14: =IF($B14="","",IFERROR(INDEX('CCA Util %'!$G:$G,MATCH($B14,'CCA Util %'!$E:$E,0)),"")) | AE14: =IF(OR($B14="",$U14=""),"",$U14&" & "&IF(OR($AD14="",$AD14=0),"Util NA",$AD14&" Util"))
A15: 46304 | B15: BLR-BANNERGHATTA | C15: RETAIL_STORE | D15: No | E15: Bengaluru | F15: 5222 | G15: 0.75277671 | H15: 0.82269143 | I15: 0.959299 | J15: 0.82269143 | K15: 0 | L15: 0.94639639 | M15: 4 | N15: =IF($B15="","",IF($C15="SUPERSTORE","Superstore","DH")) | O15: =IF($B15="","",IFERROR(VLOOKUP($B15,Mapping!$A:$C,2,0),"Not Mapped")) | P15: =IF($B15="","",IFERROR(VLOOKUP($B15,Mapping!$A:$C,3,0),"Not Mapped")) | Q15: =IF($B15="","",IFERROR(VLOOKUP($O15,Leaders!$A:$B,2,0),"Not Mapped")) | R15: =IF($B15="","",IF(COUNTIF(Exclusions!$A:$A,$B15)>0,"Yes","No")) | S15: =IF($B15="","",MIN(1,DAY($A15)/IF($N15="Superstore",Settings!$B$5,Settings!$B$4))) | T15: =IF(OR($B15="",$G15="",$S15=0),"",$G15/$S15) | U15: =IF($T15="","",IF($T15<Settings!$B$8,"Critical",IF($T15<Settings!$B$9,"Semi Critical","Non Critical"))) | Z15: =IF($B15="","",IFERROR(VLOOKUP($B15,'Plan HC for CCA'!$A:$B,2,0),"")) | AA15: =IF(OR($B15="",$Z15=""),"",IF(N($M15)<$Z15,"Delta","No Delta")) | AB15: =IF(OR($B15="",$Z15=""),"",MAX(0,$Z15-N($M15))) | AC15: =IF($B15="","",IFERROR(INDEX('CCA Util %'!$H:$H,MATCH($B15,'CCA Util %'!$E:$E,0)),"")) | AD15: =IF($B15="","",IFERROR(INDEX('CCA Util %'!$G:$G,MATCH($B15,'CCA Util %'!$E:$E,0)),"")) | AE15: =IF(OR($B15="",$U15=""),"",$U15&" & "&IF(OR($AD15="",$AD15=0),"Util NA",$AD15&" Util"))
A16: 46304 | B16: BLR-BASAVANAPURA | C16: RETAIL_STORE | D16: Yes | E16: Bengaluru | F16: 4538 | G16: 0.2717056 | H16: 0.39253852 | I16: 0.836175 | J16: 0.36737602 | K16: 0 | L16: 0.73963838 | M16: 3 | N16: =IF($B16="","",IF($C16="SUPERSTORE","Superstore","DH")) | O16: =IF($B16="","",IFERROR(VLOOKUP($B16,Mapping!$A:$C,2,0),"Not Mapped")) | P16: =IF($B16="","",IFERROR(VLOOKUP($B16,Mapping!$A:$C,3,0),"Not Mapped")) | Q16: =IF($B16="","",IFERROR(VLOOKUP($O16,Leaders!$A:$B,2,0),"Not Mapped")) | R16: =IF($B16="","",IF(COUNTIF(Exclusions!$A:$A,$B16)>0,"Yes","No")) | S16: =IF($B16="","",MIN(1,DAY($A16)/IF($N16="Superstore",Settings!$B$5,Settings!$B$4))) | T16: =IF(OR($B16="",$G16="",$S16=0),"",$G16/$S16) | U16: =IF($T16="","",IF($T16<Settings!$B$8,"Critical",IF($T16<Settings!$B$9,"Semi Critical","Non Critical"))) | Z16: =IF($B16="","",IFERROR(VLOOKUP($B16,'Plan HC for CCA'!$A:$B,2,0),"")) | AA16: =IF(OR($B16="",$Z16=""),"",IF(N($M16)<$Z16,"Delta","No Delta")) | AB16: =IF(OR($B16="",$Z16=""),"",MAX(0,$Z16-N($M16))) | AC16: =IF($B16="","",IFERROR(INDEX('CCA Util %'!$H:$H,MATCH($B16,'CCA Util %'!$E:$E,0)),"")) | AD16: =IF($B16="","",IFERROR(INDEX('CCA Util %'!$G:$G,MATCH($B16,'CCA Util %'!$E:$E,0)),"")) | AE16: =IF(OR($B16="",$U16=""),"",$U16&" & "&IF(OR($AD16="",$AD16=0),"Util NA",$AD16&" Util"))
A17: 46304 | B17: BLR-BASAVANAPURA NETWORK 2 | C17: RETAIL_STORE | D17: Yes | E17: Bengaluru | F17: 5302 | G17: 0.45039608 | H17: 0.76046901 | I17: 0.936732 | J17: 0.76046901 | K17: 0 | L17: 0.92019748 | M17: 3 | N17: =IF($B17="","",IF($C17="SUPERSTORE","Superstore","DH")) | O17: =IF($B17="","",IFERROR(VLOOKUP($B17,Mapping!$A:$C,2,0),"Not Mapped")) | P17: =IF($B17="","",IFERROR(VLOOKUP($B17,Mapping!$A:$C,3,0),"Not Mapped")) | Q17: =IF($B17="","",IFERROR(VLOOKUP($O17,Leaders!$A:$B,2,0),"Not Mapped")) | R17: =IF($B17="","",IF(COUNTIF(Exclusions!$A:$A,$B17)>0,"Yes","No")) | S17: =IF($B17="","",MIN(1,DAY($A17)/IF($N17="Superstore",Settings!$B$5,Settings!$B$4))) | T17: =IF(OR($B17="",$G17="",$S17=0),"",$G17/$S17) | U17: =IF($T17="","",IF($T17<Settings!$B$8,"Critical",IF($T17<Settings!$B$9,"Semi Critical","Non Critical"))) | Z17: =IF($B17="","",IFERROR(VLOOKUP($B17,'Plan HC for CCA'!$A:$B,2,0),"")) | AA17: =IF(OR($B17="",$Z17=""),"",IF(N($M17)<$Z17,"Delta","No Delta")) | AB17: =IF(OR($B17="",$Z17=""),"",MAX(0,$Z17-N($M17))) | AC17: =IF($B17="","",IFERROR(INDEX('CCA Util %'!$H:$H,MATCH($B17,'CCA Util %'!$E:$E,0)),"")) | AD17: =IF($B17="","",IFERROR(INDEX('CCA Util %'!$G:$G,MATCH($B17,'CCA Util %'!$E:$E,0)),"")) | AE17: =IF(OR($B17="",$U17=""),"",$U17&" & "&IF(OR($AD17="",$AD17=0),"Util NA",$AD17&" Util"))
A18: 46304 | B18: BLR-BASAVANAPURA SS | C18: SUPERSTORE | D18: No | E18: Bengaluru | F18: 13185 | G18: 0.48668942 | H18: 0.99672744 | I18: 0.999136 | J18: 0.99672744 | K18: 0 | L18: 1 | M18: 4 | N18: =IF($B18="","",IF($C18="SUPERSTORE","Superstore","DH")) | O18: =IF($B18="","",IFERROR(VLOOKUP($B18,Mapping!$A:$C,2,0),"Not Mapped")) | P18: =IF($B18="","",IFERROR(VLOOKUP($B18,Mapping!$A:$C,3,0),"Not Mapped")) | Q18: =IF($B18="","",IFERROR(VLOOKUP($O18,Leaders!$A:$B,2,0),"Not Mapped")) | R18: =IF($B18="","",IF(COUNTIF(Exclusions!$A:$A,$B18)>0,"Yes","No")) | S18: =IF($B18="","",MIN(1,DAY($A18)/IF($N18="Superstore",Settings!$B$5,Settings!$B$4))) | T18: =IF(OR($B18="",$G18="",$S18=0),"",$G18/$S18) | U18: =IF($T18="","",IF($T18<Settings!$B$8,"Critical",IF($T18<Settings!$B$9,"Semi Critical","Non Critical"))) | Z18: =IF($B18="","",IFERROR(VLOOKUP($B18,'Plan HC for CCA'!$A:$B,2,0),"")) | AA18: =IF(OR($B18="",$Z18=""),"",IF(N($M18)<$Z18,"Delta","No Delta")) | AB18: =IF(OR($B18="",$Z18=""),"",MAX(0,$Z18-N($M18))) | AC18: =IF($B18="","",IFERROR(INDEX('CCA Util %'!$H:$H,MATCH($B18,'CCA Util %'!$E:$E,0)),"")) | AD18: =IF($B18="","",IFERROR(INDEX('CCA Util %'!$G:$G,MATCH($B18,'CCA Util %'!$E:$E,0)),"")) | AE18: =IF(OR($B18="",$U18=""),"",$U18&" & "&IF(OR($AD18="",$AD18=0),"Util NA",$AD18&" Util"))
A19: 46304 | B19: BLR-BELLANDUR - 2 | C19: RETAIL_STORE | D19: Yes | E19: Bengaluru | F19: 5663 | G19: 0.96556595 | H19: 0.89630578 | I19: 0.977457 | J19: 0.89630578 | K19: 0.0088284287 | L19: 0.97562622 | M19: 4 | N19: =IF($B19="","",IF($C19="SUPERSTORE","Superstore","DH")) | O19: =IF($B19="","",IFERROR(VLOOKUP($B19,Mapping!$A:$C,2,0),"Not Mapped")) | P19: =IF($B19="","",IFERROR(VLOOKUP($B19,Mapping!$A:$C,3,0),"Not Mapped")) | Q19: =IF($B19="","",IFERROR(VLOOKUP($O19,Leaders!$A:$B,2,0),"Not Mapped")) | R19: =IF($B19="","",IF(COUNTIF(Exclusions!$A:$A,$B19)>0,"Yes","No")) | S19: =IF($B19="","",MIN(1,DAY($A19)/IF($N19="Superstore",Settings!$B$5,Settings!$B$4))) | T19: =IF(OR($B19="",$G19="",$S19=0),"",$G19/$S19) | U19: =IF($T19="","",IF($T19<Settings!$B$8,"Critical",IF($T19<Settings!$B$9,"Semi Critical","Non Critical"))) | Z19: =IF($B19="","",IFERROR(VLOOKUP($B19,'Plan HC for CCA'!$A:$B,2,0),"")) | AA19: =IF(OR($B19="",$Z19=""),"",IF(N($M19)<$Z19,"Delta","No Delta")) | AB19: =IF(OR($B19="",$Z19=""),"",MAX(0,$Z19-N($M19))) | AC19: =IF($B19="","",IFERROR(INDEX('CCA Util %'!$H:$H,MATCH($B19,'CCA Util %'!$E:$E,0)),"")) | AD19: =IF($B19="","",IFERROR(INDEX('CCA Util %'!$G:$G,MATCH($B19,'CCA Util %'!$E:$E,0)),"")) | AE19: =IF(OR($B19="",$U19=""),"",$U19&" & "&IF(OR($AD19="",$AD19=0),"Util NA",$AD19&" Util"))
A20: 46304 | B20: BLR-BELLANDUR-4 | C20: RETAIL_STORE | D20: Yes | E20: Bengaluru | F20: 5551 | G20: 0.47540984 | H20: 0.82417582 | I20: 0.937842 | J20: 0.82417582 | K20: 0 | L20: 0.9470214 | M20: 4 | N20: =IF($B20="","",IF($C20="SUPERSTORE","Superstore","DH")) | O20: =IF($B20="","",IFERROR(VLOOKUP($B20,Mapping!$A:$C,2,0),"Not Mapped")) | P20: =IF($B20="","",IFERROR(VLOOKUP($B20,Mapping!$A:$C,3,0),"Not Mapped")) | Q20: =IF($B20="","",IFERROR(VLOOKUP($O20,Leaders!$A:$B,2,0),"Not Mapped")) | R20: =IF($B20="","",IF(COUNTIF(Exclusions!$A:$A,$B20)>0,"Yes","No")) | S20: =IF($B20="","",MIN(1,DAY($A20)/IF($N20="Superstore",Settings!$B$5,Settings!$B$4))) | T20: =IF(OR($B20="",$G20="",$S20=0),"",$G20/$S20) | U20: =IF($T20="","",IF($T20<Settings!$B$8,"Critical",IF($T20<Settings!$B$9,"Semi Critical","Non Critical"))) | Z20: =IF($B20="","",IFERROR(VLOOKUP($B20,'Plan HC for CCA'!$A:$B,2,0),"")) | AA20: =IF(OR($B20="",$Z20=""),"",IF(N($M20)<$Z20,"Delta","No Delta")) | AB20: =IF(OR($B20="",$Z20=""),"",MAX(0,$Z20-N($M20))) | AC20: =IF($B20="","",IFERROR(INDEX('CCA Util %'!$H:$H,MATCH($B20,'CCA Util %'!$E:$E,0)),"")) | AD20: =IF($B20="","",IFERROR(INDEX('CCA Util %'!$G:$G,MATCH($B20,'CCA Util %'!$E:$E,0)),"")) | AE20: =IF(OR($B20="",$U20=""),"",$U20&" & "&IF(OR($AD20="",$AD20=0),"Util NA",$AD20&" Util"))
A21: 46304 | B21: BLR-BEML Layout | C21: RETAIL_STORE | D21: Yes | E21: Bengaluru | F21: 6734 | G21: 0.96124146 | H21: 0.9720377 | I21: 0.989857 | J21: 0.9720377 | K21: 0.0032021096 | L21: 0.99935958 | M21: 4 | N21: =IF($B21="","",IF($C21="SUPERSTORE","Superstore","DH")) | O21: =IF($B21="","",IFERROR(VLOOKUP($B21,Mapping!$A:$C,2,0),"Not Mapped")) | P21: =IF($B21="","",IFERROR(VLOOKUP($B21,Mapping!$A:$C,3,0),"Not Mapped")) | Q21: =IF($B21="","",IFERROR(VLOOKUP($O21,Leaders!$A:$B,2,0),"Not Mapped")) | R21: =IF($B21="","",IF(COUNTIF(Exclusions!$A:$A,$B21)>0,"Yes","No")) | S21: =IF($B21="","",MIN(1,DAY($A21)/IF($N21="Superstore",Settings!$B$5,Settings!$B$4))) | T21: =IF(OR($B21="",$G21="",$S21=0),"",$G21/$S21) | U21: =IF($T21="","",IF($T21<Settings!$B$8,"Critical",IF($T21<Settings!$B$9,"Semi Critical","Non Critical"))) | Z21: =IF($B21="","",IFERROR(VLOOKUP($B21,'Plan HC for CCA'!$A:$B,2,0),"")) | AA21: =IF(OR($B21="",$Z21=""),"",IF(N($M21)<$Z21,"Delta","No Delta")) | AB21: =IF(OR($B21="",$Z21=""),"",MAX(0,$Z21-N($M21))) | AC21: =IF($B21="","",IFERROR(INDEX('CCA Util %'!$H:$H,MATCH($B21,'CCA Util %'!$E:$E,0)),"")) | AD21: =IF($B21="","",IFERROR(INDEX('CCA Util %'!$G:$G,MATCH($B21,'CCA Util %'!$E:$E,0)),"")) | AE21: =IF(OR($B21="",$U21=""),"",$U21&" & "&IF(OR($AD21="",$AD21=0),"Util NA",$AD21&" Util"))
A22: 46304 | B22: BLR-BHADRAPPA LAYOUT NETWORK | C22: RETAIL_STORE | D22: Yes | E22: Bengaluru | F22: 6324 | G22: 0.76723593 | H22: 0.78833471 | I22: 0.8286 | J22: 0.78833471 | K22: 0.0035360679 | L22: 0.93122319 | M22: 6 | N22: =IF($B22="","",IF($C22="SUPERSTORE","Superstore","DH")) | O22: =IF($B22="","",IFERROR(VLOOKUP($B22,Mapping!$A:$C,2,0),"Not Mapped")) | P22: =IF($B22="","",IFERROR(VLOOKUP($B22,Mapping!$A:$C,3,0),"Not Mapped")) | Q22: =IF($B22="","",IFERROR(VLOOKUP($O22,Leaders!$A:$B,2,0),"Not Mapped")) | R22: =IF($B22="","",IF(COUNTIF(Exclusions!$A:$A,$B22)>0,"Yes","No")) | S22: =IF($B22="","",MIN(1,DAY($A22)/IF($N22="Superstore",Settings!$B$5,Settings!$B$4))) | T22: =IF(OR($B22="",$G22="",$S22=0),"",$G22/$S22) | U22: =IF($T22="","",IF($T22<Settings!$B$8,"Critical",IF($T22<Settings!$B$9,"Semi Critical","Non Critical"))) | Z22: =IF($B22="","",IFERROR(VLOOKUP($B22,'Plan HC for CCA'!$A:$B,2,0),"")) | AA22: =IF(OR($B22="",$Z22=""),"",IF(N($M22)<$Z22,"Delta","No Delta")) | AB22: =IF(OR($B22="",$Z22=""),"",MAX(0,$Z22-N($M22))) | AC22: =IF($B22="","",IFERROR(INDEX('CCA Util %'!$H:$H,MATCH($B22,'CCA Util %'!$E:$E,0)),"")) | AD22: =IF($B22="","",IFERROR(INDEX('CCA Util %'!$G:$G,MATCH($B22,'CCA Util %'!$E:$E,0)),"")) | AE22: =IF(OR($B22="",$U22=""),"",$U22&" & "&IF(OR($AD22="",$AD22=0),"Util NA",$AD22&" Util"))
A23: 46304 | B23: BLR-BROOKEFIELD | C23: RETAIL_STORE | D23: Yes | E23: Bengaluru | F23: 7849 | G23: 0 | K23: 0 | L23: 0.6 | N23: =IF($B23="","",IF($C23="SUPERSTORE","Superstore","DH")) | O23: =IF($B23="","",IFERROR(VLOOKUP($B23,Mapping!$A:$C,2,0),"Not Mapped")) | P23: =IF($B23="","",IFERROR(VLOOKUP($B23,Mapping!$A:$C,3,0),"Not Mapped")) | Q23: =IF($B23="","",IFERROR(VLOOKUP($O23,Leaders!$A:$B,2,0),"Not Mapped")) | R23: =IF($B23="","",IF(COUNTIF(Exclusions!$A:$A,$B23)>0,"Yes","No")) | S23: =IF($B23="","",MIN(1,DAY($A23)/IF($N23="Superstore",Settings!$B$5,Settings!$B$4))) | T23: =IF(OR($B23="",$G23="",$S23=0),"",$G23/$S23) | U23: =IF($T23="","",IF($T23<Settings!$B$8,"Critical",IF($T23<Settings!$B$9,"Semi Critical","Non Critical"))) | V23: Store Closed | Z23: =IF($B23="","",IFERROR(VLOOKUP($B23,'Plan HC for CCA'!$A:$B,2,0),"")) | AA23: =IF(OR($B23="",$Z23=""),"",IF(N($M23)<$Z23,"Delta","No Delta")) | AB23: =IF(OR($B23="",$Z23=""),"",MAX(0,$Z23-N($M23))) | AC23: =IF($B23="","",IFERROR(INDEX('CCA Util %'!$H:$H,MATCH($B23,'CCA Util %'!$E:$E,0)),"")) | AD23: =IF($B23="","",IFERROR(INDEX('CCA Util %'!$G:$G,MATCH($B23,'CCA Util %'!$E:$E,0)),"")) | AE23: =IF(OR($B23="",$U23=""),"",$U23&" & "&IF(OR($AD23="",$AD23=0),"Util NA",$AD23&" Util"))
A24: 46304 | B24: BLR-BTM LAYOUT NEW | C24: RETAIL_STORE | D24: No | E24: Bengaluru | F24: 6976 | G24: 0.78282683 | H24: 0.8514924 | I24: 0.958625 | J24: 0.8514924 | K24: 0 | L24: 0.95852312 | M24: 7 | N24: =IF($B24="","",IF($C24="SUPERSTORE","Superstore","DH")) | O24: =IF($B24="","",IFERROR(VLOOKUP($B24,Mapping!$A:$C,2,0),"Not Mapped")) | P24: =IF($B24="","",IFERROR(VLOOKUP($B24,Mapping!$A:$C,3,0),"Not Mapped")) | Q24: =IF($B24="","",IFERROR(VLOOKUP($O24,Leaders!$A:$B,2,0),"Not Mapped")) | R24: =IF($B24="","",IF(COUNTIF(Exclusions!$A:$A,$B24)>0,"Yes","No")) | S24: =IF($B24="","",MIN(1,DAY($A24)/IF($N24="Superstore",Settings!$B$5,Settings!$B$4))) | T24: =IF(OR($B24="",$G24="",$S24=0),"",$G24/$S24) | U24: =IF($T24="","",IF($T24<Settings!$B$8,"Critical",IF($T24<Settings!$B$9,"Semi Critical","Non Critical"))) | Z24: =IF($B24="","",IFERROR(VLOOKUP($B24,'Plan HC for CCA'!$A:$B,2,0),"")) | AA24: =IF(OR($B24="",$Z24=""),"",IF(N($M24)<$Z24,"Delta","No Delta")) | AB24: =IF(OR($B24="",$Z24=""),"",MAX(0,$Z24-N($M24))) | AC24: =IF($B24="","",IFERROR(INDEX('CCA Util %'!$H:$H,MATCH($B24,'CCA Util %'!$E:$E,0)),"")) | AD24: =IF($B24="","",IFERROR(INDEX('CCA Util %'!$G:$G,MATCH($B24,'CCA Util %'!$E:$E,0)),"")) | AE24: =IF(OR($B24="",$U24=""),"",$U24&" & "&IF(OR($AD24="",$AD24=0),"Util NA",$AD24&" Util"))
A25: 46304 | B25: BLR-BTM Layout Network-3 | C25: RETAIL_STORE | D25: Yes | E25: Bengaluru | F25: 5155 | G25: 0.6785645 | H25: 0.83962264 | I25: 0.965423 | J25: 0.83962264 | K25: 0.0049375545 | L25: 0.95253781 | M25: 4 | N25: =IF($B25="","",IF($C25="SUPERSTORE","Superstore","DH")) | O25: =IF($B25="","",IFERROR(VLOOKUP($B25,Mapping!$A:$C,2,0),"Not Mapped")) | P25: =IF($B25="","",IFERROR(VLOOKUP($B25,Mapping!$A:$C,3,0),"Not Mapped")) | Q25: =IF($B25="","",IFERROR(VLOOKUP($O25,Leaders!$A:$B,2,0),"Not Mapped")) | R25: =IF($B25="","",IF(COUNTIF(Exclusions!$A:$A,$B25)>0,"Yes","No")) | S25: =IF($B25="","",MIN(1,DAY($A25)/IF($N25="Superstore",Settings!$B$5,Settings!$B$4))) | T25: =IF(OR($B25="",$G25="",$S25=0),"",$G25/$S25) | U25: =IF($T25="","",IF($T25<Settings!$B$8,"Critical",IF($T25<Settings!$B$9,"Semi Critical","Non Critical"))) | Z25: =IF($B25="","",IFERROR(VLOOKUP($B25,'Plan HC for CCA'!$A:$B,2,0),"")) | AA25: =IF(OR($B25="",$Z25=""),"",IF(N($M25)<$Z25,"Delta","No Delta")) | AB25: =IF(OR($B25="",$Z25=""),"",MAX(0,$Z25-N($M25))) | AC25: =IF($B25="","",IFERROR(INDEX('CCA Util %'!$H:$H,MATCH($B25,'CCA Util %'!$E:$E,0)),"")) | AD25: =IF($B25="","",IFERROR(INDEX('CCA Util %'!$G:$G,MATCH($B25,'CCA Util %'!$E:$E,0)),"")) | AE25: =IF(OR($B25="",$U25=""),"",$U25&" & "&IF(OR($AD25="",$AD25=0),"Util NA",$AD25&" Util"))
A26: 46304 | B26: BLR-BTM-2 New | C26: RETAIL_STORE | D26: Yes | E26: Bengaluru | F26: 5768 | G26: 0.99930652 | H26: 0.93789035 | I26: 0.989143 | K26: 0.0031413613 | L26: 0.99427293 | M26: 6 | N26: =IF($B26="","",IF($C26="SUPERSTORE","Superstore","DH")) | O26: =IF($B26="","",IFERROR(VLOOKUP($B26,Mapping!$A:$C,2,0),"Not Mapped")) | P26: =IF($B26="","",IFERROR(VLOOKUP($B26,Mapping!$A:$C,3,0),"Not Mapped")) | Q26: =IF($B26="","",IFERROR(VLOOKUP($O26,Leaders!$A:$B,2,0),"Not Mapped")) | R26: =IF($B26="","",IF(COUNTIF(Exclusions!$A:$A,$B26)>0,"Yes","No")) | S26: =IF($B26="","",MIN(1,DAY($A26)/IF($N26="Superstore",Settings!$B$5,Settings!$B$4))) | T26: =IF(OR($B26="",$G26="",$S26=0),"",$G26/$S26) | U26: =IF($T26="","",IF($T26<Settings!$B$8,"Critical",IF($T26<Settings!$B$9,"Semi Critical","Non Critical"))) | Z26: =IF($B26="","",IFERROR(VLOOKUP($B26,'Plan HC for CCA'!$A:$B,2,0),"")) | AA26: =IF(OR($B26="",$Z26=""),"",IF(N($M26)<$Z26,"Delta","No Delta")) | AB26: =IF(OR($B26="",$Z26=""),"",MAX(0,$Z26-N($M26))) | AC26: =IF($B26="","",IFERROR(INDEX('CCA Util %'!$H:$H,MATCH($B26,'CCA Util %'!$E:$E,0)),"")) | AD26: =IF($B26="","",IFERROR(INDEX('CCA Util %'!$G:$G,MATCH($B26,'CCA Util %'!$E:$E,0)),"")) | AE26: =IF(OR($B26="",$U26=""),"",$U26&" & "&IF(OR($AD26="",$AD26=0),"Util NA",$AD26&" Util"))
A27: 46304 | B27: BLR-BTM-3 | C27: RETAIL_STORE | D27: Yes | E27: Bengaluru | F27: 5097 | G27: 0.78104768 | H27: 0.78623461 | I27: 0.943884 | J27: 0.78623461 | K27: 0.0067716872 | L27: 0.92969182 | M27: 6 | N27: =IF($B27="","",IF($C27="SUPERSTORE","Superstore","DH")) | O27: =IF($B27="","",IFERROR(VLOOKUP($B27,Mapping!$A:$C,2,0),"Not Mapped")) | P27: =IF($B27="","",IFERROR(VLOOKUP($B27,Mapping!$A:$C,3,0),"Not Mapped")) | Q27: =IF($B27="","",IFERROR(VLOOKUP($O27,Leaders!$A:$B,2,0),"Not Mapped")) | R27: =IF($B27="","",IF(COUNTIF(Exclusions!$A:$A,$B27)>0,"Yes","No")) | S27: =IF($B27="","",MIN(1,DAY($A27)/IF($N27="Superstore",Settings!$B$5,Settings!$B$4))) | T27: =IF(OR($B27="",$G27="",$S27=0),"",$G27/$S27) | U27: =IF($T27="","",IF($T27<Settings!$B$8,"Critical",IF($T27<Settings!$B$9,"Semi Critical","Non Critical"))) | Z27: =IF($B27="","",IFERROR(VLOOKUP($B27,'Plan HC for CCA'!$A:$B,2,0),"")) | AA27: =IF(OR($B27="",$Z27=""),"",IF(N($M27)<$Z27,"Delta","No Delta")) | AB27: =IF(OR($B27="",$Z27=""),"",MAX(0,$Z27-N($M27))) | AC27: =IF($B27="","",IFERROR(INDEX('CCA Util %'!$H:$H,MATCH($B27,'CCA Util %'!$E:$E,0)),"")) | AD27: =IF($B27="","",IFERROR(INDEX('CCA Util %'!$G:$G,MATCH($B27,'CCA Util %'!$E:$E,0)),"")) | AE27: =IF(OR($B27="",$U27=""),"",$U27&" & "&IF(OR($AD27="",$AD27=0),"Util NA",$AD27&" Util"))
A28: 46304 | B28: BLR-Bagalakunte | C28: RETAIL_STORE | D28: Yes | E28: Bengaluru | F28: 7531 | G28: 0.47204886 | H28: 0.81125176 | I28: 0.906427 | J28: 0.81125176 | K28: 0.0041293875 | L28: 0.94075381 | M28: 4 | N28: =IF($B28="","",IF($C28="SUPERSTORE","Superstore","DH")) | O28: =IF($B28="","",IFERROR(VLOOKUP($B28,Mapping!$A:$C,2,0),"Not Mapped")) | P28: =IF($B28="","",IFERROR(VLOOKUP($B28,Mapping!$A:$C,3,0),"Not Mapped")) | Q28: =IF($B28="","",IFERROR(VLOOKUP($O28,Leaders!$A:$B,2,0),"Not Mapped")) | R28: =IF($B28="","",IF(COUNTIF(Exclusions!$A:$A,$B28)>0,"Yes","No")) | S28: =IF($B28="","",MIN(1,DAY($A28)/IF($N28="Superstore",Settings!$B$5,Settings!$B$4))) | T28: =IF(OR($B28="",$G28="",$S28=0),"",$G28/$S28) | U28: =IF($T28="","",IF($T28<Settings!$B$8,"Critical",IF($T28<Settings!$B$9,"Semi Critical","Non Critical"))) | Z28: =IF($B28="","",IFERROR(VLOOKUP($B28,'Plan HC for CCA'!$A:$B,2,0),"")) | AA28: =IF(OR($B28="",$Z28=""),"",IF(N($M28)<$Z28,"Delta","No Delta")) | AB28: =IF(OR($B28="",$Z28=""),"",MAX(0,$Z28-N($M28))) | AC28: =IF($B28="","",IFERROR(INDEX('CCA Util %'!$H:$H,MATCH($B28,'CCA Util %'!$E:$E,0)),"")) | AD28: =IF($B28="","",IFERROR(INDEX('CCA Util %'!$G:$G,MATCH($B28,'CCA Util %'!$E:$E,0)),"")) | AE28: =IF(OR($B28="",$U28=""),"",$U28&" & "&IF(OR($AD28="",$AD28=0),"Util NA",$AD28&" Util"))
A29: 46304 | B29: BLR-Bagalur | C29: RETAIL_STORE | D29: Yes | E29: Bengaluru | F29: 5516 | G29: 0.79786077 | H29: 0.79277437 | I29: 0.95335 | J29: 0.79277437 | K29: 0.0016874077 | L29: 0.93346225 | M29: 4 | N29: =IF($B29="","",IF($C29="SUPERSTORE","Superstore","DH")) | O29: =IF($B29="","",IFERROR(VLOOKUP($B29,Mapping!$A:$C,2,0),"Not Mapped")) | P29: =IF($B29="","",IFERROR(VLOOKUP($B29,Mapping!$A:$C,3,0),"Not Mapped")) | Q29: =IF($B29="","",IFERROR(VLOOKUP($O29,Leaders!$A:$B,2,0),"Not Mapped")) | R29: =IF($B29="","",IF(COUNTIF(Exclusions!$A:$A,$B29)>0,"Yes","No")) | S29: =IF($B29="","",MIN(1,DAY($A29)/IF($N29="Superstore",Settings!$B$5,Settings!$B$4))) | T29: =IF(OR($B29="",$G29="",$S29=0),"",$G29/$S29) | U29: =IF($T29="","",IF($T29<Settings!$B$8,"Critical",IF($T29<Settings!$B$9,"Semi Critical","Non Critical"))) | Z29: =IF($B29="","",IFERROR(VLOOKUP($B29,'Plan HC for CCA'!$A:$B,2,0),"")) | AA29: =IF(OR($B29="",$Z29=""),"",IF(N($M29)<$Z29,"Delta","No Delta")) | AB29: =IF(OR($B29="",$Z29=""),"",MAX(0,$Z29-N($M29))) | AC29: =IF($B29="","",IFERROR(INDEX('CCA Util %'!$H:$H,MATCH($B29,'CCA Util %'!$E:$E,0)),"")) | AD29: =IF($B29="","",IFERROR(INDEX('CCA Util %'!$G:$G,MATCH($B29,'CCA Util %'!$E:$E,0)),"")) | AE29: =IF(OR($B29="",$U29=""),"",$U29&" & "&IF(OR($AD29="",$AD29=0),"Util NA",$AD29&" Util"))
A30: 46304 | B30: BLR-Balagere SS | C30: SUPERSTORE | D30: No | E30: Bengaluru | F30: 10619 | G30: 0.033524814 | H30: 0.0084269663 | I30: -0.997121 | J30: 0.00097311236 | K30: 0 | L30: 0.2497382 | N30: =IF($B30="","",IF($C30="SUPERSTORE","Superstore","DH")) | O30: =IF($B30="","",IFERROR(VLOOKUP($B30,Mapping!$A:$C,2,0),"Not Mapped")) | P30: =IF($B30="","",IFERROR(VLOOKUP($B30,Mapping!$A:$C,3,0),"Not Mapped")) | Q30: =IF($B30="","",IFERROR(VLOOKUP($O30,Leaders!$A:$B,2,0),"Not Mapped")) | R30: =IF($B30="","",IF(COUNTIF(Exclusions!$A:$A,$B30)>0,"Yes","No")) | S30: =IF($B30="","",MIN(1,DAY($A30)/IF($N30="Superstore",Settings!$B$5,Settings!$B$4))) | T30: =IF(OR($B30="",$G30="",$S30=0),"",$G30/$S30) | U30: =IF($T30="","",IF($T30<Settings!$B$8,"Critical",IF($T30<Settings!$B$9,"Semi Critical","Non Critical"))) | V30: Store Closed | Z30: =IF($B30="","",IFERROR(VLOOKUP($B30,'Plan HC for CCA'!$A:$B,2,0),"")) | AA30: =IF(OR($B30="",$Z30=""),"",IF(N($M30)<$Z30,"Delta","No Delta")) | AB30: =IF(OR($B30="",$Z30=""),"",MAX(0,$Z30-N($M30))) | AC30: =IF($B30="","",IFERROR(INDEX('CCA Util %'!$H:$H,MATCH($B30,'CCA Util %'!$E:$E,0)),"")) | AD30: =IF($B30="","",IFERROR(INDEX('CCA Util %'!$G:$G,MATCH($B30,'CCA Util %'!$E:$E,0)),"")) | AE30: =IF(OR($B30="",$U30=""),"",$U30&" & "&IF(OR($AD30="",$AD30=0),"Util NA",$AD30&" Util"))
A31: 46304 | B31: BLR-Banashankari Network | C31: RETAIL_STORE | D31: Yes | E31: Bengaluru | F31: 5783 | G31: 0.66937576 | H31: 0.86101782 | I31: 0.960456 | J31: 0.86101782 | K31: 0 | L31: 0.96253382 | M31: 3 | N31: =IF($B31="","",IF($C31="SUPERSTORE","Superstore","DH")) | O31: =IF($B31="","",IFERROR(VLOOKUP($B31,Mapping!$A:$C,2,0),"Not Mapped")) | P31: =IF($B31="","",IFERROR(VLOOKUP($B31,Mapping!$A:$C,3,0),"Not Mapped")) | Q31: =IF($B31="","",IFERROR(VLOOKUP($O31,Leaders!$A:$B,2,0),"Not Mapped")) | R31: =IF($B31="","",IF(COUNTIF(Exclusions!$A:$A,$B31)>0,"Yes","No")) | S31: =IF($B31="","",MIN(1,DAY($A31)/IF($N31="Superstore",Settings!$B$5,Settings!$B$4))) | T31: =IF(OR($B31="",$G31="",$S31=0),"",$G31/$S31) | U31: =IF($T31="","",IF($T31<Settings!$B$8,"Critical",IF($T31<Settings!$B$9,"Semi Critical","Non Critical"))) | Z31: =IF($B31="","",IFERROR(VLOOKUP($B31,'Plan HC for CCA'!$A:$B,2,0),"")) | AA31: =IF(OR($B31="",$Z31=""),"",IF(N($M31)<$Z31,"Delta","No Delta")) | AB31: =IF(OR($B31="",$Z31=""),"",MAX(0,$Z31-N($M31))) | AC31: =IF($B31="","",IFERROR(INDEX('CCA Util %'!$H:$H,MATCH($B31,'CCA Util %'!$E:$E,0)),"")) | AD31: =IF($B31="","",IFERROR(INDEX('CCA Util %'!$G:$G,MATCH($B31,'CCA Util %'!$E:$E,0)),"")) | AE31: =IF(OR($B31="",$U31=""),"",$U31&" & "&IF(OR($AD31="",$AD31=0),"Util NA",$AD31&" Util"))
A32: 46304 | B32: BLR-Banashankari New | C32: RETAIL_STORE | D32: Yes | E32: Bengaluru | F32: 5165 | G32: 0.66292352 | H32: 0.89778037 | I32: 0.973729 | J32: 0.89778037 | K32: 0 | L32: 0.97801279 | N32: =IF($B32="","",IF($C32="SUPERSTORE","Superstore","DH")) | O32: =IF($B32="","",IFERROR(VLOOKUP($B32,Mapping!$A:$C,2,0),"Not Mapped")) | P32: =IF($B32="","",IFERROR(VLOOKUP($B32,Mapping!$A:$C,3,0),"Not Mapped")) | Q32: =IF($B32="","",IFERROR(VLOOKUP($O32,Leaders!$A:$B,2,0),"Not Mapped")) | R32: =IF($B32="","",IF(COUNTIF(Exclusions!$A:$A,$B32)>0,"Yes","No")) | S32: =IF($B32="","",MIN(1,DAY($A32)/IF($N32="Superstore",Settings!$B$5,Settings!$B$4))) | T32: =IF(OR($B32="",$G32="",$S32=0),"",$G32/$S32) | U32: =IF($T32="","",IF($T32<Settings!$B$8,"Critical",IF($T32<Settings!$B$9,"Semi Critical","Non Critical"))) | Z32: =IF($B32="","",IFERROR(VLOOKUP($B32,'Plan HC for CCA'!$A:$B,2,0),"")) | AA32: =IF(OR($B32="",$Z32=""),"",IF(N($M32)<$Z32,"Delta","No Delta")) | AB32: =IF(OR($B32="",$Z32=""),"",MAX(0,$Z32-N($M32))) | AC32: =IF($B32="","",IFERROR(INDEX('CCA Util %'!$H:$H,MATCH($B32,'CCA Util %'!$E:$E,0)),"")) | AD32: =IF($B32="","",IFERROR(INDEX('CCA Util %'!$G:$G,MATCH($B32,'CCA Util %'!$E:$E,0)),"")) | AE32: =IF(OR($B32="",$U32=""),"",$U32&" & "&IF(OR($AD32="",$AD32=0),"Util NA",$AD32&" Util"))
A33: 46304 | B33: BLR-Banjara Layout | C33: RETAIL_STORE | D33: Yes | E33: Bengaluru | F33: 7186 | G33: 0.83189535 | H33: 0.83640013 | I33: 0.928781 | J33: 0.83640013 | K33: 0 | L33: 0.95216848 | M33: 2 | N33: =IF($B33="","",IF($C33="SUPERSTORE","Superstore","DH")) | O33: =IF($B33="","",IFERROR(VLOOKUP($B33,Mapping!$A:$C,2,0),"Not Mapped")) | P33: =IF($B33="","",IFERROR(VLOOKUP($B33,Mapping!$A:$C,3,0),"Not Mapped")) | Q33: =IF($B33="","",IFERROR(VLOOKUP($O33,Leaders!$A:$B,2,0),"Not Mapped")) | R33: =IF($B33="","",IF(COUNTIF(Exclusions!$A:$A,$B33)>0,"Yes","No")) | S33: =IF($B33="","",MIN(1,DAY($A33)/IF($N33="Superstore",Settings!$B$5,Settings!$B$4))) | T33: =IF(OR($B33="",$G33="",$S33=0),"",$G33/$S33) | U33: =IF($T33="","",IF($T33<Settings!$B$8,"Critical",IF($T33<Settings!$B$9,"Semi Critical","Non Critical"))) | Z33: =IF($B33="","",IFERROR(VLOOKUP($B33,'Plan HC for CCA'!$A:$B,2,0),"")) | AA33: =IF(OR($B33="",$Z33=""),"",IF(N($M33)<$Z33,"Delta","No Delta")) | AB33: =IF(OR($B33="",$Z33=""),"",MAX(0,$Z33-N($M33))) | AC33: =IF($B33="","",IFERROR(INDEX('CCA Util %'!$H:$H,MATCH($B33,'CCA Util %'!$E:$E,0)),"")) | AD33: =IF($B33="","",IFERROR(INDEX('CCA Util %'!$G:$G,MATCH($B33,'CCA Util %'!$E:$E,0)),"")) | AE33: =IF(OR($B33="",$U33=""),"",$U33&" & "&IF(OR($AD33="",$AD33=0),"Util NA",$AD33&" Util"))
A34: 46304 | B34: BLR-Bannerghatta Network | C34: RETAIL_STORE | D34: Yes | E34: Bengaluru | F34: 5330 | G34: 0.66679174 | H34: 0.86072032 | I34: 0.968499 | J34: 0.86072032 | K34: 0.005501965 | L34: 0.96130816 | M34: 4 | N34: =IF($B34="","",IF($C34="SUPERSTORE","Superstore","DH")) | O34: =IF($B34="","",IFERROR(VLOOKUP($B34,Mapping!$A:$C,2,0),"Not Mapped")) | P34: =IF($B34="","",IFERROR(VLOOKUP($B34,Mapping!$A:$C,3,0),"Not Mapped")) | Q34: =IF($B34="","",IFERROR(VLOOKUP($O34,Leaders!$A:$B,2,0),"Not Mapped")) | R34: =IF($B34="","",IF(COUNTIF(Exclusions!$A:$A,$B34)>0,"Yes","No")) | S34: =IF($B34="","",MIN(1,DAY($A34)/IF($N34="Superstore",Settings!$B$5,Settings!$B$4))) | T34: =IF(OR($B34="",$G34="",$S34=0),"",$G34/$S34) | U34: =IF($T34="","",IF($T34<Settings!$B$8,"Critical",IF($T34<Settings!$B$9,"Semi Critical","Non Critical"))) | Z34: =IF($B34="","",IFERROR(VLOOKUP($B34,'Plan HC for CCA'!$A:$B,2,0),"")) | AA34: =IF(OR($B34="",$Z34=""),"",IF(N($M34)<$Z34,"Delta","No Delta")) | AB34: =IF(OR($B34="",$Z34=""),"",MAX(0,$Z34-N($M34))) | AC34: =IF($B34="","",IFERROR(INDEX('CCA Util %'!$H:$H,MATCH($B34,'CCA Util %'!$E:$E,0)),"")) | AD34: =IF($B34="","",IFERROR(INDEX('CCA Util %'!$G:$G,MATCH($B34,'CCA Util %'!$E:$E,0)),"")) | AE34: =IF(OR($B34="",$U34=""),"",$U34&" & "&IF(OR($AD34="",$AD34=0),"Util NA",$AD34&" Util"))
A35: 46304 | B35: BLR-Bannerghatta Network 2 | C35: RETAIL_STORE | D35: No | E35: Bengaluru | F35: 5022 | G35: 0.56770211 | H35: 0.7790249 | I35: 0.926306 | J35: 0.7790249 | K35: 0 | L35: 0.92801049 | M35: 4 | N35: =IF($B35="","",IF($C35="SUPERSTORE","Superstore","DH")) | O35: =IF($B35="","",IFERROR(VLOOKUP($B35,Mapping!$A:$C,2,0),"Not Mapped")) | P35: =IF($B35="","",IFERROR(VLOOKUP($B35,Mapping!$A:$C,3,0),"Not Mapped")) | Q35: =IF($B35="","",IFERROR(VLOOKUP($O35,Leaders!$A:$B,2,0),"Not Mapped")) | R35: =IF($B35="","",IF(COUNTIF(Exclusions!$A:$A,$B35)>0,"Yes","No")) | S35: =IF($B35="","",MIN(1,DAY($A35)/IF($N35="Superstore",Settings!$B$5,Settings!$B$4))) | T35: =IF(OR($B35="",$G35="",$S35=0),"",$G35/$S35) | U35: =IF($T35="","",IF($T35<Settings!$B$8,"Critical",IF($T35<Settings!$B$9,"Semi Critical","Non Critical"))) | Z35: =IF($B35="","",IFERROR(VLOOKUP($B35,'Plan HC for CCA'!$A:$B,2,0),"")) | AA35: =IF(OR($B35="",$Z35=""),"",IF(N($M35)<$Z35,"Delta","No Delta")) | AB35: =IF(OR($B35="",$Z35=""),"",MAX(0,$Z35-N($M35))) | AC35: =IF($B35="","",IFERROR(INDEX('CCA Util %'!$H:$H,MATCH($B35,'CCA Util %'!$E:$E,0)),"")) | AD35: =IF($B35="","",IFERROR(INDEX('CCA Util %'!$G:$G,MATCH($B35,'CCA Util %'!$E:$E,0)),"")) | AE35: =IF(OR($B35="",$U35=""),"",$U35&" & "&IF(OR($AD35="",$AD35=0),"Util NA",$AD35&" Util"))
A36: 46304 | B36: BLR-Bannerghatta SS | C36: SUPERSTORE | D36: No | E36: Bengaluru | F36: 10225 | G36: 0.35334963 | H36: 0.9706615 | I36: 0.988853 | J36: 0.9706615 | K36: 0 | L36: 1 | M36: 1 | N36: =IF($B36="","",IF($C36="SUPERSTORE","Superstore","DH")) | O36: =IF($B36="","",IFERROR(VLOOKUP($B36,Mapping!$A:$C,2,0),"Not Mapped")) | P36: =IF($B36="","",IFERROR(VLOOKUP($B36,Mapping!$A:$C,3,0),"Not Mapped")) | Q36: =IF($B36="","",IFERROR(VLOOKUP($O36,Leaders!$A:$B,2,0),"Not Mapped")) | R36: =IF($B36="","",IF(COUNTIF(Exclusions!$A:$A,$B36)>0,"Yes","No")) | S36: =IF($B36="","",MIN(1,DAY($A36)/IF($N36="Superstore",Settings!$B$5,Settings!$B$4))) | T36: =IF(OR($B36="",$G36="",$S36=0),"",$G36/$S36) | U36: =IF($T36="","",IF($T36<Settings!$B$8,"Critical",IF($T36<Settings!$B$9,"Semi Critical","Non Critical"))) | Z36: =IF($B36="","",IFERROR(VLOOKUP($B36,'Plan HC for CCA'!$A:$B,2,0),"")) | AA36: =IF(OR($B36="",$Z36=""),"",IF(N($M36)<$Z36,"Delta","No Delta")) | AB36: =IF(OR($B36="",$Z36=""),"",MAX(0,$Z36-N($M36))) | AC36: =IF($B36="","",IFERROR(INDEX('CCA Util %'!$H:$H,MATCH($B36,'CCA Util %'!$E:$E,0)),"")) | AD36: =IF($B36="","",IFERROR(INDEX('CCA Util %'!$G:$G,MATCH($B36,'CCA Util %'!$E:$E,0)),"")) | AE36: =IF(OR($B36="",$U36=""),"",$U36&" & "&IF(OR($AD36="",$AD36=0),"Util NA",$AD36&" Util"))
A37: 46304 | B37: BLR-Basavanapura Network | C37: RETAIL_STORE | D37: Yes | E37: Bengaluru | F37: 7642 | G37: 0.65532583 | H37: 0.86821086 | I37: 0.97246 | J37: 0.86821086 | K37: 0 | L37: 0.96556247 | M37: 5 | N37: =IF($B37="","",IF($C37="SUPERSTORE","Superstore","DH")) | O37: =IF($B37="","",IFERROR(VLOOKUP($B37,Mapping!$A:$C,2,0),"Not Mapped")) | P37: =IF($B37="","",IFERROR(VLOOKUP($B37,Mapping!$A:$C,3,0),"Not Mapped")) | Q37: =IF($B37="","",IFERROR(VLOOKUP($O37,Leaders!$A:$B,2,0),"Not Mapped")) | R37: =IF($B37="","",IF(COUNTIF(Exclusions!$A:$A,$B37)>0,"Yes","No")) | S37: =IF($B37="","",MIN(1,DAY($A37)/IF($N37="Superstore",Settings!$B$5,Settings!$B$4))) | T37: =IF(OR($B37="",$G37="",$S37=0),"",$G37/$S37) | U37: =IF($T37="","",IF($T37<Settings!$B$8,"Critical",IF($T37<Settings!$B$9,"Semi Critical","Non Critical"))) | Z37: =IF($B37="","",IFERROR(VLOOKUP($B37,'Plan HC for CCA'!$A:$B,2,0),"")) | AA37: =IF(OR($B37="",$Z37=""),"",IF(N($M37)<$Z37,"Delta","No Delta")) | AB37: =IF(OR($B37="",$Z37=""),"",MAX(0,$Z37-N($M37))) | AC37: =IF($B37="","",IFERROR(INDEX('CCA Util %'!$H:$H,MATCH($B37,'CCA Util %'!$E:$E,0)),"")) | AD37: =IF($B37="","",IFERROR(INDEX('CCA Util %'!$G:$G,MATCH($B37,'CCA Util %'!$E:$E,0)),"")) | AE37: =IF(OR($B37="",$U37=""),"",$U37&" & "&IF(OR($AD37="",$AD37=0),"Util NA",$AD37&" Util"))
A38: 46304 | B38: BLR-Belathur | C38: RETAIL_STORE | D38: Yes | E38: Bengaluru | F38: 5788 | G38: 0.96423635 | H38: 0.93782476 | I38: 0.990364 | J38: 0.93782476 | K38: 0 | L38: 0.99487358 | M38: 6 | N38: =IF($B38="","",IF($C38="SUPERSTORE","Superstore","DH")) | O38: =IF($B38="","",IFERROR(VLOOKUP($B38,Mapping!$A:$C,2,0),"Not Mapped")) | P38: =IF($B38="","",IFERROR(VLOOKUP($B38,Mapping!$A:$C,3,0),"Not Mapped")) | Q38: =IF($B38="","",IFERROR(VLOOKUP($O38,Leaders!$A:$B,2,0),"Not Mapped")) | R38: =IF($B38="","",IF(COUNTIF(Exclusions!$A:$A,$B38)>0,"Yes","No")) | S38: =IF($B38="","",MIN(1,DAY($A38)/IF($N38="Superstore",Settings!$B$5,Settings!$B$4))) | T38: =IF(OR($B38="",$G38="",$S38=0),"",$G38/$S38) | U38: =IF($T38="","",IF($T38<Settings!$B$8,"Critical",IF($T38<Settings!$B$9,"Semi Critical","Non Critical"))) | Z38: =IF($B38="","",IFERROR(VLOOKUP($B38,'Plan HC for CCA'!$A:$B,2,0),"")) | AA38: =IF(OR($B38="",$Z38=""),"",IF(N($M38)<$Z38,"Delta","No Delta")) | AB38: =IF(OR($B38="",$Z38=""),"",MAX(0,$Z38-N($M38))) | AC38: =IF($B38="","",IFERROR(INDEX('CCA Util %'!$H:$H,MATCH($B38,'CCA Util %'!$E:$E,0)),"")) | AD38: =IF($B38="","",IFERROR(INDEX('CCA Util %'!$G:$G,MATCH($B38,'CCA Util %'!$E:$E,0)),"")) | AE38: =IF(OR($B38="",$U38=""),"",$U38&" & "&IF(OR($AD38="",$AD38=0),"Util NA",$AD38&" Util"))
A39: 46304 | B39: BLR-Bellandur 6 | C39: RETAIL_STORE | D39: Yes | E39: Bengaluru | F39: 6158 | G39: 0.79116596 | H39: 0.83189655 | I39: 0.953668 | J39: 0.83189655 | K39: 0.0029579693 | L39: 0.94968064 | M39: 4 | N39: =IF($B39="","",IF($C39="SUPERSTORE","Superstore","DH")) | O39: =IF($B39="","",IFERROR(VLOOKUP($B39,Mapping!$A:$C,2,0),"Not Mapped")) | P39: =IF($B39="","",IFERROR(VLOOKUP($B39,Mapping!$A:$C,3,0),"Not Mapped")) | Q39: =IF($B39="","",IFERROR(VLOOKUP($O39,Leaders!$A:$B,2,0),"Not Mapped")) | R39: =IF($B39="","",IF(COUNTIF(Exclusions!$A:$A,$B39)>0,"Yes","No")) | S39: =IF($B39="","",MIN(1,DAY($A39)/IF($N39="Superstore",Settings!$B$5,Settings!$B$4))) | T39: =IF(OR($B39="",$G39="",$S39=0),"",$G39/$S39) | U39: =IF($T39="","",IF($T39<Settings!$B$8,"Critical",IF($T39<Settings!$B$9,"Semi Critical","Non Critical"))) | Z39: =IF($B39="","",IFERROR(VLOOKUP($B39,'Plan HC for CCA'!$A:$B,2,0),"")) | AA39: =IF(OR($B39="",$Z39=""),"",IF(N($M39)<$Z39,"Delta","No Delta")) | AB39: =IF(OR($B39="",$Z39=""),"",MAX(0,$Z39-N($M39))) | AC39: =IF($B39="","",IFERROR(INDEX('CCA Util %'!$H:$H,MATCH($B39,'CCA Util %'!$E:$E,0)),"")) | AD39: =IF($B39="","",IFERROR(INDEX('CCA Util %'!$G:$G,MATCH($B39,'CCA Util %'!$E:$E,0)),"")) | AE39: =IF(OR($B39="",$U39=""),"",$U39&" & "&IF(OR($AD39="",$AD39=0),"Util NA",$AD39&" Util"))
A40: 46304 | B40: BLR-Bellandur SS | C40: SUPERSTORE | D40: No | E40: Bengaluru | F40: 10796 | G40: 0.2682475 | H40: 0.94854972 | I40: 0.987524 | J40: 0.87643433 | K40: 0 | L40: 0.96897836 | M40: 1 | N40: =IF($B40="","",IF($C40="SUPERSTORE","Superstore","DH")) | O40: =IF($B40="","",IFERROR(VLOOKUP($B40,Mapping!$A:$C,2,0),"Not Mapped")) | P40: =IF($B40="","",IFERROR(VLOOKUP($B40,Mapping!$A:$C,3,0),"Not Mapped")) | Q40: =IF($B40="","",IFERROR(VLOOKUP($O40,Leaders!$A:$B,2,0),"Not Mapped")) | R40: =IF($B40="","",IF(COUNTIF(Exclusions!$A:$A,$B40)>0,"Yes","No")) | S40: =IF($B40="","",MIN(1,DAY($A40)/IF($N40="Superstore",Settings!$B$5,Settings!$B$4))) | T40: =IF(OR($B40="",$G40="",$S40=0),"",$G40/$S40) | U40: =IF($T40="","",IF($T40<Settings!$B$8,"Critical",IF($T40<Settings!$B$9,"Semi Critical","Non Critical"))) | Z40: =IF($B40="","",IFERROR(VLOOKUP($B40,'Plan HC for CCA'!$A:$B,2,0),"")) | AA40: =IF(OR($B40="",$Z40=""),"",IF(N($M40)<$Z40,"Delta","No Delta")) | AB40: =IF(OR($B40="",$Z40=""),"",MAX(0,$Z40-N($M40))) | AC40: =IF($B40="","",IFERROR(INDEX('CCA Util %'!$H:$H,MATCH($B40,'CCA Util %'!$E:$E,0)),"")) | AD40: =IF($B40="","",IFERROR(INDEX('CCA Util %'!$G:$G,MATCH($B40,'CCA Util %'!$E:$E,0)),"")) | AE40: =IF(OR($B40="",$U40=""),"",$U40&" & "&IF(OR($AD40="",$AD40=0),"Util NA",$AD40&" Util"))
...

Sheet Daily SBC
H1: =SUM(H3:H1000) | I1: =SUM(I3:I1000) | J1: =SUM(J3:J1000) | K1: =SUM(K3:K1000) | L1: =SUM(L3:L1000) | M1: =SUM(M3:M1000) | N1: =SUM(N3:N1000) | O1: =SUM(O3:O1000) | P1: =SUM(P3:P1000)
A2: Leaders | B2: CLM | C2: IM | D2: city_name | E2: store_name | F2: Total Bins | G2: Per Day SBC Traget | H2: 46032 | I2: 46063 | J2: 46091 | K2: 46122 | L2: 46152 | M2: 46183 | N2: 46213 | O2: 46244 | P2: 46275
A3: {=LET( s, E3:E1000, clm, IFERROR(VLOOKUP(s, Mapping!A:C, 2, 0), "Un Mapped"), im, IFERROR(VLOOKUP(s, Mapping!A:C, 3, 0), "Un Mapped"), ldr, IFERROR(VLOOKUP(clm, Leaders!A:B, 2, 0), "Un Mapped"), HSTACK(IF(s="",,ldr), IF(s="",,clm), IF(s="",,im)) )} | B3: Majid Kakatikar | C3: Kishor K | D3: Belgavi | E3: BEL-Khanapur Road | F3: 6826 | G3: 455 | H3: 321 | I3: 437 | J3: 520 | K3: 243 | L3: 655 | M3: 12 | N3: 207 | O3: 280 | P3: 942
A4: Bangareppa CS | B4: Majid Kakatikar | C4: Kishor K | D4: Belgavi | E4: BEL-Sector 12 | F4: 6127 | G4: 409 | H4: 1240 | I4: 950 | J4: 764 | K4: 444 | L4: 629 | M4: 92 | N4: 105 | O4: 359 | P4: 304
A5: Ashwath S | B5: Mohaideen DH | C5: Mohammed Akbar | D5: Bengaluru | E5: BLR - Bhadrappa Layout | F5: 4463 | G5: 298 | H5: 2026 | I5: 969 | J5: 747 | K5: 155 | L5: 554 | M5: 10 | N5: 1 | O5: 0 | P5: 0
A6: Lakshman Balakrishnan | B6: Arun Raj | C6: Simon Manoharan | D6: Bengaluru | E6: BLR- Brookefield SS | F6: 11768 | G6: 785 | H6: 998 | I6: 694 | J6: 374 | K6: 371 | L6: 402 | M6: 522 | N6: 560 | O6: 265 | P6: 461
A7: Deepak D M | B7: Narasimhamurthy R | C7: Kishor K | D7: Bengaluru | E7: BLR- Sonnenahalli New | F7: 5305 | G7: 354 | H7: 330 | I7: 535 | J7: 629 | K7: 213 | L7: 148 | M7: 160 | N7: 111 | O7: 119 | P7: 156
A8: Lakshman Balakrishnan | B8: Saddam Hussain | C8: Un Mapped | D8: Bengaluru | E8: BLR-27th Main Road | F8: 4212 | G8: 281 | H8: 413 | I8: 501 | J8: 797 | K8: 667 | L8: 521 | M8: 133 | N8: 99 | O8: 109 | P8: 134
A9: Bangareppa CS | B9: Akshay P | C9: Srittam Dhal | D9: Bengaluru | E9: BLR-Abbigere | F9: 6102 | G9: 407 | H9: 1447 | I9: 950 | J9: 1183 | K9: 493 | L9: 314 | M9: 936 | N9: 338 | O9: 303 | P9: 123
A10: Lakshman Balakrishnan | B10: Saddam Hussain | C10: Un Mapped | D10: Bengaluru | E10: BLR-Agrahara Road | F10: 5194 | G10: 346 | H10: 723 | I10: 661 | J10: 793 | K10: 1166 | L10: 902 | M10: 556 | N10: 200 | O10: 11 | P10: 57
A11: Raghavendra Vernekar | B11: Suhas N | C11: Aravind S | D11: Bengaluru | E11: BLR-Anjanapura | F11: 7332 | G11: 489 | H11: 8 | I11: 525 | J11: 665 | K11: 703 | L11: 1097 | M11: 834 | N11: 589 | O11: 3 | P11: 1
A12: Raghavendra Vernekar | B12: Manjunatha V | C12: Un Mapped | D12: Bengaluru | E12: BLR-Arekere | F12: 6055 | G12: 404 | H12: 1646 | I12: 1467 | J12: 187 | K12: 643 | L12: 730 | M12: 22 | N12: 39 | O12: 84 | P12: 112
A13: Lakshman Balakrishnan | B13: Sundaresh S | C13: Un Mapped | D13: Bengaluru | E13: BLR-Aswath Nagar | F13: 5167 | G13: 345 | H13: 1310 | I13: 1676 | J13: 49 | K13: 1361 | L13: 396 | M13: 25 | N13: 0 | O13: 0 | P13: 6
A14: Lakshman Balakrishnan | B14: Balaji G | C14: Mohammed Akbar | D14: Bengaluru | E14: BLR-Attibele | F14: 7445 | G14: 497 | H14: 1765 | I14: 1916 | J14: 317 | K14: 1769 | L14: 897 | M14: 442 | N14: 0 | O14: 0 | P14: 0
A15: Raghavendra Vernekar | B15: Suhas N | C15: Aravind S | D15: Bengaluru | E15: BLR-Avalahalli Main | F15: 6396 | G15: 427 | H15: 11 | I15: 19 | J15: 299 | K15: 447 | L15: 343 | M15: 239 | N15: 238 | O15: 429 | P15: 142
... A184: Lakshman Balakrishnan | B184: Saddam Hussain | C184: Un Mapped | D184: Bengaluru | E184: BLR-Silver County | F184: 5663 | G184: 378 | H184: 687 | I184: 437 | J184: 549 | K184: 611 | L184: 454 | M184: 694 | N184: 555 | O184: 333 | P184: 407
A185: Lakshman Balakrishnan | B185: Arun Raj | C185: Simon Manoharan | D185: Bengaluru | E185: BLR-Silver County SS | F185: #N/A | G185: #N/A | H185: 442 | I185: 179 | J185: 310 | K185: 594 | L185: 587 | M185: 708 | N185: 442 | O185: 73 | P185: 795
A186: Bangareppa CS | B186: Akshay P | C186: Srittam Dhal | D186: Bengaluru | E186: BLR-Singapura | F186: 4579 | G186: 305 | H186: 747 | I186: 754 | J186: 981 | K186: 563 | L186: 262 | M186: 244 | N186: 232 | O186: 221 | P186: 112
A187: Lakshman Balakrishnan | B187: Balaji G | C187: Mohammed Akbar | D187: Bengaluru | E187: BLR-Singasandra Network | F187: 5077 | G187: 339 | H187: 1257 | I187: 1279 | J187: 807 | K187: 973 | L187: 324 | M187: 352 | N187: 81 | O187: 3 | P187: 0
A188: Lakshman Balakrishnan | B188: Balaji G | C188: Mohammed Akbar | D188: Bengaluru | E188: BLR-SINGASANDRA NEW | F188: 5948 | G188: 397 | H188: 918 | I188: 840 | J188: 1042 | K188: 208 | L188: 616 | M188: 645 | N188: 456 | O188: 602 | P188: 481
A189: Lakshman Balakrishnan | B189: Arun Raj | C189: Simon Manoharan | D189: Bengaluru | E189: BLR-Singasandra SS | F189: 12266 | G189: 818 | H189: 501 | I189: 714 | J189: 842 | K189: 571 | L189: 511 | M189: 1185 | N189: 267 | O189: 787 | P189: 1020
A190: Lakshman Balakrishnan | B190: Sundaresh S | C190: Un Mapped | D190: Bengaluru | E190: BLR-Sompura | F190: 5757 | G190: 384 | H190: 680 | I190: 549 | J190: 378 | K190: 307 | L190: 641 | M190: 658 | N190: 233 | O190: 419 | P190: 407
A191: Ashwath S | B191: Ashwath S | C191: Kantha Kumar | D191: Bengaluru | E191: BLR-Soukya | F191: 6865 | G191: 458 | H191: 271 | I191: 440 | J191: 615 | K191: 687 | L191: 817 | M191: 494 | N191: 329 | O191: 831 | P191: 955
A192: Raghavendra Vernekar | B192: Manjunatha V | C192: Un Mapped | D192: Bengaluru | E192: BLR-Sunrise Layout | F192: 5780 | G192: 386 | H192: 622 | I192: 691 | J192: 777 | K192: 418 | L192: 388 | M192: 423 | N192: 444 | O192: 452 | P192: 689
A193: Lakshman Balakrishnan | B193: Rizwan Ahmed | C193: Un Mapped | D193: Bengaluru | E193: BLR-TC Palaya | F193: 6360 | G193: 424 | H193: 77 | I193: 670 | J193: 623 | K193: 743 | L193: 291 | M193: 176 | N193: 885 | O193: 543 | P193: 229
A194: Lakshman Balakrishnan | B194: Saddam Hussain | C194: Un Mapped | D194: Bengaluru | E194: BLR-Teachers colony | F194: 4901 | G194: 327 | H194: 727 | I194: 590 | J194: 194 | K194: 331 | L194: 665 | M194: 338 | N194: 279 | O194: 645 | P194: 819
A195: Raghavendra Vernekar | B195: Suhas N | C195: Aravind S | D195: Bengaluru | E195: BLR-Thyagaraja Nagar | F195: 6444 | G195: 430 | H195: 893 | I195: 343 | J195: 285 | K195: 191 | L195: 423 | M195: 424 | N195: 366 | O195: 316 | P195: 295
A196: Bangareppa CS | B196: Akshay P | C196: Srittam Dhal | D196: Bengaluru | E196: BLR-Tippenahalli | F196: 4636 | G196: 309 | H196: 712 | I196: 1128 | J196: 545 | K196: 755 | L196: 485 | M196: 147 | N196: 196 | O196: 354 | P196: 130
A197: Raghavendra Vernekar | B197: Raghavendra Vernekar | C197: Prakash BS | D197: Bengaluru | E197: BLR-TMC Layout | F197: 4755 | G197: 317 | H197: 992 | I197: 889 | J197: 837 | K197: 694 | L197: 856 | M197: 228 | N197: 225 | O197: 1 | P197: 15
... A254: Bangareppa CS | B254: Akshay P | C254: Srittam Dhal | D254: Tumkuru | E254: TUM-SS Puram | F254: 7007 | G254: 467 | H254: 637 | I254: 993 | J254: 719 | K254: 189 | L254: 251 | M254: 1117 | N254: 222 | O254: 181 | P254: 469

Sheet City Split
A1: Select Date ▶ | B1: 46304 | C1: =IF($B$1="All","<>",$B$1) | D1: (pick a date or "All" from the dropdown)
A3: DH - City Split
A4: Type | B4: City | C4: Store Count | D4: Total Bins | E4: CC MTD % | F4: BA MTD % | G4: IA MTD % | H4: CC ACC % | I4: PD % | J4: Inv Health | K4: CC MTD Target | L4: CC MTD Achieved %
